File: XRD/data/substrates/Si_substrate.ras
*RAS_DATA_START
*RAS_HEADER_START
*DISP_LINE_COLOR "4294901760"
*FILE_COMMENT ""
*FILE_MD5 ""
*FILE_MEMO ""
*FILE_OPERATOR "Administrator"
*FILE_PACKAGE_NAME ""
*FILE_PART_ID "GeneralMeasurement"
*FILE_SAMPLE ""
*FILE_SYSTEM_NAME "SmartLab"
*FILE_TYPE "RAS_RAW"
*FILE_USERGROUP "Administrators"
*FILE_VERSION "1"
*HW_ATTACHMENT_ID "ATT0025"
*HW_ATTACHMENT_NAME "Standard"
*HW_ATTACHMENT_NAME_INTERNAL "Standard"
*HW_COUNTER_ID-0 "CUT0051"
*HW_COUNTER_ID-1 "CMC0020"
*HW_COUNTER_MONOCHRO_ID "CMC0020"
*HW_COUNTER_MONOCHRO_NAME "None"
*HW_COUNTER_MONOCHRO_NAME_INTERNAL "None"
*HW_COUNTER_NAME_INTERNAL "HyPix3000(H)"
*HW_COUNTER_NAME-0 "HyPix3000(H)"
*HW_COUNTER_NAME-1 "None"
*HW_COUNTER_SELECT_NAME "HyPix3000(H)"
*HW_EXTERNAL_CONTROLLER_NAME "None"
*HW_EXTERNAL_CONTROLLER_NAME_INTERNAL "None"
*HW_GONIOMETER_ID "GON0021"
*HW_GONIOMETER_NAME "StandardEnc"
*HW_GONIOMETER_NAME_INTERNAL "StandardEnc"
*HW_GONIOMETER_RADIUS-0 "90.0"
*HW_GONIOMETER_RADIUS-1 "114.0"
*HW_GONIOMETER_RADIUS-2 "190.0"
*HW_GONIOMETER_RADIUS-3 "300.0"
*HW_GONIOMETER_RADIUS-4 "187.0"
*HW_GONIOMETER_RADIUS-5 "300.0"
*HW_GONIOMETER_RADIUS-6 "113.0000"
*HW_GONIOMETER_RADIUS-7 "331.0"
*HW_I_CBO_ID "CBO0021"
*HW_I_CBO_NAME "CBO"
*HW_I_CBO_NAME_INTERNAL "CBO"
*HW_I_MONOCHRO_ID "ISO0021"
*HW_I_MONOCHRO_NAME "IPS_adaptor"
*HW_I_MONOCHRO_NAME_INTERNAL "IPS_adaptor"
*HW_I_OPT_ID-0 "CBO0021"
*HW_I_OPT_ID-1 "ISL0021"
*HW_I_PRIMARY_NAME_INTERNAL "Standard"
*HW_I_SLIT_ID "ISL0021"
*HW_I_SLIT_NAME "Auto"
*HW_I_SLIT_NAME_INTERNAL "Auto"
*HW_R_ATTENUATER_AUTOMODE "0"
*HW_R_ATTENUATER_ID "ATN0020"
*HW_R_ATTENUATER_NAME "No_unit"
*HW_R_ATTENUATOR_NAME_INTERNAL "No_unit"
*HW_R_OPT_ID-0 "RSS0022"
*HW_R_OPT_ID-1 "RCR0022"
*HW_R_OPT_ID-2 "RSO0021"
*HW_R_OPT_ID-3 "RRS0022"
*HW_R_OPT_ID-4 "ATN0020"
*HW_R_ROD_ID "RCR0022"
*HW_R_ROD_NAME "ROD_adaptor"
*HW_R_ROD_NAME_INTERNAL "ROD_adaptor"
*HW_R_RPS_ID "RSO0021"
*HW_R_RPS_NAME "RPS_adaptor"
*HW_R_RPS_NAME_INTERNAL "RPS_adaptor"
*HW_R_RS_ID "RRS0022"
*HW_R_RS_NAME "Virtual"
*HW_R_RS_NAME_INTERNAL "Virtual"
*HW_R_SS_ID "RSS0022"
*HW_R_SS_NAME "Auto_Zr"
*HW_R_SS_NAME_INTERNAL "Auto_Zr"
*HW_ROBOT_NAME "No_unit"
*HW_ROBOT_NAME_INTERNAL "No_unit"
*HW_SAMPLE_CAMERA_NAME "SampleCamera_Std"
*HW_SAMPLE_CAMERA_NAME_INTERNAL "SampleCamera_Std"
*HW_SAMPLE_HOLDER_ID "SMP0021"
*HW_SAMPLE_HOLDER_NAME "Z_ChiPhi"
*HW_SAMPLE_HOLDER_NAME_INTERNAL "Z_ChiPhi"
*HW_SAMPLE_NAME "WaferSample"
*HW_SAMPLE_NAME_INTERNAL "WaferSample"
*HW_SAMPLE_PLATE_NAME "ForWafer"
*HW_SAMPLE_PLATE_NAME_INTERNAL "ForWafer"
*HW_SAMPLE_SPACER_NAME "0-3mm"
*HW_SAMPLE_SPACER_NAME_INTERNAL "0-3mm"
*HW_USERINFO_CATALOG_NO ""
*HW_USERINFO_INSTRUMENT_ID ""
*HW_USERINFO_INSTRUMENT_NAME ""
*HW_USERINFO_MODEL ""
*HW_USERINFO_ORDER_NO ""
*HW_USERINFO_SERIAL_NO ""
*HW_USERINFO_VERIFY_INSTRUMENT_ID "00-07-fe-01-14-97"
*HW_VER_RCD_COUNTER_UNIT "1.0.1"
*HW_VER_RCD_CPU "3.2.2"
*HW_VER_RCD_FPGA "1.2.3"
*HW_VER_RCD_GONIO_UNIT "6.1.1"
*HW_VER_RCD_INCIDENT_UNIT "6.1.1"
*HW_VER_RCD_RECEIVING_UNIT "6.1.1"
*HW_VER_RCD_TYPE "RINC"
*HW_VER_XGC_CPU "3.2.2"
*HW_VER_XGC_CW "1.4.9"
*HW_VER_XGC_HV "1.4.9"
*HW_VER_XGC_RS1 "1.4.9"
*HW_VER_XGC_RS2 "N/A"
*HW_VER_XGC_RT "N/A"
*HW_VER_XGC_TYPE "RINC"
*HW_XG_CURRENT_UNIT "mA"
*HW_XG_FOCUS "0.4mm x 12mm"
*HW_XG_FOCUS_TYPE "LongFine"
*HW_XG_TARGET_ATOMIC_NUMBER "29"
*HW_XG_TARGET_NAME "Cu"
*HW_XG_TYPE "Hermetic"
*HW_XG_VOLTAGE_UNIT "kV"
*HW_XG_WAVE_LENGTH_ALPHA1 "1.540593"
*HW_XG_WAVE_LENGTH_ALPHA2 "1.544414"
*HW_XG_WAVE_LENGTH_BETA "1.392246"
*HW_XG_WAVE_LENGTH_UNIT "Angstrom"
*MEAS_COND_AXIS_NAME_INTERNAL-0 "ThetaS"
*MEAS_COND_AXIS_NAME_INTERNAL-1 "ThetaD"
*MEAS_COND_AXIS_NAME_INTERNAL-10 "CBOType"
*MEAS_COND_AXIS_NAME_INTERNAL-11 "CBO-M"
*MEAS_COND_AXIS_NAME_INTERNAL-12 "CBO"
*MEAS_COND_AXIS_NAME_INTERNAL-13 "IncidentSollerSlit"
*MEAS_COND_AXIS_NAME_INTERNAL-14 "IncidentSlitBox"
*MEAS_COND_AXIS_NAME_INTERNAL-15 "IncidentSlitBox-_Axis"
*MEAS_COND_AXIS_NAME_INTERNAL-16 "SlitDS"
*MEAS_COND_AXIS_NAME_INTERNAL-17 "Zs"
*MEAS_COND_AXIS_NAME_INTERNAL-18 "IncidentAxdSlit"
*MEAS_COND_AXIS_NAME_INTERNAL-19 "LLS"
*MEAS_COND_AXIS_NAME_INTERNAL-2 "TwoTheta"
*MEAS_COND_AXIS_NAME_INTERNAL-20 "DHLSlit"
*MEAS_COND_AXIS_NAME_INTERNAL-21 "Chi"
*MEAS_COND_AXIS_NAME_INTERNAL-22 "Phi"
*MEAS_COND_AXIS_NAME_INTERNAL-23 "Z"
*MEAS_COND_AXIS_NAME_INTERNAL-24 "Alpha"
*MEAS_COND_AXIS_NAME_INTERNAL-25 "Beta"
*MEAS_COND_AXIS_NAME_INTERNAL-26 "ReceivingSlitBox1"
*MEAS_COND_AXIS_NAME_INTERNAL-27 "ReceivingSlitBox1-_Axis"
*MEAS_COND_AXIS_NAME_INTERNAL-28 "SlitSS"
*MEAS_COND_AXIS_NAME_INTERNAL-29 "Zr"
*MEAS_COND_AXIS_NAME_INTERNAL-3 "Omega"
*MEAS_COND_AXIS_NAME_INTERNAL-30 "Filter"
*MEAS_COND_AXIS_NAME_INTERNAL-31 "PSA"
*MEAS_COND_AXIS_NAME_INTERNAL-32 "ReceivingSollerSlit"
*MEAS_COND_AXIS_NAME_INTERNAL-33 "ReceivingSlitBox2"
*MEAS_COND_AXIS_NAME_INTERNAL-34 "ReceivingSlitBox2-_Axis"
*MEAS_COND_AXIS_NAME_INTERNAL-35 "SlitRS"
*MEAS_COND_AXIS_NAME_INTERNAL-36 "ModuleSensorType"
*MEAS_COND_AXIS_NAME_INTERNAL-37 "PHA"
*MEAS_COND_AXIS_NAME_INTERNAL-38 "DetectorBeamStop"
*MEAS_COND_AXIS_NAME_INTERNAL-39 "DetectorFilter"
*MEAS_COND_AXIS_NAME_INTERNAL-4 "TwoThetaTheta"
*MEAS_COND_AXIS_NAME_INTERNAL-40 "DedicatedHolder"
*MEAS_COND_AXIS_NAME_INTERNAL-41 "Target_TargetTime"
*MEAS_COND_AXIS_NAME_INTERNAL-42 "Target_XrayOnTime"
*MEAS_COND_AXIS_NAME_INTERNAL-43 "Target_TMPTime"
*MEAS_COND_AXIS_NAME_INTERNAL-44 "Target_RPTime"
*MEAS_COND_AXIS_NAME_INTERNAL-45 "Target_FilamentTime"
*MEAS_COND_AXIS_NAME_INTERNAL-46 "Target_IG"
*MEAS_COND_AXIS_NAME_INTERNAL-47 "Target_GP"
*MEAS_COND_AXIS_NAME_INTERNAL-48 "Target_FC"
*MEAS_COND_AXIS_NAME_INTERNAL-49 "HVPS_HVPSTime"
*MEAS_COND_AXIS_NAME_INTERNAL-5 "TwoThetaOmega"
*MEAS_COND_AXIS_NAME_INTERNAL-50 "HVPS_Type1Time"
*MEAS_COND_AXIS_NAME_INTERNAL-51 "HVPS_Type2Time"
*MEAS_COND_AXIS_NAME_INTERNAL-52 "HVPS_Type3Time"
*MEAS_COND_AXIS_NAME_INTERNAL-53 "CW_IERTime"
*MEAS_COND_AXIS_NAME_INTERNAL-54 "CW_ECTime"
*MEAS_COND_AXIS_NAME_INTERNAL-55 "CW_Flow1"
*MEAS_COND_AXIS_NAME_INTERNAL-56 "CW_Temperature1"
*MEAS_COND_AXIS_NAME_INTERNAL-57 "CW_Pressure1"
*MEAS_COND_AXIS_NAME_INTERNAL-58 "CW_PressureIn"
*MEAS_COND_AXIS_NAME_INTERNAL-59 "CW_PressureOut"
*MEAS_COND_AXIS_NAME_INTERNAL-6 "OmegaTwoTheta"
*MEAS_COND_AXIS_NAME_INTERNAL-60 "CW_Flow2"
*MEAS_COND_AXIS_NAME_INTERNAL-61 "CW_Temperature2"
*MEAS_COND_AXIS_NAME_INTERNAL-62 "CW_Pressure2"
*MEAS_COND_AXIS_NAME_INTERNAL-63 "RE_EnclosureTemp"
*MEAS_COND_AXIS_NAME_INTERNAL-64 "RE_EnclosureHummidity"
*MEAS_COND_AXIS_NAME_INTERNAL-65 "RE_CabinetTemp"
*MEAS_COND_AXIS_NAME_INTERNAL-66 "RE_RPTemp"
*MEAS_COND_AXIS_NAME_INTERNAL-67 "RE_ShutterAXrayOnTime"
*MEAS_COND_AXIS_NAME_INTERNAL-68 "RE_ShutterATimes"
*MEAS_COND_AXIS_NAME_INTERNAL-69 "RE_ShutterAOpenCloseTime"
*MEAS_COND_AXIS_NAME_INTERNAL-7 "Ts"
*MEAS_COND_AXIS_NAME_INTERNAL-70 "RE_ShutterACloseOpenTime"
*MEAS_COND_AXIS_NAME_INTERNAL-71 "RE_ShutterBXrayOnTime"
*MEAS_COND_AXIS_NAME_INTERNAL-72 "RE_ShutterBTimes"
*MEAS_COND_AXIS_NAME_INTERNAL-73 "RE_ShutterBOpenCloseTime"
*MEAS_COND_AXIS_NAME_INTERNAL-74 "RE_ShutterBCloseOpenTime"
*MEAS_COND_AXIS_NAME_INTERNAL-75 "RE_XrayWarningRamp"
*MEAS_COND_AXIS_NAME_INTERNAL-76 "RE_ShutterAInstallation"
*MEAS_COND_AXIS_NAME_INTERNAL-77 "RE_ShutterARamp"
*MEAS_COND_AXIS_NAME_INTERNAL-78 "RE_ShutterBInstallation"
*MEAS_COND_AXIS_NAME_INTERNAL-79 "RE_ShutterBRamp"
*MEAS_COND_AXIS_NAME_INTERNAL-8 "PrimaryGeometry"
*MEAS_COND_AXIS_NAME_INTERNAL-80 "RE_ExtShutterCLS"
*MEAS_COND_AXIS_NAME_INTERNAL-81 "RE_ExtXrayOFF"
*MEAS_COND_AXIS_NAME_INTERNAL-82 "RE_ExtSafetyCircuit"
*MEAS_COND_AXIS_NAME_INTERNAL-83 "Version_CPU"
*MEAS_COND_AXIS_NAME_INTERNAL-84 "Version_RS1"
*MEAS_COND_AXIS_NAME_INTERNAL-85 "Version_RS2"
*MEAS_COND_AXIS_NAME_INTERNAL-86 "Version_HV"
*MEAS_COND_AXIS_NAME_INTERNAL-87 "Version_CW"
*MEAS_COND_AXIS_NAME_INTERNAL-88 "Version_RT"
*MEAS_COND_AXIS_NAME_INTERNAL-89 "Lens"
*MEAS_COND_AXIS_NAME_INTERNAL-9 "PrimaryMirrorType"
*MEAS_COND_AXIS_NAME_INTERNAL-90 "IncidentPrimary"
*MEAS_COND_AXIS_NAME_INTERNAL-91 "IncidentMonochromator"
*MEAS_COND_AXIS_NAME_INTERNAL-92 "ReceivingOptics"
*MEAS_COND_AXIS_NAME_INTERNAL-93 "CounterMonochromatorKind"
*MEAS_COND_AXIS_NAME-0 "ThetaS"
*MEAS_COND_AXIS_NAME-1 "ThetaD"
*MEAS_COND_AXIS_NAME-10 "CBOType"
*MEAS_COND_AXIS_NAME-11 "CBO-M"
*MEAS_COND_AXIS_NAME-12 "CBO"
*MEAS_COND_AXIS_NAME-13 "IncidentSollerSlit"
*MEAS_COND_AXIS_NAME-14 "IncidentSlitBox"
*MEAS_COND_AXIS_NAME-15 "IncidentSlitBox-_Axis"
*MEAS_COND_AXIS_NAME-16 "SlitDS"
*MEAS_COND_AXIS_NAME-17 "Zs"
*MEAS_COND_AXIS_NAME-18 "IncidentAxdSlit"
*MEAS_COND_AXIS_NAME-19 "LLS"
*MEAS_COND_AXIS_NAME-2 "TwoTheta"
*MEAS_COND_AXIS_NAME-20 "DHLSlit"
*MEAS_COND_AXIS_NAME-21 "Chi"
*MEAS_COND_AXIS_NAME-22 "Phi"
*MEAS_COND_AXIS_NAME-23 "Z"
*MEAS_COND_AXIS_NAME-24 "Alpha"
*MEAS_COND_AXIS_NAME-25 "Beta"
*MEAS_COND_AXIS_NAME-26 "ReceivingSlitBox1"
*MEAS_COND_AXIS_NAME-27 "ReceivingSlitBox1-_Axis"
*MEAS_COND_AXIS_NAME-28 "SlitSS"
*MEAS_COND_AXIS_NAME-29 "Zr"
*MEAS_COND_AXIS_NAME-3 "Omega"
*MEAS_COND_AXIS_NAME-30 "Filter"
*MEAS_COND_AXIS_NAME-31 "PSA"
*MEAS_COND_AXIS_NAME-32 "ReceivingSollerSlit"
*MEAS_COND_AXIS_NAME-33 "ReceivingSlitBox2"
*MEAS_COND_AXIS_NAME-34 "ReceivingSlitBox2-_Axis"
*MEAS_COND_AXIS_NAME-35 "SlitRS"
*MEAS_COND_AXIS_NAME-36 "ModuleSensorType"
*MEAS_COND_AXIS_NAME-37 "PHA"
*MEAS_COND_AXIS_NAME-38 "DetectorBeamStop"
*MEAS_COND_AXIS_NAME-39 "DetectorFilter"
*MEAS_COND_AXIS_NAME-4 "TwoThetaTheta"
*MEAS_COND_AXIS_NAME-40 "DedicatedHolder"
*MEAS_COND_AXIS_NAME-41 "Target_TargetTime"
*MEAS_COND_AXIS_NAME-42 "Target_XrayOnTime"
*MEAS_COND_AXIS_NAME-43 "Target_TMPTime"
*MEAS_COND_AXIS_NAME-44 "Target_RPTime"
*MEAS_COND_AXIS_NAME-45 "Target_FilamentTime"
*MEAS_COND_AXIS_NAME-46 "Target_IG"
*MEAS_COND_AXIS_NAME-47 "Target_GP"
*MEAS_COND_AXIS_NAME-48 "Target_FC"
*MEAS_COND_AXIS_NAME-49 "HVPS_HVPSTime"
*MEAS_COND_AXIS_NAME-5 "TwoThetaOmega"
*MEAS_COND_AXIS_NAME-50 "HVPS_Type1Time"
*MEAS_COND_AXIS_NAME-51 "HVPS_Type2Time"
*MEAS_COND_AXIS_NAME-52 "HVPS_Type3Time"
*MEAS_COND_AXIS_NAME-53 "CW_IERTime"
*MEAS_COND_AXIS_NAME-54 "CW_ECTime"
*MEAS_COND_AXIS_NAME-55 "CW_Flow1"
*MEAS_COND_AXIS_NAME-56 "CW_Temperature1"
*MEAS_COND_AXIS_NAME-57 "CW_Pressure1"
*MEAS_COND_AXIS_NAME-58 "CW_PressureIn"
*MEAS_COND_AXIS_NAME-59 "CW_PressureOut"
*MEAS_COND_AXIS_NAME-6 "OmegaTwoTheta"
*MEAS_COND_AXIS_NAME-60 "CW_Flow2"
*MEAS_COND_AXIS_NAME-61 "CW_Temperature2"
*MEAS_COND_AXIS_NAME-62 "CW_Pressure2"
*MEAS_COND_AXIS_NAME-63 "RE_EnclosureTemp"
*MEAS_COND_AXIS_NAME-64 "RE_EnclosureHummidity"
*MEAS_COND_AXIS_NAME-65 "RE_CabinetTemp"
*MEAS_COND_AXIS_NAME-66 "RE_RPTemp"
*MEAS_COND_AXIS_NAME-67 "RE_ShutterAXrayOnTime"
*MEAS_COND_AXIS_NAME-68 "RE_ShutterATimes"
*MEAS_COND_AXIS_NAME-69 "RE_ShutterAOpenCloseTime"
*MEAS_COND_AXIS_NAME-7 "Ts"
*MEAS_COND_AXIS_NAME-70 "RE_ShutterACloseOpenTime"
*MEAS_COND_AXIS_NAME-71 "RE_ShutterBXrayOnTime"
*MEAS_COND_AXIS_NAME-72 "RE_ShutterBTimes"
*MEAS_COND_AXIS_NAME-73 "RE_ShutterBOpenCloseTime"
*MEAS_COND_AXIS_NAME-74 "RE_ShutterBCloseOpenTime"
*MEAS_COND_AXIS_NAME-75 "RE_XrayWarningRamp"
*MEAS_COND_AXIS_NAME-76 "RE_ShutterAInstallation"
*MEAS_COND_AXIS_NAME-77 "RE_ShutterARamp"
*MEAS_COND_AXIS_NAME-78 "RE_ShutterBInstallation"
*MEAS_COND_AXIS_NAME-79 "RE_ShutterBRamp"
*MEAS_COND_AXIS_NAME-8 "PrimaryGeometry"
*MEAS_COND_AXIS_NAME-80 "RE_ExtShutterCLS"
*MEAS_COND_AXIS_NAME-81 "RE_ExtXrayOFF"
*MEAS_COND_AXIS_NAME-82 "RE_ExtSafetyCircuit"
*MEAS_COND_AXIS_NAME-83 "Version_CPU"
*MEAS_COND_AXIS_NAME-84 "Version_RS1"
*MEAS_COND_AXIS_NAME-85 "Version_RS2"
*MEAS_COND_AXIS_NAME-86 "Version_HV"
*MEAS_COND_AXIS_NAME-87 "Version_CW"
*MEAS_COND_AXIS_NAME-88 "Version_RT"
*MEAS_COND_AXIS_NAME-89 "Lens"
*MEAS_COND_AXIS_NAME-9 "PrimaryMirrorType"
*MEAS_COND_AXIS_NAME-90 "IncidentPrimary"
*MEAS_COND_AXIS_NAME-91 "IncidentMonochromator"
*MEAS_COND_AXIS_NAME-92 "ReceivingOptics"
*MEAS_COND_AXIS_NAME-93 "CounterMonochromatorKind"
*MEAS_COND_AXIS_OFFSET-0 "1.4312"
*MEAS_COND_AXIS_OFFSET-1 "-0.1425"
*MEAS_COND_AXIS_OFFSET-10 "0"
*MEAS_COND_AXIS_OFFSET-11 "0"
*MEAS_COND_AXIS_OFFSET-12 "0"
*MEAS_COND_AXIS_OFFSET-13 "0"
*MEAS_COND_AXIS_OFFSET-14 "0"
*MEAS_COND_AXIS_OFFSET-15 "0"
*MEAS_COND_AXIS_OFFSET-16 "0"
*MEAS_COND_AXIS_OFFSET-17 "0"
*MEAS_COND_AXIS_OFFSET-18 "0"
*MEAS_COND_AXIS_OFFSET-19 "0"
*MEAS_COND_AXIS_OFFSET-2 "1.2887"
*MEAS_COND_AXIS_OFFSET-20 "0"
*MEAS_COND_AXIS_OFFSET-21 "0"
*MEAS_COND_AXIS_OFFSET-22 "0"
*MEAS_COND_AXIS_OFFSET-23 "0"
*MEAS_COND_AXIS_OFFSET-24 "0"
*MEAS_COND_AXIS_OFFSET-25 "0"
*MEAS_COND_AXIS_OFFSET-26 "0"
*MEAS_COND_AXIS_OFFSET-27 "0"
*MEAS_COND_AXIS_OFFSET-28 "0"
*MEAS_COND_AXIS_OFFSET-29 "0"
*MEAS_COND_AXIS_OFFSET-3 "1.4312"
*MEAS_COND_AXIS_OFFSET-30 "0"
*MEAS_COND_AXIS_OFFSET-31 "0"
*MEAS_COND_AXIS_OFFSET-32 "0"
*MEAS_COND_AXIS_OFFSET-33 "0"
*MEAS_COND_AXIS_OFFSET-34 "0"
*MEAS_COND_AXIS_OFFSET-35 "0"
*MEAS_COND_AXIS_OFFSET-36 "0"
*MEAS_COND_AXIS_OFFSET-37 "0"
*MEAS_COND_AXIS_OFFSET-38 "0"
*MEAS_COND_AXIS_OFFSET-39 "0"
*MEAS_COND_AXIS_OFFSET-4 "0"
*MEAS_COND_AXIS_OFFSET-40 "0"
*MEAS_COND_AXIS_OFFSET-41 "0"
*MEAS_COND_AXIS_OFFSET-42 "0"
*MEAS_COND_AXIS_OFFSET-43 "0"
*MEAS_COND_AXIS_OFFSET-44 "0"
*MEAS_COND_AXIS_OFFSET-45 "0"
*MEAS_COND_AXIS_OFFSET-46 "0"
*MEAS_COND_AXIS_OFFSET-47 "0"
*MEAS_COND_AXIS_OFFSET-48 "0"
*MEAS_COND_AXIS_OFFSET-49 "0"
*MEAS_COND_AXIS_OFFSET-5 "0"
*MEAS_COND_AXIS_OFFSET-50 "0"
*MEAS_COND_AXIS_OFFSET-51 "0"
*MEAS_COND_AXIS_OFFSET-52 "0"
*MEAS_COND_AXIS_OFFSET-53 "0"
*MEAS_COND_AXIS_OFFSET-54 "0"
*MEAS_COND_AXIS_OFFSET-55 "0"
*MEAS_COND_AXIS_OFFSET-56 "0"
*MEAS_COND_AXIS_OFFSET-57 "0"
*MEAS_COND_AXIS_OFFSET-58 "0"
*MEAS_COND_AXIS_OFFSET-59 "0"
*MEAS_COND_AXIS_OFFSET-6 "0"
*MEAS_COND_AXIS_OFFSET-60 "0"
*MEAS_COND_AXIS_OFFSET-61 "0"
*MEAS_COND_AXIS_OFFSET-62 "0"
*MEAS_COND_AXIS_OFFSET-63 "0"
*MEAS_COND_AXIS_OFFSET-64 "0"
*MEAS_COND_AXIS_OFFSET-65 "0"
*MEAS_COND_AXIS_OFFSET-66 "0"
*MEAS_COND_AXIS_OFFSET-67 "0"
*MEAS_COND_AXIS_OFFSET-68 "0"
*MEAS_COND_AXIS_OFFSET-69 "0"
*MEAS_COND_AXIS_OFFSET-7 "0"
*MEAS_COND_AXIS_OFFSET-70 "0"
*MEAS_COND_AXIS_OFFSET-71 "0"
*MEAS_COND_AXIS_OFFSET-72 "0"
*MEAS_COND_AXIS_OFFSET-73 "0"
*MEAS_COND_AXIS_OFFSET-74 "0"
*MEAS_COND_AXIS_OFFSET-75 "0"
*MEAS_COND_AXIS_OFFSET-76 "0"
*MEAS_COND_AXIS_OFFSET-77 "0"
*MEAS_COND_AXIS_OFFSET-78 "0"
*MEAS_COND_AXIS_OFFSET-79 "0"
*MEAS_COND_AXIS_OFFSET-8 "0"
*MEAS_COND_AXIS_OFFSET-80 "0"
*MEAS_COND_AXIS_OFFSET-81 "0"
*MEAS_COND_AXIS_OFFSET-82 "0"
*MEAS_COND_AXIS_OFFSET-83 "0"
*MEAS_COND_AXIS_OFFSET-84 "0"
*MEAS_COND_AXIS_OFFSET-85 "0"
*MEAS_COND_AXIS_OFFSET-86 "0"
*MEAS_COND_AXIS_OFFSET-87 "0"
*MEAS_COND_AXIS_OFFSET-88 "0"
*MEAS_COND_AXIS_OFFSET-89 "0"
*MEAS_COND_AXIS_OFFSET-9 "0"
*MEAS_COND_AXIS_OFFSET-90 "0"
*MEAS_COND_AXIS_OFFSET-91 "0"
*MEAS_COND_AXIS_OFFSET-92 "0"
*MEAS_COND_AXIS_OFFSET-93 "0"
*MEAS_COND_AXIS_POSITION-0 "0.0000"
*MEAS_COND_AXIS_POSITION-1 "0.0000"
*MEAS_COND_AXIS_POSITION-10 "Type1"
*MEAS_COND_AXIS_POSITION-11 "0"
*MEAS_COND_AXIS_POSITION-12 "PB"
*MEAS_COND_AXIS_POSITION-13 "Soller_slit_2.5deg"
*MEAS_COND_AXIS_POSITION-14 "1.000mm"
*MEAS_COND_AXIS_POSITION-15 "1.000000"
*MEAS_COND_AXIS_POSITION-16 "1.000mm"
*MEAS_COND_AXIS_POSITION-17 "-0.6296875"
*MEAS_COND_AXIS_POSITION-18 "5mm"
*MEAS_COND_AXIS_POSITION-19 "5mm"
*MEAS_COND_AXIS_POSITION-2 "0.0000"
*MEAS_COND_AXIS_POSITION-20 "5mm"
*MEAS_COND_AXIS_POSITION-21 "0.000"
*MEAS_COND_AXIS_POSITION-22 "0.000"
*MEAS_COND_AXIS_POSITION-23 "0.1064"
*MEAS_COND_AXIS_POSITION-24 "90.000"
*MEAS_COND_AXIS_POSITION-25 "0.000"
*MEAS_COND_AXIS_POSITION-26 "1.000mm"
*MEAS_COND_AXIS_POSITION-27 "1.000000"
*MEAS_COND_AXIS_POSITION-28 "1.000mm"
*MEAS_COND_AXIS_POSITION-29 "0.0100000"
*MEAS_COND_AXIS_POSITION-3 "0.0000"
*MEAS_COND_AXIS_POSITION-30 "Cu_K-beta"
*MEAS_COND_AXIS_POSITION-31 "PSA_open"
*MEAS_COND_AXIS_POSITION-32 "Soller_slit_2.5deg"
*MEAS_COND_AXIS_POSITION-33 "1.100mm"
*MEAS_COND_AXIS_POSITION-34 "1.1"
*MEAS_COND_AXIS_POSITION-35 "1.100mm"
*MEAS_COND_AXIS_POSITION-36 "AC"
*MEAS_COND_AXIS_POSITION-37 ""
*MEAS_COND_AXIS_POSITION-38 "None"
*MEAS_COND_AXIS_POSITION-39 "None"
*MEAS_COND_AXIS_POSITION-4 "0.0000"
*MEAS_COND_AXIS_POSITION-40 "None"
*MEAS_COND_AXIS_POSITION-41 ""
*MEAS_COND_AXIS_POSITION-42 ""
*MEAS_COND_AXIS_POSITION-43 ""
*MEAS_COND_AXIS_POSITION-44 ""
*MEAS_COND_AXIS_POSITION-45 ""
*MEAS_COND_AXIS_POSITION-46 ""
*MEAS_COND_AXIS_POSITION-47 ""
*MEAS_COND_AXIS_POSITION-48 ""
*MEAS_COND_AXIS_POSITION-49 ""
*MEAS_COND_AXIS_POSITION-5 "0.0000"
*MEAS_COND_AXIS_POSITION-50 ""
*MEAS_COND_AXIS_POSITION-51 ""
*MEAS_COND_AXIS_POSITION-52 ""
*MEAS_COND_AXIS_POSITION-53 ""
*MEAS_COND_AXIS_POSITION-54 ""
*MEAS_COND_AXIS_POSITION-55 ""
*MEAS_COND_AXIS_POSITION-56 ""
*MEAS_COND_AXIS_POSITION-57 ""
*MEAS_COND_AXIS_POSITION-58 ""
*MEAS_COND_AXIS_POSITION-59 ""
*MEAS_COND_AXIS_POSITION-6 "0.0000"
*MEAS_COND_AXIS_POSITION-60 ""
*MEAS_COND_AXIS_POSITION-61 ""
*MEAS_COND_AXIS_POSITION-62 ""
*MEAS_COND_AXIS_POSITION-63 ""
*MEAS_COND_AXIS_POSITION-64 ""
*MEAS_COND_AXIS_POSITION-65 ""
*MEAS_COND_AXIS_POSITION-66 ""
*MEAS_COND_AXIS_POSITION-67 ""
*MEAS_COND_AXIS_POSITION-68 ""
*MEAS_COND_AXIS_POSITION-69 ""
*MEAS_COND_AXIS_POSITION-7 "0.4652500"
*MEAS_COND_AXIS_POSITION-70 ""
*MEAS_COND_AXIS_POSITION-71 ""
*MEAS_COND_AXIS_POSITION-72 ""
*MEAS_COND_AXIS_POSITION-73 ""
*MEAS_COND_AXIS_POSITION-74 ""
*MEAS_COND_AXIS_POSITION-75 ""
*MEAS_COND_AXIS_POSITION-76 ""
*MEAS_COND_AXIS_POSITION-77 ""
*MEAS_COND_AXIS_POSITION-78 ""
*MEAS_COND_AXIS_POSITION-79 ""
*MEAS_COND_AXIS_POSITION-8 "Right"
*MEAS_COND_AXIS_POSITION-80 ""
*MEAS_COND_AXIS_POSITION-81 ""
*MEAS_COND_AXIS_POSITION-82 ""
*MEAS_COND_AXIS_POSITION-83 ""
*MEAS_COND_AXIS_POSITION-84 ""
*MEAS_COND_AXIS_POSITION-85 ""
*MEAS_COND_AXIS_POSITION-86 ""
*MEAS_COND_AXIS_POSITION-87 ""
*MEAS_COND_AXIS_POSITION-88 ""
*MEAS_COND_AXIS_POSITION-89 "1"
*MEAS_COND_AXIS_POSITION-9 "None"
*MEAS_COND_AXIS_POSITION-90 "Standard"
*MEAS_COND_AXIS_POSITION-91 "IPS_adaptor"
*MEAS_COND_AXIS_POSITION-92 "PSA_open"
*MEAS_COND_AXIS_POSITION-93 "None"
*MEAS_COND_AXIS_UNIT-0 "deg"
*MEAS_COND_AXIS_UNIT-1 "deg"
*MEAS_COND_AXIS_UNIT-10 ""
*MEAS_COND_AXIS_UNIT-11 "pulse"
*MEAS_COND_AXIS_UNIT-12 ""
*MEAS_COND_AXIS_UNIT-13 ""
*MEAS_COND_AXIS_UNIT-14 ""
*MEAS_COND_AXIS_UNIT-15 "mm"
*MEAS_COND_AXIS_UNIT-16 ""
*MEAS_COND_AXIS_UNIT-17 "mm"
*MEAS_COND_AXIS_UNIT-18 ""
*MEAS_COND_AXIS_UNIT-19 ""
*MEAS_COND_AXIS_UNIT-2 "deg"
*MEAS_COND_AXIS_UNIT-20 ""
*MEAS_COND_AXIS_UNIT-21 "deg"
*MEAS_COND_AXIS_UNIT-22 "deg"
*MEAS_COND_AXIS_UNIT-23 "mm"
*MEAS_COND_AXIS_UNIT-24 "deg"
*MEAS_COND_AXIS_UNIT-25 "deg"
*MEAS_COND_AXIS_UNIT-26 ""
*MEAS_COND_AXIS_UNIT-27 "mm"
*MEAS_COND_AXIS_UNIT-28 ""
*MEAS_COND_AXIS_UNIT-29 "mm"
*MEAS_COND_AXIS_UNIT-3 "deg"
*MEAS_COND_AXIS_UNIT-30 ""
*MEAS_COND_AXIS_UNIT-31 ""
*MEAS_COND_AXIS_UNIT-32 ""
*MEAS_COND_AXIS_UNIT-33 ""
*MEAS_COND_AXIS_UNIT-34 "mm"
*MEAS_COND_AXIS_UNIT-35 ""
*MEAS_COND_AXIS_UNIT-36 ""
*MEAS_COND_AXIS_UNIT-37 "keV"
*MEAS_COND_AXIS_UNIT-38 ""
*MEAS_COND_AXIS_UNIT-39 ""
*MEAS_COND_AXIS_UNIT-4 "deg"
*MEAS_COND_AXIS_UNIT-40 ""
*MEAS_COND_AXIS_UNIT-41 "H"
*MEAS_COND_AXIS_UNIT-42 "H"
*MEAS_COND_AXIS_UNIT-43 "H"
*MEAS_COND_AXIS_UNIT-44 "H"
*MEAS_COND_AXIS_UNIT-45 "H"
*MEAS_COND_AXIS_UNIT-46 "mV"
*MEAS_COND_AXIS_UNIT-47 "V"
*MEAS_COND_AXIS_UNIT-48 "V"
*MEAS_COND_AXIS_UNIT-49 "H"
*MEAS_COND_AXIS_UNIT-5 "deg"
*MEAS_COND_AXIS_UNIT-50 "H"
*MEAS_COND_AXIS_UNIT-51 "H"
*MEAS_COND_AXIS_UNIT-52 "H"
*MEAS_COND_AXIS_UNIT-53 "H"
*MEAS_COND_AXIS_UNIT-54 "uS/m"
*MEAS_COND_AXIS_UNIT-55 "L/min"
*MEAS_COND_AXIS_UNIT-56 "degree"
*MEAS_COND_AXIS_UNIT-57 "MPa"
*MEAS_COND_AXIS_UNIT-58 "MPa"
*MEAS_COND_AXIS_UNIT-59 "MPa"
*MEAS_COND_AXIS_UNIT-6 "deg"
*MEAS_COND_AXIS_UNIT-60 "L/min"
*MEAS_COND_AXIS_UNIT-61 "C"
*MEAS_COND_AXIS_UNIT-62 "MPa"
*MEAS_COND_AXIS_UNIT-63 "degree"
*MEAS_COND_AXIS_UNIT-64 "percent"
*MEAS_COND_AXIS_UNIT-65 "degree"
*MEAS_COND_AXIS_UNIT-66 "C"
*MEAS_COND_AXIS_UNIT-67 "H"
*MEAS_COND_AXIS_UNIT-68 "time"
*MEAS_COND_AXIS_UNIT-69 "msec"
*MEAS_COND_AXIS_UNIT-7 "mm"
*MEAS_COND_AXIS_UNIT-70 "msec"
*MEAS_COND_AXIS_UNIT-71 "H"
*MEAS_COND_AXIS_UNIT-72 "times"
*MEAS_COND_AXIS_UNIT-73 "msec"
*MEAS_COND_AXIS_UNIT-74 "msec"
*MEAS_COND_AXIS_UNIT-75 "-"
*MEAS_COND_AXIS_UNIT-76 "-"
*MEAS_COND_AXIS_UNIT-77 "-"
*MEAS_COND_AXIS_UNIT-78 ""
*MEAS_COND_AXIS_UNIT-79 "-"
*MEAS_COND_AXIS_UNIT-8 ""
*MEAS_COND_AXIS_UNIT-80 "-"
*MEAS_COND_AXIS_UNIT-81 "-"
*MEAS_COND_AXIS_UNIT-82 ""
*MEAS_COND_AXIS_UNIT-83 ""
*MEAS_COND_AXIS_UNIT-84 ""
*MEAS_COND_AXIS_UNIT-85 ""
*MEAS_COND_AXIS_UNIT-86 ""
*MEAS_COND_AXIS_UNIT-87 ""
*MEAS_COND_AXIS_UNIT-88 ""
*MEAS_COND_AXIS_UNIT-89 ""
*MEAS_COND_AXIS_UNIT-9 ""
*MEAS_COND_AXIS_UNIT-90 ""
*MEAS_COND_AXIS_UNIT-91 ""
*MEAS_COND_AXIS_UNIT-92 ""
*MEAS_COND_AXIS_UNIT-93 ""
*MEAS_COND_OPT_ATTR "PB"
*MEAS_COND_OPT_NAME "User defined settings"
*MEAS_COND_XG_CURRENT "40"
*MEAS_COND_XG_VOLTAGE "40"
*MEAS_COND_XG_WAVE_TYPE "Ka"
*MEAS_DATA_COUNT "7001"
*MEAS_SCAN_AXIS_X "TwoThetaTheta"
*MEAS_SCAN_AXIS_X_INTERNAL "TwoThetaTheta"
*MEAS_SCAN_END_TIME "03/07/2023 15:47:19"
*MEAS_SCAN_MODE "CONTINUOUS"
*MEAS_SCAN_MODE_INTERNAL "CONTINUOUS"
*MEAS_SCAN_RESOLUTION_X "0.0002"
*MEAS_SCAN_SPEED "4.0000"
*MEAS_SCAN_SPEED_UNIT "deg/min"
*MEAS_SCAN_START "10.0000"
*MEAS_SCAN_START_TIME "03/07/2023 15:29:28"
*MEAS_SCAN_STEP "0.0100"
*MEAS_SCAN_STOP "80.0000"
*MEAS_SCAN_UNIT_X "deg"
*MEAS_SCAN_UNIT_Y "counts"
*RAS_HEADER_END
*RAS_INT_START
10.0000 4.0443 1.0000
10.0500 6.3817 1.0000
10.1000 2.0055 1.0000
10.1500 1.3078 1.0000
10.2000 4.0687 1.0000
10.2500 5.6974 1.0000
10.3000 4.6327 1.0000
10.3500 2.0350 1.0000
10.4000 0.0000 1.0000
10.4500 4.0185 1.0000
10.5000 0.0000 1.0000
10.5500 3.9698 1.0000
10.6000 4.9468 1.0000
10.6500 3.0144 1.0000
10.7000 3.3189 1.0000
10.7500 3.9183 1.0000
10.8000 0.0000 1.0000
10.8500 4.3571 1.0000
10.9000 8.9246 1.0000
10.9500 3.3659 1.0000
11.0000 2.9065 1.0000
11.0500 4.3549 1.0000
11.1000 2.5881 1.0000
11.1500 5.0096 1.0000
11.2000 5.0656 1.0000
11.2500 4.0601 1.0000
11.3000 1.3023 1.0000
11.3500 2.3554 1.0000
11.4000 4.0013 1.0000
11.4500 4.9538 1.0000
11.5000 1.3412 1.0000
11.5500 1.9682 1.0000
11.6000 4.1671 1.0000
11.6500 5.3458 1.0000
11.7000 5.3384 1.0000
11.7500 2.0082 1.0000
11.8000 2.0067 1.0000
11.8500 2.0277 1.0000
11.9000 0.3419 1.0000
11.9500 3.4302 1.0000
12.0000 2.7649 1.0000
12.0500 4.0693 1.0000
12.1000 3.9944 1.0000
12.1500 3.3427 1.0000
12.2000 2.0536 1.0000
12.2500 3.6494 1.0000
12.3000 4.2695 1.0000
12.3500 4.9925 1.0000
12.4000 0.9552 1.0000
12.4500 3.5391 1.0000
12.5000 2.9844 1.0000
12.5500 6.5364 1.0000
12.6000 3.9820 1.0000
12.6500 6.5746 1.0000
12.7000 1.2889 1.0000
12.7500 2.3271 1.0000
12.8000 5.7140 1.0000
12.8500 5.2851 1.0000
12.9000 2.0125 1.0000
12.9500 2.0008 1.0000
13.0000 2.6964 1.0000
13.0500 3.3484 1.0000
13.1000 2.8893 1.0000
13.1500 3.3439 1.0000
13.2000 2.0772 1.0000
13.2500 0.9775 1.0000
13.3000 1.6575 1.0000
13.3500 2.0309 1.0000
13.4000 3.9990 1.0000
13.4500 4.3406 1.0000
13.5000 7.3278 1.0000
13.5500 0.9618 1.0000
13.6000 2.6681 1.0000
13.6500 5.3118 1.0000
13.7000 5.0635 1.0000
13.7500 4.5731 1.0000
13.8000 2.3105 1.0000
13.8500 5.0232 1.0000
13.9000 2.3618 1.0000
13.9500 2.0583 1.0000
14.0000 1.3378 1.0000
14.0500 1.3413 1.0000
14.1000 3.3344 1.0000
14.1500 1.6715 1.0000
14.2000 2.0275 1.0000
14.2500 0.0000 1.0000
14.3000 3.3312 1.0000
14.3500 0.9826 1.0000
14.4000 4.0797 1.0000
14.4500 3.4931 1.0000
14.5000 7.4725 1.0000
14.5500 2.0527 1.0000
14.6000 1.9849 1.0000
14.6500 3.0357 1.0000
14.7000 1.9772 1.0000
14.7500 2.2842 1.0000
14.8000 2.0410 1.0000
14.8500 0.9492 1.0000
14.9000 5.1828 1.0000
14.9500 0.3266 1.0000
15.0000 3.3753 1.0000
15.0500 3.0409 1.0000
15.1000 0.0000 1.0000
15.1500 3.4193 1.0000
15.2000 0.3419 1.0000
15.2500 0.9868 1.0000
15.3000 1.0008 1.0000
15.3500 2.3275 1.0000
15.4000 1.3351 1.0000
15.4500 0.9919 1.0000
15.5000 0.6487 1.0000
15.5500 3.3162 1.0000
15.6000 5.9653 1.0000
15.6500 4.4047 1.0000
15.7000 2.9701 1.0000
15.7500 6.1532 1.0000
15.8000 5.1724 1.0000
15.8500 1.3819 1.0000
15.9000 0.0000 1.0000
15.9500 2.0301 1.0000
16.0000 0.9997 1.0000
16.0500 5.4231 1.0000
16.1000 3.3565 1.0000
16.1500 2.5884 1.0000
16.2000 3.0089 1.0000
16.2500 3.3557 1.0000
16.3000 2.0558 1.0000
16.3500 0.0000 1.0000
16.4000 2.3925 1.0000
16.4500 4.4622 1.0000
16.5000 2.7885 1.0000
16.5500 2.6126 1.0000
16.6000 0.3481 1.0000
16.6500 4.3497 1.0000
16.7000 0.0000 1.0000
16.7500 0.9940 1.0000
16.8000 2.0634 1.0000
16.8500 0.0000 1.0000
16.9000 2.9487 1.0000
16.9500 1.6572 1.0000
17.0000 0.9960 1.0000
17.0500 4.0597 1.0000
17.1000 2.6052 1.0000
17.1500 2.0314 1.0000
17.2000 2.3289 1.0000
17.2500 1.9765 1.0000
17.3000 2.3617 1.0000
17.3500 3.1050 1.0000
17.4000 1.3611 1.0000
17.4500 0.6870 1.0000
17.5000 5.0359 1.0000
17.5500 1.9473 1.0000
17.6000 1.0359 1.0000
17.6500 2.0503 1.0000
17.7000 2.2809 1.0000
17.7500 2.3094 1.0000
17.8000 0.0000 1.0000
17.8500 2.9451 1.0000
17.9000 0.9613 1.0000
17.9500 1.9330 1.0000
18.0000 3.7214 1.0000
18.0500 2.2933 1.0000
18.1000 1.3265 1.0000
18.1500 3.0346 1.0000
18.2000 5.7263 1.0000
18.2500 1.0046 1.0000
18.3000 1.0206 1.0000
18.3500 3.3388 1.0000
18.4000 0.6700 1.0000
18.4500 0.0000 1.0000
18.5000 4.2863 1.0000
18.5500 1.3290 1.0000
18.6000 2.0182 1.0000
18.6500 1.0013 1.0000
18.7000 0.0000 1.0000
18.7500 1.3191 1.0000
18.8000 2.5334 1.0000
18.8500 0.0000 1.0000
18.9000 2.0468 1.0000
18.9500 1.9733 1.0000
19.0000 2.0461 1.0000
19.0500 0.9884 1.0000
19.1000 0.6487 1.0000
19.1500 2.9767 1.0000
19.2000 1.0206 1.0000
19.2500 4.3695 1.0000
19.3000 1.0133 1.0000
19.3500 3.5561 1.0000
19.4000 0.9852 1.0000
19.4500 4.4064 1.0000
19.5000 0.9613 1.0000
19.5500 2.0133 1.0000
19.6000 3.0078 1.0000
19.6500 0.0000 1.0000
19.7000 2.3422 1.0000
19.7500 2.0259 1.0000
19.8000 2.9879 1.0000
19.8500 1.3436 1.0000
19.9000 4.3383 1.0000
19.9500 0.0000 1.0000
20.0000 0.0000 1.0000
20.0500 2.9990 1.0000
20.1000 1.0300 1.0000
20.1500 1.9758 1.0000
20.2000 0.9792 1.0000
20.2500 1.3317 1.0000
20.3000 2.1022 1.0000
20.3500 3.0464 1.0000
20.4000 0.0000 1.0000
20.4500 2.3682 1.0000
20.5000 0.0000 1.0000
20.5500 0.3319 1.0000
20.6000 2.0382 1.0000
20.6500 3.0691 1.0000
20.7000 1.3967 1.0000
20.7500 1.0218 1.0000
20.8000 2.2765 1.0000
20.8500 0.3333 1.0000
20.9000 1.3383 1.0000
20.9500 2.3658 1.0000
21.0000 2.9575 1.0000
21.0500 2.3158 1.0000
21.1000 1.0320 1.0000
21.1500 0.0000 1.0000
21.2000 2.0324 1.0000
21.2500 1.0402 1.0000
21.3000 2.0647 1.0000
21.3500 0.9783 1.0000
21.4000 2.5734 1.0000
21.4500 1.3817 1.0000
21.5000 3.3021 1.0000
21.5500 2.3361 1.0000
21.6000 2.3855 1.0000
21.6500 1.6289 1.0000
21.7000 1.0244 1.0000
21.7500 0.3382 1.0000
21.8000 2.3336 1.0000
21.8500 1.5172 1.0000
21.9000 2.0300 1.0000
21.9500 2.3778 1.0000
22.0000 1.0074 1.0000
22.0500 4.7533 1.0000
22.1000 1.9827 1.0000
22.1500 1.0151 1.0000
22.2000 3.0911 1.0000
22.2500 2.0653 1.0000
22.3000 2.3457 1.0000
22.3500 2.0491 1.0000
22.4000 1.9858 1.0000
22.4500 1.9799 1.0000
22.5000 0.9802 1.0000
22.5500 3.7262 1.0000
22.6000 1.0266 1.0000
22.6500 0.6538 1.0000
22.7000 3.9923 1.0000
22.7500 1.2901 1.0000
22.8000 3.1508 1.0000
22.8500 2.9879 1.0000
22.9000 0.1433 1.0000
22.9500 0.0000 1.0000
23.0000 2.0075 1.0000
23.0500 1.3308 1.0000
23.1000 3.0556 1.0000
23.1500 0.9639 1.0000
23.2000 1.0037 1.0000
23.2500 2.9780 1.0000
23.3000 0.0000 1.0000
23.3500 2.0146 1.0000
23.4000 0.9999 1.0000
23.4500 1.9478 1.0000
23.5000 0.9608 1.0000
23.5500 2.0747 1.0000
23.6000 0.0000 1.0000
23.6500 2.0281 1.0000
23.7000 1.9703 1.0000
23.7500 0.9897 1.0000
23.8000 2.0092 1.0000
23.8500 2.1796 1.0000
23.9000 0.9991 1.0000
23.9500 0.0000 1.0000
24.0000 1.9248 1.0000
24.0500 2.2883 1.0000
24.1000 0.3266 1.0000
24.1500 0.6682 1.0000
24.2000 1.9730 1.0000
24.2500 1.9734 1.0000
24.3000 0.0000 1.0000
24.3500 0.0000 1.0000
24.4000 0.0000 1.0000
24.4500 1.9730 1.0000
24.5000 0.0000 1.0000
24.5500 0.0000 1.0000
24.6000 1.0130 1.0000
24.6500 0.0000 1.0000
24.7000 0.0000 1.0000
24.7500 4.0882 1.0000
24.8000 1.0357 1.0000
24.8500 2.0603 1.0000
24.9000 1.0452 1.0000
24.9500 1.3194 1.0000
25.0000 0.9501 1.0000
25.0500 1.0181 1.0000
25.1000 2.0119 1.0000
25.1500 2.9524 1.0000
25.2000 1.9918 1.0000
25.2500 1.9691 1.0000
25.3000 0.0000 1.0000
25.3500 1.0218 1.0000
25.4000 0.3396 1.0000
25.4500 3.0223 1.0000
25.5000 0.0000 1.0000
25.5500 3.3554 1.0000
25.6000 2.0927 1.0000
25.6500 0.3455 1.0000
25.7000 1.0048 1.0000
25.7500 2.0609 1.0000
25.8000 2.0525 1.0000
25.8500 0.9726 1.0000
25.9000 1.3445 1.0000
25.9500 1.0307 1.0000
26.0000 0.0000 1.0000
26.0500 0.3547 1.0000
26.1000 1.3280 1.0000
26.1500 3.1017 1.0000
26.2000 0.9768 1.0000
26.2500 0.0000 1.0000
26.3000 1.0523 1.0000
26.3500 0.0000 1.0000
26.4000 1.9770 1.0000
26.4500 1.3223 1.0000
26.5000 0.9889 1.0000
26.5500 1.6464 1.0000
26.6000 3.0959 1.0000
26.6500 1.3554 1.0000
26.7000 1.4191 1.0000
26.7500 0.0000 1.0000
26.8000 0.9989 1.0000
26.8500 0.0000 1.0000
26.9000 2.5634 1.0000
26.9500 1.0721 1.0000
27.0000 1.0599 1.0000
27.0500 0.0000 1.0000
27.1000 0.0000 1.0000
27.1500 1.0877 1.0000
27.2000 1.0090 1.0000
27.2500 1.4334 1.0000
27.3000 0.9886 1.0000
27.3500 2.0230 1.0000
27.4000 2.0165 1.0000
27.4500 0.9783 1.0000
27.5000 0.0000 1.0000
27.5500 0.3314 1.0000
27.6000 1.0191 1.0000
27.6500 0.0000 1.0000
27.7000 0.9517 1.0000
27.7500 0.0000 1.0000
27.8000 0.0000 1.0000
27.8500 2.0669 1.0000
27.9000 1.9969 1.0000
27.9500 2.4360 1.0000
28.0000 0.0000 1.0000
28.0500 0.0000 1.0000
28.1000 0.0000 1.0000
28.1500 2.8759 1.0000
28.2000 2.0330 1.0000
28.2500 4.0038 1.0000
28.3000 1.3692 1.0000
28.3500 1.0401 1.0000
28.4000 0.0000 1.0000
28.4500 0.9613 1.0000
28.5000 0.0000 1.0000
28.5500 0.0000 1.0000
28.6000 1.0197 1.0000
28.6500 1.0295 1.0000
28.7000 4.7604 1.0000
28.7500 1.5284 1.0000
28.8000 1.0155 1.0000
28.8500 1.9553 1.0000
28.9000 0.0000 1.0000
28.9500 0.9861 1.0000
29.0000 1.0301 1.0000
29.0500 0.0000 1.0000
29.1000 0.0000 1.0000
29.1500 0.0000 1.0000
29.2000 2.3424 1.0000
29.2500 0.3290 1.0000
29.3000 1.0178 1.0000
29.3500 1.9825 1.0000
29.4000 1.0067 1.0000
29.4500 0.9460 1.0000
29.5000 0.9749 1.0000
29.5500 1.0558 1.0000
29.6000 0.3455 1.0000
29.6500 0.3402 1.0000
29.7000 1.0216 1.0000
29.7500 0.9971 1.0000
29.8000 0.3266 1.0000
29.8500 1.0186 1.0000
29.9000 2.0482 1.0000
29.9500 0.9974 1.0000
30.0000 0.0000 1.0000
30.0500 2.1362 1.0000
30.1000 0.0000 1.0000
30.1500 0.9768 1.0000
30.2000 2.3056 1.0000
30.2500 1.9898 1.0000
30.3000 0.9937 1.0000
30.3500 0.0000 1.0000
30.4000 1.3761 1.0000
30.4500 0.0000 1.0000
30.5000 0.0000 1.0000
30.5500 0.9613 1.0000
30.6000 1.0377 1.0000
30.6500 0.9565 1.0000
30.7000 0.0000 1.0000
30.7500 3.0932 1.0000
30.8000 0.0000 1.0000
30.8500 0.9620 1.0000
30.9000 3.3352 1.0000
30.9500 3.0197 1.0000
31.0000 1.3537 1.0000
31.0500 1.0041 1.0000
31.1000 1.0219 1.0000
31.1500 0.0000 1.0000
31.2000 1.3585 1.0000
31.2500 0.0000 1.0000
31.3000 0.0000 1.0000
31.3500 1.0709 1.0000
31.4000 0.0000 1.0000
31.4500 1.3644 1.0000
31.5000 1.0265 1.0000
31.5500 0.9934 1.0000
31.6000 3.0224 1.0000
31.6500 0.9997 1.0000
31.7000 1.0514 1.0000
31.7500 1.9401 1.0000
31.8000 0.0000 1.0000
31.8500 0.0000 1.0000
31.9000 0.0000 1.0000
31.9500 3.0530 1.0000
32.0000 0.0000 1.0000
32.0500 2.0378 1.0000
32.1000 1.0655 1.0000
32.1500 0.0000 1.0000
32.2000 0.0000 1.0000
32.2500 0.0000 1.0000
32.3000 0.9687 1.0000
32.3500 1.0079 1.0000
32.4000 0.9919 1.0000
32.4500 0.9912 1.0000
32.5000 0.0000 1.0000
32.5500 0.0000 1.0000
32.6000 1.0300 1.0000
32.6500 0.0000 1.0000
32.7000 0.9846 1.0000
32.7500 0.0000 1.0000
32.8000 2.0541 1.0000
32.8500 3.0388 1.0000
32.9000 1.0531 1.0000
32.9500 3.0048 1.0000
33.0000 0.9946 1.0000
33.0500 0.9620 1.0000
33.1000 0.0000 1.0000
33.1500 3.0888 1.0000
33.2000 1.0159 1.0000
33.2500 0.9684 1.0000
33.3000 0.0000 1.0000
33.3500 0.0000 1.0000
33.4000 1.9465 1.0000
33.4500 0.0000 1.0000
33.5000 1.3907 1.0000
33.5500 1.0452 1.0000
33.6000 1.0093 1.0000
33.6500 0.0000 1.0000
33.7000 1.7111 1.0000
33.7500 0.9840 1.0000
33.8000 0.0000 1.0000
33.8500 1.0262 1.0000
33.9000 0.0000 1.0000
33.9500 1.9911 1.0000
34.0000 1.0461 1.0000
34.0500 0.3236 1.0000
34.1000 0.3306 1.0000
34.1500 1.3252 1.0000
34.2000 2.0258 1.0000
34.2500 0.0000 1.0000
34.3000 0.0000 1.0000
34.3500 0.0000 1.0000
34.4000 0.0000 1.0000
34.4500 0.0000 1.0000
34.5000 0.9889 1.0000
34.5500 1.7340 1.0000
34.6000 1.0692 1.0000
34.6500 2.0160 1.0000
34.7000 0.9613 1.0000
34.7500 0.0000 1.0000
34.8000 0.9460 1.0000
34.8500 0.0000 1.0000
34.9000 0.0000 1.0000
34.9500 2.0531 1.0000
35.0000 0.0000 1.0000
35.0500 0.9683 1.0000
35.1000 0.9860 1.0000
35.1500 0.0000 1.0000
35.2000 0.0000 1.0000
35.2500 2.0083 1.0000
35.3000 2.0571 1.0000
35.3500 1.2861 1.0000
35.4000 1.0093 1.0000
35.4500 0.3258 1.0000
35.5000 2.0200 1.0000
35.5500 0.0000 1.0000
35.6000 0.0000 1.0000
35.6500 0.0000 1.0000
35.7000 0.0000 1.0000
35.7500 1.0508 1.0000
35.8000 2.0043 1.0000
35.8500 0.0000 1.0000
35.9000 2.2842 1.0000
35.9500 2.0349 1.0000
36.0000 1.3497 1.0000
36.0500 0.0000 1.0000
36.1000 0.0000 1.0000
36.1500 1.0570 1.0000
36.2000 0.0000 1.0000
36.2500 0.0000 1.0000
36.3000 1.3873 1.0000
36.3500 3.5123 1.0000
36.4000 0.0000 1.0000
36.4500 2.0688 1.0000
36.5000 1.0358 1.0000
36.5500 0.0000 1.0000
36.6000 1.5116 1.0000
36.6500 0.9880 1.0000
36.7000 1.0071 1.0000
36.7500 1.0093 1.0000
36.8000 1.9877 1.0000
36.8500 0.9946 1.0000
36.9000 0.0000 1.0000
36.9500 0.0000 1.0000
37.0000 0.9811 1.0000
37.0500 0.0000 1.0000
37.1000 0.0000 1.0000
37.1500 0.0000 1.0000
37.2000 0.0000 1.0000
37.2500 2.0279 1.0000
37.3000 1.0055 1.0000
37.3500 2.0154 1.0000
37.4000 1.0047 1.0000
37.4500 1.0197 1.0000
37.5000 0.0000 1.0000
37.5500 0.3236 1.0000
37.6000 1.0317 1.0000
37.6500 0.9832 1.0000
37.7000 1.9941 1.0000
37.7500 1.6663 1.0000
37.8000 0.0000 1.0000
37.8500 0.0000 1.0000
37.9000 2.9703 1.0000
37.9500 0.0000 1.0000
38.0000 0.9846 1.0000
38.0500 1.1257 1.0000
38.1000 1.0669 1.0000
38.1500 1.0096 1.0000
38.2000 0.0000 1.0000
38.2500 0.0000 1.0000
38.3000 0.0000 1.0000
38.3500 0.3311 1.0000
38.4000 0.0000 1.0000
38.4500 3.9209 1.0000
38.5000 1.9920 1.0000
38.5500 1.0055 1.0000
38.6000 0.0000 1.0000
38.6500 1.9972 1.0000
38.7000 0.0000 1.0000
38.7500 0.0000 1.0000
38.8000 0.0000 1.0000
38.8500 0.3356 1.0000
38.9000 0.9986 1.0000
38.9500 2.9299 1.0000
39.0000 2.0215 1.0000
39.0500 0.3403 1.0000
39.1000 1.0485 1.0000
39.1500 0.0000 1.0000
39.2000 0.0000 1.0000
39.2500 0.0000 1.0000
39.3000 0.0000 1.0000
39.3500 1.0148 1.0000
39.4000 0.0000 1.0000
39.4500 0.6567 1.0000
39.5000 3.0061 1.0000
39.5500 0.0000 1.0000
39.6000 3.0099 1.0000
39.6500 0.9971 1.0000
39.7000 2.0291 1.0000
39.7500 2.0201 1.0000
39.8000 1.3974 1.0000
39.8500 0.0000 1.0000
39.9000 0.9683 1.0000
39.9500 2.0580 1.0000
40.0000 1.0287 1.0000
40.0500 0.0000 1.0000
40.1000 1.3534 1.0000
40.1500 0.0000 1.0000
40.2000 0.0000 1.0000
40.2500 1.0319 1.0000
40.3000 0.3274 1.0000
40.3500 0.0000 1.0000
40.4000 0.0000 1.0000
40.4500 1.9503 1.0000
40.5000 0.0000 1.0000
40.5500 3.0083 1.0000
40.6000 2.0338 1.0000
40.6500 0.9921 1.0000
40.7000 1.0069 1.0000
40.7500 0.0000 1.0000
40.8000 0.0000 1.0000
40.8500 0.0000 1.0000
40.9000 1.0120 1.0000
40.9500 0.0000 1.0000
41.0000 0.0000 1.0000
41.0500 0.0000 1.0000
41.1000 1.0597 1.0000
41.1500 0.0000 1.0000
41.2000 2.0198 1.0000
41.2500 1.5669 1.0000
41.3000 0.0000 1.0000
41.3500 0.0000 1.0000
41.4000 0.0000 1.0000
41.4500 0.3211 1.0000
41.5000 0.3311 1.0000
41.5500 0.0000 1.0000
41.6000 0.9999 1.0000
41.6500 0.0000 1.0000
41.7000 2.0587 1.0000
41.7500 1.3077 1.0000
41.8000 1.0041 1.0000
41.8500 1.3485 1.0000
41.9000 0.3147 1.0000
41.9500 0.0000 1.0000
42.0000 0.0000 1.0000
42.0500 1.0289 1.0000
42.1000 0.3288 1.0000
42.1500 2.0380 1.0000
42.2000 0.0000 1.0000
42.2500 1.0143 1.0000
42.3000 0.9924 1.0000
42.3500 0.3370 1.0000
42.4000 0.0000 1.0000
42.4500 1.0485 1.0000
42.5000 0.9954 1.0000
42.5500 0.0000 1.0000
42.6000 0.9704 1.0000
42.6500 0.0000 1.0000
42.7000 0.0000 1.0000
42.7500 2.3375 1.0000
42.8000 0.0000 1.0000
42.8500 1.2983 1.0000
42.9000 2.0211 1.0000
42.9500 0.9927 1.0000
43.0000 2.2805 1.0000
43.0500 2.5286 1.0000
43.1000 2.0220 1.0000
43.1500 0.3274 1.0000
43.2000 1.0269 1.0000
43.2500 0.0000 1.0000
43.3000 0.0000 1.0000
43.3500 0.0000 1.0000
43.4000 0.0000 1.0000
43.4500 0.3258 1.0000
43.5000 0.0000 1.0000
43.5500 4.1054 1.0000
43.6000 0.0000 1.0000
43.6500 0.9622 1.0000
43.7000 1.0675 1.0000
43.7500 1.0359 1.0000
43.8000 0.0000 1.0000
43.8500 0.0000 1.0000
43.9000 0.9643 1.0000
43.9500 0.9608 1.0000
44.0000 0.0000 1.0000
44.0500 0.0000 1.0000
44.1000 0.0000 1.0000
44.1500 0.0000 1.0000
44.2000 1.0379 1.0000
44.2500 0.9954 1.0000
44.3000 3.2699 1.0000
44.3500 1.5142 1.0000
44.4000 1.9649 1.0000
44.4500 0.9784 1.0000
44.5000 0.0000 1.0000
44.5500 2.0065 1.0000
44.6000 1.9744 1.0000
44.6500 2.0246 1.0000
44.7000 3.0591 1.0000
44.7500 1.0193 1.0000
44.8000 0.0000 1.0000
44.8500 0.0000 1.0000
44.9000 0.3403 1.0000
44.9500 2.0297 1.0000
45.0000 0.0000 1.0000
45.0500 0.0000 1.0000
45.1000 0.9987 1.0000
45.1500 1.0152 1.0000
45.2000 0.0000 1.0000
45.2500 0.3274 1.0000
45.3000 0.9970 1.0000
45.3500 0.3406 1.0000
45.4000 0.0000 1.0000
45.4500 0.0000 1.0000
45.5000 2.0875 1.0000
45.5500 1.3610 1.0000
45.6000 0.0000 1.0000
45.6500 0.0000 1.0000
45.7000 0.0000 1.0000
45.7500 2.1999 1.0000
45.8000 0.9821 1.0000
45.8500 0.3341 1.0000
45.9000 0.0000 1.0000
45.9500 1.0066 1.0000
46.0000 1.0624 1.0000
46.0500 1.3368 1.0000
46.1000 2.0014 1.0000
46.1500 1.9988 1.0000
46.2000 1.0042 1.0000
46.2500 0.3288 1.0000
46.3000 0.0000 1.0000
46.3500 1.0293 1.0000
46.4000 0.9863 1.0000
46.4500 1.3733 1.0000
46.5000 1.0655 1.0000
46.5500 1.0130 1.0000
46.6000 2.0499 1.0000
46.6500 0.9759 1.0000
46.7000 1.0214 1.0000
46.7500 0.9824 1.0000
46.8000 0.0000 1.0000
46.8500 2.0259 1.0000
46.9000 0.3410 1.0000
46.9500 0.0000 1.0000
47.0000 0.0000 1.0000
47.0500 0.9639 1.0000
47.1000 0.0000 1.0000
47.1500 0.0000 1.0000
47.2000 1.3166 1.0000
47.2500 2.1108 1.0000
47.3000 1.0148 1.0000
47.3500 0.9918 1.0000
47.4000 0.0000 1.0000
47.4500 0.0000 1.0000
47.5000 0.0000 1.0000
47.5500 1.0029 1.0000
47.6000 0.0000 1.0000
47.6500 4.1062 1.0000
47.7000 0.0000 1.0000
47.7500 0.0000 1.0000
47.8000 1.0020 1.0000
47.8500 0.0000 1.0000
47.9000 0.0000 1.0000
47.9500 0.0000 1.0000
48.0000 2.0636 1.0000
48.0500 2.0599 1.0000
48.1000 1.0153 1.0000
48.1500 0.0000 1.0000
48.2000 0.0000 1.0000
48.2500 0.0000 1.0000
48.3000 1.0153 1.0000
48.3500 0.0000 1.0000
48.4000 0.0000 1.0000
48.4500 0.9859 1.0000
48.5000 0.0000 1.0000
48.5500 0.0000 1.0000
48.6000 0.9926 1.0000
48.6500 0.9875 1.0000
48.7000 0.0000 1.0000
48.7500 3.0102 1.0000
48.8000 0.9826 1.0000
48.8500 0.9937 1.0000
48.9000 0.9828 1.0000
48.9500 2.9676 1.0000
49.0000 0.0000 1.0000
49.0500 1.0364 1.0000
49.1000 0.0000 1.0000
49.1500 0.0000 1.0000
49.2000 3.5606 1.0000
49.2500 0.0000 1.0000
49.3000 0.9987 1.0000
49.3500 0.0000 1.0000
49.4000 0.0000 1.0000
49.4500 1.3044 1.0000
49.5000 0.0000 1.0000
49.5500 0.0000 1.0000
49.6000 2.2840 1.0000
49.6500 0.0000 1.0000
49.7000 0.0000 1.0000
49.7500 1.0338 1.0000
49.8000 1.3441 1.0000
49.8500 2.0430 1.0000
49.9000 0.0000 1.0000
49.9500 0.9843 1.0000
50.0000 0.0000 1.0000
50.0500 2.9929 1.0000
50.1000 0.0000 1.0000
50.1500 0.9668 1.0000
50.2000 1.0692 1.0000
50.2500 0.9942 1.0000
50.3000 2.0022 1.0000
50.3500 0.0000 1.0000
50.4000 0.0000 1.0000
50.4500 2.0136 1.0000
50.5000 2.5435 1.0000
50.5500 3.0374 1.0000
50.6000 1.9387 1.0000
50.6500 1.0388 1.0000
50.7000 0.0000 1.0000
50.7500 1.3420 1.0000
50.8000 0.0000 1.0000
50.8500 0.0000 1.0000
50.9000 1.0226 1.0000
50.9500 1.0194 1.0000
51.0000 1.2768 1.0000
51.0500 0.9639 1.0000
51.1000 0.0000 1.0000
51.1500 0.0000 1.0000
51.2000 2.0599 1.0000
51.2500 0.0000 1.0000
51.3000 3.0348 1.0000
51.3500 0.9921 1.0000
51.4000 0.0000 1.0000
51.4500 0.0000 1.0000
51.5000 0.0000 1.0000
51.5500 1.0033 1.0000
51.6000 0.0000 1.0000
51.6500 0.0000 1.0000
51.7000 1.0274 1.0000
51.7500 1.0335 1.0000
51.8000 0.9446 1.0000
51.8500 1.0197 1.0000
51.9000 3.0240 1.0000
51.9500 0.9852 1.0000
52.0000 0.0000 1.0000
52.0500 2.0317 1.0000
52.1000 1.0006 1.0000
52.1500 0.0000 1.0000
52.2000 0.0000 1.0000
52.2500 0.0000 1.0000
52.3000 1.0226 1.0000
52.3500 0.3274 1.0000
52.4000 1.0048 1.0000
52.4500 0.0000 1.0000
52.5000 2.0046 1.0000
52.5500 0.9934 1.0000
52.6000 1.0100 1.0000
52.6500 0.0000 1.0000
52.7000 0.0000 1.0000
52.7500 1.0123 1.0000
52.8000 0.9935 1.0000
52.8500 0.0000 1.0000
52.9000 2.0206 1.0000
52.9500 1.9966 1.0000
53.0000 2.0160 1.0000
53.0500 1.0481 1.0000
53.1000 0.0000 1.0000
53.1500 1.3327 1.0000
53.2000 1.0241 1.0000
53.2500 0.0000 1.0000
53.3000 0.9989 1.0000
53.3500 0.0000 1.0000
53.4000 0.9927 1.0000
53.4500 0.0000 1.0000
53.5000 0.0000 1.0000
53.5500 0.0000 1.0000
53.6000 0.0000 1.0000
53.6500 2.0071 1.0000
53.7000 1.0001 1.0000
53.7500 0.0000 1.0000
53.8000 0.0000 1.0000
53.8500 0.3306 1.0000
53.9000 3.0798 1.0000
53.9500 1.0388 1.0000
54.0000 2.0618 1.0000
54.0500 1.9979 1.0000
54.1000 0.0000 1.0000
54.1500 1.0655 1.0000
54.2000 1.3491 1.0000
54.2500 0.0000 1.0000
54.3000 1.0098 1.0000
54.3500 1.9696 1.0000
54.4000 3.0521 1.0000
54.4500 0.9526 1.0000
54.5000 1.0218 1.0000
54.5500 0.0000 1.0000
54.6000 2.1198 1.0000
54.6500 0.0000 1.0000
54.7000 0.0000 1.0000
54.7500 1.0418 1.0000
54.8000 0.0000 1.0000
54.8500 0.9921 1.0000
54.9000 0.0000 1.0000
54.9500 1.0487 1.0000
55.0000 0.0000 1.0000
55.0500 1.0026 1.0000
55.1000 0.9902 1.0000
55.1500 0.0000 1.0000
55.2000 1.9913 1.0000
55.2500 2.0097 1.0000
55.3000 0.0000 1.0000
55.3500 0.0000 1.0000
55.4000 1.0667 1.0000
55.4500 0.0000 1.0000
55.5000 0.9627 1.0000
55.5500 1.3056 1.0000
55.6000 3.0018 1.0000
55.6500 0.9758 1.0000
55.7000 1.3717 1.0000
55.7500 0.0000 1.0000
55.8000 1.0618 1.0000
55.8500 0.9846 1.0000
55.9000 1.3211 1.0000
55.9500 3.9442 1.0000
56.0000 4.0160 1.0000
56.0500 0.9699 1.0000
56.1000 2.0479 1.0000
56.1500 0.0000 1.0000
56.2000 1.0421 1.0000
56.2500 1.3427 1.0000
56.3000 0.0000 1.0000
56.3500 0.9914 1.0000
56.4000 0.0000 1.0000
56.4500 0.0000 1.0000
56.5000 0.9905 1.0000
56.5500 0.0000 1.0000
56.6000 0.0000 1.0000
56.6500 0.9932 1.0000
56.7000 0.0000 1.0000
56.7500 0.0000 1.0000
56.8000 0.0000 1.0000
56.8500 2.4046 1.0000
56.9000 0.0000 1.0000
56.9500 1.9623 1.0000
57.0000 0.3253 1.0000
57.0500 0.0000 1.0000
57.1000 1.0268 1.0000
57.1500 0.9637 1.0000
57.2000 0.0000 1.0000
57.2500 0.0000 1.0000
57.3000 0.0000 1.0000
57.3500 1.0050 1.0000
57.4000 2.0494 1.0000
57.4500 2.0250 1.0000
57.5000 1.0335 1.0000
57.5500 0.0000 1.0000
57.6000 0.0000 1.0000
57.6500 0.3356 1.0000
57.7000 3.5421 1.0000
57.7500 0.0000 1.0000
57.8000 1.0461 1.0000
57.8500 0.9832 1.0000
57.9000 2.1129 1.0000
57.9500 0.9620 1.0000
58.0000 0.0000 1.0000
58.0500 0.0000 1.0000
58.1000 2.9967 1.0000
58.1500 1.9366 1.0000
58.2000 0.9492 1.0000
58.2500 1.0464 1.0000
58.3000 1.0226 1.0000
58.3500 0.0000 1.0000
58.4000 0.0000 1.0000
58.4500 0.0000 1.0000
58.5000 1.1308 1.0000
58.5500 2.1266 1.0000
58.6000 1.9756 1.0000
58.6500 1.9689 1.0000
58.7000 1.5105 1.0000
58.7500 0.9425 1.0000
58.8000 0.9768 1.0000
58.8500 0.0000 1.0000
58.9000 0.0000 1.0000
58.9500 0.0000 1.0000
59.0000 0.0000 1.0000
59.0500 1.0537 1.0000
59.1000 0.9971 1.0000
59.1500 0.0000 1.0000
59.2000 0.9911 1.0000
59.2500 2.3482 1.0000
59.3000 0.9967 1.0000
59.3500 1.0388 1.0000
59.4000 1.0089 1.0000
59.4500 0.0000 1.0000
59.5000 0.9924 1.0000
59.5500 1.0596 1.0000
59.6000 2.0519 1.0000
59.6500 0.9976 1.0000
59.7000 1.9559 1.0000
59.7500 2.0062 1.0000
59.8000 0.9460 1.0000
59.8500 1.9993 1.0000
59.9000 0.3258 1.0000
59.9500 0.0000 1.0000
60.0000 0.9993 1.0000
60.0500 1.0161 1.0000
60.1000 1.0166 1.0000
60.1500 0.3319 1.0000
60.2000 0.0000 1.0000
60.2500 2.5127 1.0000
60.3000 0.9608 1.0000
60.3500 1.0463 1.0000
60.4000 1.0268 1.0000
60.4500 0.0000 1.0000
60.5000 1.3615 1.0000
60.5500 1.0193 1.0000
60.6000 0.9870 1.0000
60.6500 0.3465 1.0000
60.7000 0.9743 1.0000
60.7500 2.9873 1.0000
60.8000 2.0709 1.0000
60.8500 1.4955 1.0000
60.9000 2.0337 1.0000
60.9500 0.0000 1.0000
61.0000 0.0000 1.0000
61.0500 1.0181 1.0000
61.1000 2.1517 1.0000
61.1500 1.0087 1.0000
61.2000 0.9775 1.0000
61.2500 1.9746 1.0000
61.3000 1.0152 1.0000
61.3500 0.3408 1.0000
61.4000 3.0111 1.0000
61.4500 1.0090 1.0000
61.5000 0.3410 1.0000
61.5500 1.0052 1.0000
61.6000 2.0677 1.0000
61.6500 0.0000 1.0000
61.7000 1.3087 1.0000
61.7500 3.0230 1.0000
61.8000 0.0000 1.0000
61.8500 0.0000 1.0000
61.9000 0.9919 1.0000
61.9500 2.0273 1.0000
62.0000 0.0000 1.0000
62.0500 2.5767 1.0000
62.1000 1.9993 1.0000
62.1500 0.9950 1.0000
62.2000 1.9442 1.0000
62.2500 1.9929 1.0000
62.3000 0.0000 1.0000
62.3500 1.0172 1.0000
62.4000 2.1039 1.0000
62.4500 1.6013 1.0000
62.5000 1.0306 1.0000
62.5500 1.0485 1.0000
62.6000 4.0675 1.0000
62.6500 2.0593 1.0000
62.7000 1.0442 1.0000
62.7500 1.3182 1.0000
62.8000 1.0561 1.0000
62.8500 1.9804 1.0000
62.9000 3.9057 1.0000
62.9500 6.0049 1.0000
63.0000 0.3368 1.0000
63.0500 2.2833 1.0000
63.1000 1.0328 1.0000
63.1500 1.9750 1.0000
63.2000 1.0123 1.0000
63.2500 1.0141 1.0000
63.3000 1.0059 1.0000
63.3500 1.0359 1.0000
63.4000 0.0000 1.0000
63.4500 3.5404 1.0000
63.5000 1.9930 1.0000
63.5500 0.0000 1.0000
63.6000 2.9504 1.0000
63.6500 0.9924 1.0000
63.7000 0.0000 1.0000
63.7500 2.0202 1.0000
63.8000 1.0152 1.0000
63.8500 4.1032 1.0000
63.9000 1.2731 1.0000
63.9500 2.0258 1.0000
64.0000 4.0544 1.0000
64.0500 1.0108 1.0000
64.1000 3.8555 1.0000
64.1500 2.0641 1.0000
64.2000 0.9943 1.0000
64.2500 3.1014 1.0000
64.3000 2.1307 1.0000
64.3500 5.9930 1.0000
64.4000 1.3112 1.0000
64.4500 2.9159 1.0000
64.5000 3.9760 1.0000
64.5500 1.3036 1.0000
64.6000 0.9920 1.0000
64.6500 1.0037 1.0000
64.7000 1.0335 1.0000
64.7500 2.0370 1.0000
64.8000 1.9807 1.0000
64.8500 5.2142 1.0000
64.9000 1.9780 1.0000
64.9500 2.3485 1.0000
65.0000 0.9914 1.0000
65.0500 4.0465 1.0000
65.1000 5.0388 1.0000
65.1500 2.0203 1.0000
65.2000 1.2949 1.0000
65.2500 6.0440 1.0000
65.3000 0.0000 1.0000
65.3500 3.0527 1.0000
65.4000 3.0520 1.0000
65.4500 5.3907 1.0000
65.5000 4.4720 1.0000
65.5500 5.9864 1.0000
65.6000 1.9733 1.0000
65.6500 3.2808 1.0000
65.7000 3.9594 1.0000
65.7500 4.6443 1.0000
65.8000 4.9827 1.0000
65.8500 5.6380 1.0000
65.9000 7.3306 1.0000
65.9500 3.1044 1.0000
66.0000 7.1848 1.0000
66.0500 6.2240 1.0000
66.1000 10.6327 1.0000
66.1500 7.0301 1.0000
66.2000 8.3384 1.0000
66.2500 3.4196 1.0000
66.3000 6.0748 1.0000
66.3500 6.9461 1.0000
66.4000 9.2780 1.0000
66.4500 5.9819 1.0000
66.5000 9.3201 1.0000
66.5500 12.2162 1.0000
66.6000 6.9481 1.0000
66.6500 6.3254 1.0000
66.7000 3.6799 1.0000
66.7500 9.5606 1.0000
66.8000 11.2168 1.0000
66.8500 6.3068 1.0000
66.9000 16.0864 1.0000
66.9500 16.0251 1.0000
67.0000 7.0202 1.0000
67.0500 14.9732 1.0000
67.1000 9.8470 1.0000
67.1500 14.6067 1.0000
67.2000 11.4269 1.0000
67.2500 9.8391 1.0000
67.3000 11.0346 1.0000
67.3500 14.3200 1.0000
67.4000 14.5670 1.0000
67.4500 12.0932 1.0000
67.5000 22.6938 1.0000
67.5500 19.7048 1.0000
67.6000 28.0987 1.0000
67.6500 12.6831 1.0000
67.7000 19.4821 1.0000
67.7500 25.7119 1.0000
67.8000 31.4765 1.0000
67.8500 20.4301 1.0000
67.9000 28.7111 1.0000
67.9500 36.1029 1.0000
68.0000 27.4931 1.0000
68.0500 37.1899 1.0000
68.1000 39.1661 1.0000
68.1500 40.5238 1.0000
68.2000 41.7114 1.0000
68.2500 55.1741 1.0000
68.3000 56.7476 1.0000
68.3500 54.6687 1.0000
68.4000 65.6449 1.0000
68.4500 76.9095 1.0000
68.5000 78.0242 1.0000
68.5500 82.5945 1.0000
68.6000 113.0504 1.0000
68.6500 133.1887 1.0000
68.7000 145.1217 1.0000
68.7500 179.5258 1.0000
68.8000 199.7826 1.0000
68.8500 233.2568 1.0000
68.9000 302.3305 1.0000
68.9500 332.8313 1.0000
69.0000 390.2874 1.0000
69.0500 403.5747 1.0000
69.1000 424.4988 1.0000
69.1500 429.2492 1.0000
69.2000 405.2108 1.0000
69.2500 336.7133 1.0000
69.3000 300.4538 1.0000
69.3500 285.5943 1.0000
69.4000 222.8134 1.0000
69.4500 204.5937 1.0000
69.5000 198.4070 1.0000
69.5500 172.4585 1.0000
69.6000 117.5696 1.0000
69.6500 121.5415 1.0000
69.7000 78.6606 1.0000
69.7500 96.1129 1.0000
69.8000 76.2623 1.0000
69.8500 68.0645 1.0000
69.9000 66.3368 1.0000
69.9500 61.7317 1.0000
70.0000 53.3690 1.0000
70.0500 36.1344 1.0000
70.1000 39.9935 1.0000
70.1500 36.2131 1.0000
70.2000 36.0751 1.0000
70.2500 35.8188 1.0000
70.3000 19.2307 1.0000
70.3500 38.1564 1.0000
70.4000 22.6384 1.0000
70.4500 19.0235 1.0000
70.5000 26.9357 1.0000
70.5500 22.2663 1.0000
70.6000 16.5642 1.0000
70.6500 27.1054 1.0000
70.7000 8.3066 1.0000
70.7500 18.3831 1.0000
70.8000 18.1352 1.0000
70.8500 9.0694 1.0000
70.9000 14.1792 1.0000
70.9500 16.1440 1.0000
71.0000 11.1789 1.0000
71.0500 12.1522 1.0000
71.1000 9.1525 1.0000
71.1500 15.0532 1.0000
71.2000 6.4141 1.0000
71.2500 3.3378 1.0000
71.3000 15.2379 1.0000
71.3500 6.0402 1.0000
71.4000 11.5539 1.0000
71.4500 5.4723 1.0000
71.5000 5.0286 1.0000
71.5500 8.8998 1.0000
71.6000 7.3253 1.0000
71.6500 12.0772 1.0000
71.7000 1.9739 1.0000
71.7500 10.8449 1.0000
71.8000 6.0006 1.0000
71.8500 13.5436 1.0000
71.9000 3.8599 1.0000
71.9500 4.0201 1.0000
72.0000 7.1746 1.0000
72.0500 7.9452 1.0000
72.1000 3.1238 1.0000
72.1500 5.3690 1.0000
72.2000 2.0820 1.0000
72.2500 6.6715 1.0000
72.3000 2.0007 1.0000
72.3500 4.4173 1.0000
72.4000 5.0170 1.0000
72.4500 5.3608 1.0000
72.5000 1.9877 1.0000
72.5500 5.8478 1.0000
72.6000 5.0953 1.0000
72.6500 0.9896 1.0000
72.7000 4.0845 1.0000
72.7500 2.3543 1.0000
72.8000 7.0594 1.0000
72.8500 1.0207 1.0000
72.9000 8.9847 1.0000
72.9500 3.9016 1.0000
73.0000 7.1484 1.0000
73.0500 2.0419 1.0000
73.1000 6.1333 1.0000
73.1500 6.1078 1.0000
73.2000 3.2952 1.0000
73.2500 1.3855 1.0000
73.3000 2.9502 1.0000
73.3500 2.9861 1.0000
73.4000 6.6575 1.0000
73.4500 5.4357 1.0000
73.5000 6.0308 1.0000
73.5500 0.9558 1.0000
73.6000 6.4708 1.0000
73.6500 2.0578 1.0000
73.7000 2.0505 1.0000
73.7500 5.0722 1.0000
73.8000 2.3731 1.0000
73.8500 3.9449 1.0000
73.9000 3.0044 1.0000
73.9500 0.0000 1.0000
74.0000 4.0559 1.0000
74.0500 4.9474 1.0000
74.1000 4.0918 1.0000
74.1500 4.5431 1.0000
74.2000 2.0369 1.0000
74.2500 3.0036 1.0000
74.3000 7.0752 1.0000
74.3500 0.9501 1.0000
74.4000 1.9986 1.0000
74.4500 0.9749 1.0000
74.5000 0.9933 1.0000
74.5500 2.0088 1.0000
74.6000 5.0294 1.0000
74.6500 0.0000 1.0000
74.7000 2.0102 1.0000
74.7500 4.0357 1.0000
74.8000 1.9608 1.0000
74.8500 0.9937 1.0000
74.9000 3.0011 1.0000
74.9500 1.0253 1.0000
75.0000 0.9949 1.0000
75.0500 3.0703 1.0000
75.1000 3.5182 1.0000
75.1500 1.9553 1.0000
75.2000 0.0000 1.0000
75.2500 2.0732 1.0000
75.3000 3.3224 1.0000
75.3500 2.3906 1.0000
75.4000 1.0063 1.0000
75.4500 1.0531 1.0000
75.5000 1.9970 1.0000
75.5500 0.0000 1.0000
75.6000 1.9969 1.0000
75.6500 2.9986 1.0000
75.7000 4.9848 1.0000
75.7500 5.0628 1.0000
75.8000 2.0256 1.0000
75.8500 1.9708 1.0000
75.9000 2.9974 1.0000
75.9500 5.0653 1.0000
76.0000 0.9775 1.0000
76.0500 2.0005 1.0000
76.1000 0.9526 1.0000
76.1500 2.5088 1.0000
76.2000 1.9781 1.0000
76.2500 2.0472 1.0000
76.3000 1.0196 1.0000
76.3500 1.0098 1.0000
76.4000 0.9902 1.0000
76.4500 1.9674 1.0000
76.5000 0.9620 1.0000
76.5500 3.0660 1.0000
76.6000 0.9894 1.0000
76.6500 3.3313 1.0000
76.7000 0.9843 1.0000
76.7500 2.0379 1.0000
76.8000 0.0000 1.0000
76.8500 1.9826 1.0000
76.9000 5.9757 1.0000
76.9500 0.0000 1.0000
77.0000 2.0455 1.0000
77.0500 3.0012 1.0000
77.1000 1.0034 1.0000
77.1500 0.0000 1.0000
77.2000 0.9693 1.0000
77.2500 3.0023 1.0000
77.3000 1.0520 1.0000
77.3500 0.0000 1.0000
77.4000 0.9897 1.0000
77.4500 0.0000 1.0000
77.5000 6.2015 1.0000
77.5500 1.0502 1.0000
77.6000 2.3198 1.0000
77.6500 2.0025 1.0000
77.7000 1.0048 1.0000
77.7500 1.9556 1.0000
77.8000 1.0144 1.0000
77.8500 1.3513 1.0000
77.9000 3.1294 1.0000
77.9500 0.0000 1.0000
78.0000 1.0102 1.0000
78.0500 1.0002 1.0000
78.1000 0.0000 1.0000
78.1500 0.0000 1.0000
78.2000 1.1017 1.0000
78.2500 0.0000 1.0000
78.3000 0.9513 1.0000
78.3500 4.0171 1.0000
78.4000 0.0000 1.0000
78.4500 3.6842 1.0000
78.5000 0.9726 1.0000
78.5500 0.0000 1.0000
78.6000 1.0041 1.0000
78.6500 1.0359 1.0000
78.7000 1.9799 1.0000
78.7500 0.0000 1.0000
78.8000 2.0107 1.0000
78.8500 0.0000 1.0000
78.9000 0.9923 1.0000
78.9500 0.9988 1.0000
79.0000 3.9711 1.0000
79.0500 1.0432 1.0000
79.1000 3.9353 1.0000
79.1500 0.9745 1.0000
79.2000 1.9702 1.0000
79.2500 2.0771 1.0000
79.3000 2.0969 1.0000
79.3500 2.0948 1.0000
79.4000 3.0422 1.0000
79.4500 1.0319 1.0000
79.5000 0.9889 1.0000
79.5500 0.0000 1.0000
79.6000 0.0000 1.0000
79.6500 0.0000 1.0000
79.7000 1.0199 1.0000
79.7500 2.9785 1.0000
79.8000 3.0168 1.0000
79.8500 1.0174 1.0000
79.9000 2.0655 1.0000
79.9500 1.0093 1.0000
80.0000 1.0669 1.0000
*RAS_INT_END
*RAS_DATA_END
*DSC_DATA_END