File: XRD/data/substrates/sub_glass_sample_8.csv
[Measurement conditions]
Sample identification,BFO_Glass_Test
Comment - 1,"Configuration=Spinner-1, Owner=User-1, Creation date=30/06/2014 21:58:06"
Comment - 2,"Goniometer=PW3050/60 (Theta/2Theta); Minimum step size 2Theta:0.001; Minimum step size Omega:0.001"
Comment - 3,"Sample stage=Spinner PW3064"
Comment - 4,"Diffractometer system=XPERT-PRO"
Comment - 5,"Measurement program=C:\XRD Data\Finlay\ZnO_test.xrdmp, Identifier={BBCAE591-F20A-49C9-93EC-615EC0561F4C}"
Comment - 6,"Batch program=C:\XRD Data\Finlay\2023-02-15_BatchSamplesZnOSteelBFOGlass.xrdmp, Identifier={B3E1DC79-A0EB-4A26-AF34-6AF87A09E2E1}"
Anode material,Cu
K-Alpha1 wavelength,1.5405980
K-Alpha2 wavelength,1.5444260
Ratio K-Alpha2/K-Alpha1,0.000
Divergence slit,Fixed,0.5
Monochromator used,YES
Generator voltage, 40
Tube current, 40
File date and time,15/Feb/2023 10:13
Unit cell,
h k l, 0 0 0
Scan axis,Gonio
Scan range,5.000000001,100.003564139
Scan step size,0.0041778
No. of points, 22740
Scan type,CONTINUOUS
Time per step,13.970
[Scan points]
Angle, TimePerStep, Intensity, ESD
5.002088910, 13.970, 76.0, 8.7178
5.068933986, 13.970, 83.0, 9.1104
5.135779062, 13.970, 87.0, 9.3274
5.202624138, 13.970, 63.0, 7.9373
5.269469214, 13.970, 80.0, 8.9443
5.336314290, 13.970, 70.0, 8.3666
5.403159365, 13.970, 57.0, 7.5498
5.470004441, 13.970, 68.0, 8.2462
5.536849517, 13.970, 67.0, 8.1854
5.603694593, 13.970, 51.0, 7.1414
5.670539669, 13.970, 56.0, 7.4833
5.737384745, 13.970, 67.0, 8.1854
5.804229821, 13.970, 40.0, 6.3246
5.871074897, 13.970, 62.0, 7.8740
5.937919973, 13.970, 56.0, 7.4833
6.004765049, 13.970, 57.0, 7.5498
6.071610125, 13.970, 62.0, 7.8740
6.138455200, 13.970, 57.0, 7.5498
6.205300276, 13.970, 64.0, 8.0000
6.272145352, 13.970, 44.0, 6.6332
6.338990428, 13.970, 50.0, 7.0711
6.405835504, 13.970, 59.0, 7.6811
6.472680580, 13.970, 44.0, 6.6332
6.539525656, 13.970, 52.0, 7.2111
6.606370732, 13.970, 33.0, 5.7446
6.673215808, 13.970, 40.0, 6.3246
6.740060884, 13.970, 49.0, 7.0000
6.806905960, 13.970, 51.0, 7.1414
6.873751035, 13.970, 61.0, 7.8102
6.940596111, 13.970, 42.0, 6.4807
7.007441187, 13.970, 57.0, 7.5498
7.074286263, 13.970, 54.0, 7.3485
7.141131339, 13.970, 45.0, 6.7082
7.207976415, 13.970, 47.0, 6.8557
7.274821491, 13.970, 52.0, 7.2111
7.341666567, 13.970, 48.0, 6.9282
7.408511643, 13.970, 43.0, 6.5574
7.475356719, 13.970, 50.0, 7.0711
7.542201795, 13.970, 35.0, 5.9161
7.609046870, 13.970, 38.0, 6.1644
7.675891946, 13.970, 43.0, 6.5574
7.742737022, 13.970, 39.0, 6.2450
7.809582098, 13.970, 35.0, 5.9161
7.876427174, 13.970, 42.0, 6.4807
7.943272250, 13.970, 44.0, 6.6332
8.010117326, 13.970, 33.0, 5.7446
8.076962402, 13.970, 35.0, 5.9161
8.143807478, 13.970, 52.0, 7.2111
8.210652554, 13.970, 45.0, 6.7082
8.277497630, 13.970, 47.0, 6.8557
8.344342706, 13.970, 36.0, 6.0000
8.411187781, 13.970, 35.0, 5.9161
8.478032857, 13.970, 40.0, 6.3246
8.544877933, 13.970, 37.0, 6.0828
8.611723009, 13.970, 32.0, 5.6569
8.678568085, 13.970, 39.0, 6.2450
8.745413161, 13.970, 47.0, 6.8557
8.812258237, 13.970, 28.0, 5.2915
8.879103313, 13.970, 38.0, 6.1644
8.945948389, 13.970, 39.0, 6.2450
9.012793465, 13.970, 32.0, 5.6569
9.079638541, 13.970, 36.0, 6.0000
9.146483616, 13.970, 40.0, 6.3246
9.213328692, 13.970, 36.0, 6.0000
9.280173768, 13.970, 33.0, 5.7446
9.347018844, 13.970, 28.0, 5.2915
9.413863920, 13.970, 36.0, 6.0000
9.480708996, 13.970, 35.0, 5.9161
9.547554072, 13.970, 20.0, 4.4721
9.614399148, 13.970, 47.0, 6.8557
9.681244224, 13.970, 29.0, 5.3852
9.748089300, 13.970, 27.0, 5.1962
9.814934376, 13.970, 32.0, 5.6569
9.881779451, 13.970, 25.0, 5.0000
9.948624527, 13.970, 32.0, 5.6569
10.015469603, 13.970, 24.0, 4.8990
10.082314679, 13.970, 39.0, 6.2450
10.149159755, 13.970, 24.0, 4.8990
10.216004831, 13.970, 32.0, 5.6569
10.282849907, 13.970, 37.0, 6.0828
10.349694983, 13.970, 37.0, 6.0828
10.416540059, 13.970, 30.0, 5.4772
10.483385135, 13.970, 28.0, 5.2915
10.550230211, 13.970, 26.0, 5.0990
10.617075286, 13.970, 36.0, 6.0000
10.683920362, 13.970, 25.0, 5.0000
10.750765438, 13.970, 33.0, 5.7446
10.817610514, 13.970, 27.0, 5.1962
10.884455590, 13.970, 27.0, 5.1962
10.951300666, 13.970, 25.0, 5.0000
11.018145742, 13.970, 21.0, 4.5826
11.084990818, 13.970, 31.0, 5.5678
11.151835894, 13.970, 20.0, 4.4721
11.218680970, 13.970, 24.0, 4.8990
11.285526046, 13.970, 24.0, 4.8990
11.352371121, 13.970, 29.0, 5.3852
11.419216197, 13.970, 35.0, 5.9161
11.486061273, 13.970, 24.0, 4.8990
11.552906349, 13.970, 18.0, 4.2426
11.619751425, 13.970, 32.0, 5.6569
11.686596501, 13.970, 24.0, 4.8990
11.753441577, 13.970, 36.0, 6.0000
11.820286653, 13.970, 17.0, 4.1231
11.887131729, 13.970, 32.0, 5.6569
11.953976805, 13.970, 19.0, 4.3589
12.020821881, 13.970, 29.0, 5.3852
12.087666956, 13.970, 28.0, 5.2915
12.154512032, 13.970, 20.0, 4.4721
12.221357108, 13.970, 30.0, 5.4772
12.288202184, 13.970, 29.0, 5.3852
12.355047260, 13.970, 24.0, 4.8990
12.421892336, 13.970, 26.0, 5.0990
12.488737412, 13.970, 26.0, 5.0990
12.555582488, 13.970, 25.0, 5.0000
12.622427564, 13.970, 17.0, 4.1231
12.689272640, 13.970, 26.0, 5.0990
12.756117716, 13.970, 26.0, 5.0990
12.822962791, 13.970, 25.0, 5.0000
12.889807867, 13.970, 19.0, 4.3589
12.956652943, 13.970, 18.0, 4.2426
13.023498019, 13.970, 19.0, 4.3589
13.090343095, 13.970, 27.0, 5.1962
13.157188171, 13.970, 15.0, 3.8730
13.224033247, 13.970, 13.0, 3.6056
13.290878323, 13.970, 24.0, 4.8990
13.357723399, 13.970, 25.0, 5.0000
13.424568475, 13.970, 20.0, 4.4721
13.491413551, 13.970, 14.0, 3.7417
13.558258626, 13.970, 31.0, 5.5678
13.625103702, 13.970, 12.0, 3.4641
13.691948778, 13.970, 36.0, 6.0000
13.758793854, 13.970, 20.0, 4.4721
13.825638930, 13.970, 18.0, 4.2426
13.892484006, 13.970, 19.0, 4.3589
13.959329082, 13.970, 22.0, 4.6904
14.026174158, 13.970, 28.0, 5.2915
14.093019234, 13.970, 17.0, 4.1231
14.159864310, 13.970, 21.0, 4.5826
14.226709386, 13.970, 15.0, 3.8730
14.293554462, 13.970, 20.0, 4.4721
14.360399537, 13.970, 25.0, 5.0000
14.427244613, 13.970, 20.0, 4.4721
14.494089689, 13.970, 21.0, 4.5826
14.560934765, 13.970, 27.0, 5.1962
14.627779841, 13.970, 24.0, 4.8990
14.694624917, 13.970, 22.0, 4.6904
14.761469993, 13.970, 28.0, 5.2915
14.828315069, 13.970, 32.0, 5.6569
14.895160145, 13.970, 32.0, 5.6569
14.962005221, 13.970, 18.0, 4.2426
15.028850297, 13.970, 31.0, 5.5678
15.095695372, 13.970, 22.0, 4.6904
15.162540448, 13.970, 17.0, 4.1231
15.229385524, 13.970, 22.0, 4.6904
15.296230600, 13.970, 18.0, 4.2426
15.363075676, 13.970, 22.0, 4.6904
15.429920752, 13.970, 20.0, 4.4721
15.496765828, 13.970, 33.0, 5.7446
15.563610904, 13.970, 18.0, 4.2426
15.630455980, 13.970, 22.0, 4.6904
15.697301056, 13.970, 10.0, 3.1623
15.764146132, 13.970, 30.0, 5.4772
15.830991207, 13.970, 24.0, 4.8990
15.897836283, 13.970, 21.0, 4.5826
15.964681359, 13.970, 17.0, 4.1231
16.031526435, 13.970, 31.0, 5.5678
16.098371511, 13.970, 25.0, 5.0000
16.165216587, 13.970, 19.0, 4.3589
16.232061663, 13.970, 21.0, 4.5826
16.298906739, 13.970, 27.0, 5.1962
16.365751815, 13.970, 24.0, 4.8990
16.432596891, 13.970, 28.0, 5.2915
16.499441967, 13.970, 22.0, 4.6904
16.566287042, 13.970, 28.0, 5.2915
16.633132118, 13.970, 19.0, 4.3589
16.699977194, 13.970, 22.0, 4.6904
16.766822270, 13.970, 28.0, 5.2915
16.833667346, 13.970, 29.0, 5.3852
16.900512422, 13.970, 19.0, 4.3589
16.967357498, 13.970, 39.0, 6.2450
17.034202574, 13.970, 28.0, 5.2915
17.101047650, 13.970, 21.0, 4.5826
17.167892726, 13.970, 32.0, 5.6569
17.234737802, 13.970, 15.0, 3.8730
17.301582877, 13.970, 19.0, 4.3589
17.368427953, 13.970, 30.0, 5.4772
17.435273029, 13.970, 29.0, 5.3852
17.502118105, 13.970, 31.0, 5.5678
17.568963181, 13.970, 32.0, 5.6569
17.635808257, 13.970, 27.0, 5.1962
17.702653333, 13.970, 18.0, 4.2426
17.769498409, 13.970, 18.0, 4.2426
17.836343485, 13.970, 29.0, 5.3852
17.903188561, 13.970, 22.0, 4.6904
17.970033637, 13.970, 26.0, 5.0990
18.036878712, 13.970, 32.0, 5.6569
18.103723788, 13.970, 32.0, 5.6569
18.170568864, 13.970, 43.0, 6.5574
18.237413940, 13.970, 27.0, 5.1962
18.304259016, 13.970, 40.0, 6.3246
18.371104092, 13.970, 21.0, 4.5826
18.437949168, 13.970, 40.0, 6.3246
18.504794244, 13.970, 33.0, 5.7446
18.571639320, 13.970, 26.0, 5.0990
18.638484396, 13.970, 32.0, 5.6569
18.705329472, 13.970, 33.0, 5.7446
18.772174547, 13.970, 36.0, 6.0000
18.839019623, 13.970, 30.0, 5.4772
18.905864699, 13.970, 25.0, 5.0000
18.972709775, 13.970, 31.0, 5.5678
19.039554851, 13.970, 30.0, 5.4772
19.106399927, 13.970, 20.0, 4.4721
19.173245003, 13.970, 36.0, 6.0000
19.240090079, 13.970, 40.0, 6.3246
19.306935155, 13.970, 40.0, 6.3246
19.373780231, 13.970, 33.0, 5.7446
19.440625307, 13.970, 24.0, 4.8990
19.507470382, 13.970, 44.0, 6.6332
19.574315458, 13.970, 38.0, 6.1644
19.641160534, 13.970, 38.0, 6.1644
19.708005610, 13.970, 36.0, 6.0000
19.774850686, 13.970, 36.0, 6.0000
19.841695762, 13.970, 29.0, 5.3852
19.908540838, 13.970, 29.0, 5.3852
19.975385914, 13.970, 30.0, 5.4772
20.042230990, 13.970, 22.0, 4.6904
20.109076066, 13.970, 41.0, 6.4031
20.175921142, 13.970, 33.0, 5.7446
20.242766218, 13.970, 32.0, 5.6569
20.309611293, 13.970, 32.0, 5.6569
20.376456369, 13.970, 28.0, 5.2915
20.443301445, 13.970, 40.0, 6.3246
20.510146521, 13.970, 47.0, 6.8557
20.576991597, 13.970, 37.0, 6.0828
20.643836673, 13.970, 37.0, 6.0828
20.710681749, 13.970, 41.0, 6.4031
20.777526825, 13.970, 33.0, 5.7446
20.844371901, 13.970, 30.0, 5.4772
20.911216977, 13.970, 33.0, 5.7446
20.978062053, 13.970, 35.0, 5.9161
21.044907128, 13.970, 42.0, 6.4807
21.111752204, 13.970, 38.0, 6.1644
21.178597280, 13.970, 40.0, 6.3246
21.245442356, 13.970, 40.0, 6.3246
21.312287432, 13.970, 43.0, 6.5574
21.379132508, 13.970, 35.0, 5.9161
21.445977584, 13.970, 38.0, 6.1644
21.512822660, 13.970, 33.0, 5.7446
21.579667736, 13.970, 39.0, 6.2450
21.646512812, 13.970, 42.0, 6.4807
21.713357888, 13.970, 38.0, 6.1644
21.780202963, 13.970, 33.0, 5.7446
21.847048039, 13.970, 40.0, 6.3246
21.913893115, 13.970, 38.0, 6.1644
21.980738191, 13.970, 35.0, 5.9161
22.047583267, 13.970, 35.0, 5.9161
22.114428343, 13.970, 37.0, 6.0828
22.181273419, 13.970, 36.0, 6.0000
22.248118495, 13.970, 44.0, 6.6332
22.314963571, 13.970, 32.0, 5.6569
22.381808647, 13.970, 41.0, 6.4031
22.448653723, 13.970, 39.0, 6.2450
22.515498798, 13.970, 42.0, 6.4807
22.582343874, 13.970, 33.0, 5.7446
22.649188950, 13.970, 51.0, 7.1414
22.716034026, 13.970, 43.0, 6.5574
22.782879102, 13.970, 31.0, 5.5678
22.849724178, 13.970, 45.0, 6.7082
22.916569254, 13.970, 38.0, 6.1644
22.983414330, 13.970, 36.0, 6.0000
23.050259406, 13.970, 35.0, 5.9161
23.117104482, 13.970, 36.0, 6.0000
23.183949558, 13.970, 39.0, 6.2450
23.250794633, 13.970, 37.0, 6.0828
23.317639709, 13.970, 28.0, 5.2915
23.384484785, 13.970, 53.0, 7.2801
23.451329861, 13.970, 39.0, 6.2450
23.518174937, 13.970, 38.0, 6.1644
23.585020013, 13.970, 29.0, 5.3852
23.651865089, 13.970, 45.0, 6.7082
23.718710165, 13.970, 40.0, 6.3246
23.785555241, 13.970, 42.0, 6.4807
23.852400317, 13.970, 32.0, 5.6569
23.919245393, 13.970, 38.0, 6.1644
23.986090468, 13.970, 47.0, 6.8557
24.052935544, 13.970, 33.0, 5.7446
24.119780620, 13.970, 30.0, 5.4772
24.186625696, 13.970, 47.0, 6.8557
24.253470772, 13.970, 35.0, 5.9161
24.320315848, 13.970, 40.0, 6.3246
24.387160924, 13.970, 42.0, 6.4807
24.454006000, 13.970, 36.0, 6.0000
24.520851076, 13.970, 57.0, 7.5498
24.587696152, 13.970, 37.0, 6.0828
24.654541228, 13.970, 31.0, 5.5678
24.721386303, 13.970, 43.0, 6.5574
24.788231379, 13.970, 43.0, 6.5574
24.855076455, 13.970, 36.0, 6.0000
24.921921531, 13.970, 49.0, 7.0000
24.988766607, 13.970, 30.0, 5.4772
25.055611683, 13.970, 39.0, 6.2450
25.122456759, 13.970, 56.0, 7.4833
25.189301835, 13.970, 41.0, 6.4031
25.256146911, 13.970, 43.0, 6.5574
25.322991987, 13.970, 43.0, 6.5574
25.389837063, 13.970, 30.0, 5.4772
25.456682138, 13.970, 40.0, 6.3246
25.523527214, 13.970, 38.0, 6.1644
25.590372290, 13.970, 45.0, 6.7082
25.657217366, 13.970, 39.0, 6.2450
25.724062442, 13.970, 41.0, 6.4031
25.790907518, 13.970, 26.0, 5.0990
25.857752594, 13.970, 38.0, 6.1644
25.924597670, 13.970, 36.0, 6.0000
25.991442746, 13.970, 45.0, 6.7082
26.058287822, 13.970, 39.0, 6.2450
26.125132898, 13.970, 33.0, 5.7446
26.191977974, 13.970, 30.0, 5.4772
26.258823049, 13.970, 44.0, 6.6332
26.325668125, 13.970, 36.0, 6.0000
26.392513201, 13.970, 33.0, 5.7446
26.459358277, 13.970, 36.0, 6.0000
26.526203353, 13.970, 48.0, 6.9282
26.593048429, 13.970, 40.0, 6.3246
26.659893505, 13.970, 28.0, 5.2915
26.726738581, 13.970, 51.0, 7.1414
26.793583657, 13.970, 37.0, 6.0828
26.860428733, 13.970, 32.0, 5.6569
26.927273809, 13.970, 37.0, 6.0828
26.994118884, 13.970, 37.0, 6.0828
27.060963960, 13.970, 47.0, 6.8557
27.127809036, 13.970, 36.0, 6.0000
27.194654112, 13.970, 42.0, 6.4807
27.261499188, 13.970, 40.0, 6.3246
27.328344264, 13.970, 40.0, 6.3246
27.395189340, 13.970, 37.0, 6.0828
27.462034416, 13.970, 24.0, 4.8990
27.528879492, 13.970, 30.0, 5.4772
27.595724568, 13.970, 37.0, 6.0828
27.662569644, 13.970, 38.0, 6.1644
27.729414719, 13.970, 33.0, 5.7446
27.796259795, 13.970, 44.0, 6.6332
27.863104871, 13.970, 31.0, 5.5678
27.929949947, 13.970, 38.0, 6.1644
27.996795023, 13.970, 47.0, 6.8557
28.063640099, 13.970, 43.0, 6.5574
28.130485175, 13.970, 37.0, 6.0828
28.197330251, 13.970, 36.0, 6.0000
28.264175327, 13.970, 36.0, 6.0000
28.331020403, 13.970, 29.0, 5.3852
28.397865479, 13.970, 41.0, 6.4031
28.464710554, 13.970, 35.0, 5.9161
28.531555630, 13.970, 38.0, 6.1644
28.598400706, 13.970, 35.0, 5.9161
28.665245782, 13.970, 37.0, 6.0828
28.732090858, 13.970, 42.0, 6.4807
28.798935934, 13.970, 35.0, 5.9161
28.865781010, 13.970, 31.0, 5.5678
28.932626086, 13.970, 38.0, 6.1644
28.999471162, 13.970, 36.0, 6.0000
29.066316238, 13.970, 54.0, 7.3485
29.133161314, 13.970, 42.0, 6.4807
29.200006389, 13.970, 33.0, 5.7446
29.266851465, 13.970, 32.0, 5.6569
29.333696541, 13.970, 26.0, 5.0990
29.400541617, 13.970, 30.0, 5.4772
29.467386693, 13.970, 31.0, 5.5678
29.534231769, 13.970, 30.0, 5.4772
29.601076845, 13.970, 29.0, 5.3852
29.667921921, 13.970, 43.0, 6.5574
29.734766997, 13.970, 25.0, 5.0000
29.801612073, 13.970, 42.0, 6.4807
29.868457149, 13.970, 39.0, 6.2450
29.935302224, 13.970, 45.0, 6.7082
30.002147300, 13.970, 35.0, 5.9161
30.068992376, 13.970, 31.0, 5.5678
30.135837452, 13.970, 36.0, 6.0000
30.202682528, 13.970, 41.0, 6.4031
30.269527604, 13.970, 31.0, 5.5678
30.336372680, 13.970, 38.0, 6.1644
30.403217756, 13.970, 30.0, 5.4772
30.470062832, 13.970, 35.0, 5.9161
30.536907908, 13.970, 31.0, 5.5678
30.603752984, 13.970, 27.0, 5.1962
30.670598059, 13.970, 26.0, 5.0990
30.737443135, 13.970, 22.0, 4.6904
30.804288211, 13.970, 33.0, 5.7446
30.871133287, 13.970, 25.0, 5.0000
30.937978363, 13.970, 36.0, 6.0000
31.004823439, 13.970, 22.0, 4.6904
31.071668515, 13.970, 27.0, 5.1962
31.138513591, 13.970, 41.0, 6.4031
31.205358667, 13.970, 39.0, 6.2450
31.272203743, 13.970, 28.0, 5.2915
31.339048819, 13.970, 29.0, 5.3852
31.405893894, 13.970, 28.0, 5.2915
31.472738970, 13.970, 49.0, 7.0000
31.539584046, 13.970, 30.0, 5.4772
31.606429122, 13.970, 26.0, 5.0990
31.673274198, 13.970, 26.0, 5.0990
31.740119274, 13.970, 30.0, 5.4772
31.806964350, 13.970, 31.0, 5.5678
31.873809426, 13.970, 37.0, 6.0828
31.940654502, 13.970, 33.0, 5.7446
32.007499578, 13.970, 36.0, 6.0000
32.074344654, 13.970, 27.0, 5.1962
32.141189730, 13.970, 27.0, 5.1962
32.208034805, 13.970, 45.0, 6.7082
32.274879881, 13.970, 32.0, 5.6569
32.341724957, 13.970, 38.0, 6.1644
32.408570033, 13.970, 31.0, 5.5678
32.475415109, 13.970, 26.0, 5.0990
32.542260185, 13.970, 29.0, 5.3852
32.609105261, 13.970, 35.0, 5.9161
32.675950337, 13.970, 49.0, 7.0000
32.742795413, 13.970, 25.0, 5.0000
32.809640489, 13.970, 31.0, 5.5678
32.876485565, 13.970, 25.0, 5.0000
32.943330640, 13.970, 20.0, 4.4721
33.010175716, 13.970, 36.0, 6.0000
33.077020792, 13.970, 21.0, 4.5826
33.143865868, 13.970, 31.0, 5.5678
33.210710944, 13.970, 41.0, 6.4031
33.277556020, 13.970, 25.0, 5.0000
33.344401096, 13.970, 21.0, 4.5826
33.411246172, 13.970, 31.0, 5.5678
33.478091248, 13.970, 30.0, 5.4772
33.544936324, 13.970, 30.0, 5.4772
33.611781400, 13.970, 26.0, 5.0990
33.678626475, 13.970, 28.0, 5.2915
33.745471551, 13.970, 33.0, 5.7446
33.812316627, 13.970, 33.0, 5.7446
33.879161703, 13.970, 28.0, 5.2915
33.946006779, 13.970, 26.0, 5.0990
34.012851855, 13.970, 25.0, 5.0000
34.079696931, 13.970, 29.0, 5.3852
34.146542007, 13.970, 24.0, 4.8990
34.213387083, 13.970, 29.0, 5.3852
34.280232159, 13.970, 24.0, 4.8990
34.347077235, 13.970, 30.0, 5.4772
34.413922310, 13.970, 25.0, 5.0000
34.480767386, 13.970, 32.0, 5.6569
34.547612462, 13.970, 19.0, 4.3589
34.614457538, 13.970, 26.0, 5.0990
34.681302614, 13.970, 26.0, 5.0990
34.748147690, 13.970, 33.0, 5.7446
34.814992766, 13.970, 22.0, 4.6904
34.881837842, 13.970, 30.0, 5.4772
34.948682918, 13.970, 25.0, 5.0000
35.015527994, 13.970, 22.0, 4.6904
35.082373070, 13.970, 19.0, 4.3589
35.149218145, 13.970, 24.0, 4.8990
35.216063221, 13.970, 15.0, 3.8730
35.282908297, 13.970, 26.0, 5.0990
35.349753373, 13.970, 28.0, 5.2915
35.416598449, 13.970, 19.0, 4.3589
35.483443525, 13.970, 26.0, 5.0990
35.550288601, 13.970, 22.0, 4.6904
35.617133677, 13.970, 25.0, 5.0000
35.683978753, 13.970, 24.0, 4.8990
35.750823829, 13.970, 25.0, 5.0000
35.817668905, 13.970, 29.0, 5.3852
35.884513980, 13.970, 22.0, 4.6904
35.951359056, 13.970, 25.0, 5.0000
36.018204132, 13.970, 21.0, 4.5826
36.085049208, 13.970, 27.0, 5.1962
36.151894284, 13.970, 27.0, 5.1962
36.218739360, 13.970, 31.0, 5.5678
36.285584436, 13.970, 30.0, 5.4772
36.352429512, 13.970, 19.0, 4.3589
36.419274588, 13.970, 17.0, 4.1231
36.486119664, 13.970, 29.0, 5.3852
36.552964740, 13.970, 24.0, 4.8990
36.619809815, 13.970, 30.0, 5.4772
36.686654891, 13.970, 24.0, 4.8990
36.753499967, 13.970, 21.0, 4.5826
36.820345043, 13.970, 20.0, 4.4721
36.887190119, 13.970, 21.0, 4.5826
36.954035195, 13.970, 17.0, 4.1231
37.020880271, 13.970, 22.0, 4.6904
37.087725347, 13.970, 18.0, 4.2426
37.154570423, 13.970, 16.0, 4.0000
37.221415499, 13.970, 18.0, 4.2426
37.288260575, 13.970, 21.0, 4.5826
37.355105650, 13.970, 13.0, 3.6056
37.421950726, 13.970, 26.0, 5.0990
37.488795802, 13.970, 20.0, 4.4721
37.555640878, 13.970, 20.0, 4.4721
37.622485954, 13.970, 18.0, 4.2426
37.689331030, 13.970, 17.0, 4.1231
37.756176106, 13.970, 19.0, 4.3589
37.823021182, 13.970, 27.0, 5.1962
37.889866258, 13.970, 21.0, 4.5826
37.956711334, 13.970, 15.0, 3.8730
38.023556410, 13.970, 24.0, 4.8990
38.090401486, 13.970, 14.0, 3.7417
38.157246561, 13.970, 20.0, 4.4721
38.224091637, 13.970, 20.0, 4.4721
38.290936713, 13.970, 12.0, 3.4641
38.357781789, 13.970, 18.0, 4.2426
38.424626865, 13.970, 15.0, 3.8730
38.491471941, 13.970, 20.0, 4.4721
38.558317017, 13.970, 16.0, 4.0000
38.625162093, 13.970, 17.0, 4.1231
38.692007169, 13.970, 15.0, 3.8730
38.758852245, 13.970, 14.0, 3.7417
38.825697321, 13.970, 16.0, 4.0000
38.892542396, 13.970, 25.0, 5.0000
38.959387472, 13.970, 24.0, 4.8990
39.026232548, 13.970, 22.0, 4.6904
39.093077624, 13.970, 21.0, 4.5826
39.159922700, 13.970, 24.0, 4.8990
39.226767776, 13.970, 19.0, 4.3589
39.293612852, 13.970, 16.0, 4.0000
39.360457928, 13.970, 16.0, 4.0000
39.427303004, 13.970, 16.0, 4.0000
39.494148080, 13.970, 13.0, 3.6056
39.560993156, 13.970, 17.0, 4.1231
39.627838231, 13.970, 17.0, 4.1231
39.694683307, 13.970, 18.0, 4.2426
39.761528383, 13.970, 15.0, 3.8730
39.828373459, 13.970, 26.0, 5.0990
39.895218535, 13.970, 19.0, 4.3589
39.962063611, 13.970, 19.0, 4.3589
40.028908687, 13.970, 16.0, 4.0000
40.095753763, 13.970, 20.0, 4.4721
40.162598839, 13.970, 9.0, 3.0000
40.229443915, 13.970, 17.0, 4.1231
40.296288991, 13.970, 21.0, 4.5826
40.363134066, 13.970, 13.0, 3.6056
40.429979142, 13.970, 20.0, 4.4721
40.496824218, 13.970, 22.0, 4.6904
40.563669294, 13.970, 16.0, 4.0000
40.630514370, 13.970, 19.0, 4.3589
40.697359446, 13.970, 17.0, 4.1231
40.764204522, 13.970, 25.0, 5.0000
40.831049598, 13.970, 18.0, 4.2426
40.897894674, 13.970, 19.0, 4.3589
40.964739750, 13.970, 17.0, 4.1231
41.031584826, 13.970, 19.0, 4.3589
41.098429901, 13.970, 16.0, 4.0000
41.165274977, 13.970, 21.0, 4.5826
41.232120053, 13.970, 22.0, 4.6904
41.298965129, 13.970, 20.0, 4.4721
41.365810205, 13.970, 27.0, 5.1962
41.432655281, 13.970, 31.0, 5.5678
41.499500357, 13.970, 39.0, 6.2450
41.566345433, 13.970, 74.0, 8.6023
41.633190509, 13.970, 78.0, 8.8318
41.700035585, 13.970, 41.0, 6.4031
41.766880661, 13.970, 29.0, 5.3852
41.833725736, 13.970, 35.0, 5.9161
41.900570812, 13.970, 18.0, 4.2426
41.967415888, 13.970, 26.0, 5.0990
42.034260964, 13.970, 36.0, 6.0000
42.101106040, 13.970, 66.0, 8.1240
42.167951116, 13.970, 123.0, 11.0905
42.234796192, 13.970, 112.0, 10.5830
42.301641268, 13.970, 82.0, 9.0554
42.368486344, 13.970, 39.0, 6.2450
42.435331420, 13.970, 29.0, 5.3852
42.502176496, 13.970, 43.0, 6.5574
42.569021571, 13.970, 44.0, 6.6332
42.635866647, 13.970, 68.0, 8.2462
42.702711723, 13.970, 52.0, 7.2111
42.769556799, 13.970, 36.0, 6.0000
42.836401875, 13.970, 30.0, 5.4772
42.903246951, 13.970, 33.0, 5.7446
42.970092027, 13.970, 25.0, 5.0000
43.036937103, 13.970, 35.0, 5.9161
43.103782179, 13.970, 36.0, 6.0000
43.170627255, 13.970, 39.0, 6.2450
43.237472331, 13.970, 36.0, 6.0000
43.304317406, 13.970, 29.0, 5.3852
43.371162482, 13.970, 28.0, 5.2915
43.438007558, 13.970, 33.0, 5.7446
43.504852634, 13.970, 19.0, 4.3589
43.571697710, 13.970, 25.0, 5.0000
43.638542786, 13.970, 22.0, 4.6904
43.705387862, 13.970, 18.0, 4.2426
43.772232938, 13.970, 24.0, 4.8990
43.839078014, 13.970, 10.0, 3.1623
43.905923090, 13.970, 15.0, 3.8730
43.972768166, 13.970, 22.0, 4.6904
44.039613242, 13.970, 18.0, 4.2426
44.106458317, 13.970, 17.0, 4.1231
44.173303393, 13.970, 16.0, 4.0000
44.240148469, 13.970, 12.0, 3.4641
44.306993545, 13.970, 16.0, 4.0000
44.373838621, 13.970, 15.0, 3.8730
44.440683697, 13.970, 26.0, 5.0990
44.507528773, 13.970, 18.0, 4.2426
44.574373849, 13.970, 10.0, 3.1623
44.641218925, 13.970, 21.0, 4.5826
44.708064001, 13.970, 18.0, 4.2426
44.774909077, 13.970, 19.0, 4.3589
44.841754152, 13.970, 20.0, 4.4721
44.908599228, 13.970, 26.0, 5.0990
44.975444304, 13.970, 19.0, 4.3589
45.042289380, 13.970, 17.0, 4.1231
45.109134456, 13.970, 22.0, 4.6904
45.175979532, 13.970, 21.0, 4.5826
45.242824608, 13.970, 16.0, 4.0000
45.309669684, 13.970, 16.0, 4.0000
45.376514760, 13.970, 14.0, 3.7417
45.443359836, 13.970, 18.0, 4.2426
45.510204912, 13.970, 16.0, 4.0000
45.577049987, 13.970, 14.0, 3.7417
45.643895063, 13.970, 12.0, 3.4641
45.710740139, 13.970, 20.0, 4.4721
45.777585215, 13.970, 15.0, 3.8730
45.844430291, 13.970, 17.0, 4.1231
45.911275367, 13.970, 26.0, 5.0990
45.978120443, 13.970, 28.0, 5.2915
46.044965519, 13.970, 21.0, 4.5826
46.111810595, 13.970, 25.0, 5.0000
46.178655671, 13.970, 14.0, 3.7417
46.245500747, 13.970, 26.0, 5.0990
46.312345822, 13.970, 15.0, 3.8730
46.379190898, 13.970, 13.0, 3.6056
46.446035974, 13.970, 9.0, 3.0000
46.512881050, 13.970, 15.0, 3.8730
46.579726126, 13.970, 19.0, 4.3589
46.646571202, 13.970, 21.0, 4.5826
46.713416278, 13.970, 17.0, 4.1231
46.780261354, 13.970, 19.0, 4.3589
46.847106430, 13.970, 18.0, 4.2426
46.913951506, 13.970, 22.0, 4.6904
46.980796582, 13.970, 16.0, 4.0000
47.047641657, 13.970, 15.0, 3.8730
47.114486733, 13.970, 19.0, 4.3589
47.181331809, 13.970, 21.0, 4.5826
47.248176885, 13.970, 15.0, 3.8730
47.315021961, 13.970, 20.0, 4.4721
47.381867037, 13.970, 16.0, 4.0000
47.448712113, 13.970, 24.0, 4.8990
47.515557189, 13.970, 24.0, 4.8990
47.582402265, 13.970, 20.0, 4.4721
47.649247341, 13.970, 17.0, 4.1231
47.716092417, 13.970, 14.0, 3.7417
47.782937492, 13.970, 20.0, 4.4721
47.849782568, 13.970, 10.0, 3.1623
47.916627644, 13.970, 21.0, 4.5826
47.983472720, 13.970, 28.0, 5.2915
48.050317796, 13.970, 29.0, 5.3852
48.117162872, 13.970, 36.0, 6.0000
48.184007948, 13.970, 30.0, 5.4772
48.250853024, 13.970, 35.0, 5.9161
48.317698100, 13.970, 50.0, 7.0711
48.384543176, 13.970, 83.0, 9.1104
48.451388252, 13.970, 131.0, 11.4455
48.518233327, 13.970, 135.0, 11.6190
48.585078403, 13.970, 107.0, 10.3441
48.651923479, 13.970, 76.0, 8.7178
48.718768555, 13.970, 41.0, 6.4031
48.785613631, 13.970, 57.0, 7.5498
48.852458707, 13.970, 54.0, 7.3485
48.919303783, 13.970, 50.0, 7.0711
48.986148859, 13.970, 61.0, 7.8102
49.052993935, 13.970, 73.0, 8.5440
49.119839011, 13.970, 60.0, 7.7460
49.186684087, 13.970, 38.0, 6.1644
49.253529162, 13.970, 35.0, 5.9161
49.320374238, 13.970, 30.0, 5.4772
49.387219314, 13.970, 21.0, 4.5826
49.454064390, 13.970, 26.0, 5.0990
49.520909466, 13.970, 27.0, 5.1962
49.587754542, 13.970, 28.0, 5.2915
49.654599618, 13.970, 39.0, 6.2450
49.721444694, 13.970, 54.0, 7.3485
49.788289770, 13.970, 50.0, 7.0711
49.855134846, 13.970, 37.0, 6.0828
49.921979922, 13.970, 28.0, 5.2915
49.988824998, 13.970, 15.0, 3.8730
50.055670073, 13.970, 24.0, 4.8990
50.122515149, 13.970, 22.0, 4.6904
50.189360225, 13.970, 21.0, 4.5826
50.256205301, 13.970, 13.0, 3.6056
50.323050377, 13.970, 17.0, 4.1231
50.389895453, 13.970, 15.0, 3.8730
50.456740529, 13.970, 14.0, 3.7417
50.523585605, 13.970, 19.0, 4.3589
50.590430681, 13.970, 14.0, 3.7417
50.657275757, 13.970, 24.0, 4.8990
50.724120833, 13.970, 17.0, 4.1231
50.790965908, 13.970, 18.0, 4.2426
50.857810984, 13.970, 15.0, 3.8730
50.924656060, 13.970, 13.0, 3.6056
50.991501136, 13.970, 21.0, 4.5826
51.058346212, 13.970, 16.0, 4.0000
51.125191288, 13.970, 25.0, 5.0000
51.192036364, 13.970, 20.0, 4.4721
51.258881440, 13.970, 16.0, 4.0000
51.325726516, 13.970, 14.0, 3.7417
51.392571592, 13.970, 18.0, 4.2426
51.459416668, 13.970, 22.0, 4.6904
51.526261743, 13.970, 20.0, 4.4721
51.593106819, 13.970, 8.0, 2.8284
51.659951895, 13.970, 8.0, 2.8284
51.726796971, 13.970, 16.0, 4.0000
51.793642047, 13.970, 22.0, 4.6904
51.860487123, 13.970, 20.0, 4.4721
51.927332199, 13.970, 13.0, 3.6056
51.994177275, 13.970, 13.0, 3.6056
52.061022351, 13.970, 18.0, 4.2426
52.127867427, 13.970, 18.0, 4.2426
52.194712503, 13.970, 14.0, 3.7417
52.261557578, 13.970, 10.0, 3.1623
52.328402654, 13.970, 12.0, 3.4641
52.395247730, 13.970, 19.0, 4.3589
52.462092806, 13.970, 22.0, 4.6904
52.528937882, 13.970, 18.0, 4.2426
52.595782958, 13.970, 15.0, 3.8730
52.662628034, 13.970, 17.0, 4.1231
52.729473110, 13.970, 19.0, 4.3589
52.796318186, 13.970, 16.0, 4.0000
52.863163262, 13.970, 13.0, 3.6056
52.930008338, 13.970, 20.0, 4.4721
52.996853413, 13.970, 19.0, 4.3589
53.063698489, 13.970, 14.0, 3.7417
53.130543565, 13.970, 14.0, 3.7417
53.197388641, 13.970, 9.0, 3.0000
53.264233717, 13.970, 16.0, 4.0000
53.331078793, 13.970, 15.0, 3.8730
53.397923869, 13.970, 13.0, 3.6056
53.464768945, 13.970, 8.0, 2.8284
53.531614021, 13.970, 14.0, 3.7417
53.598459097, 13.970, 13.0, 3.6056
53.665304173, 13.970, 18.0, 4.2426
53.732149248, 13.970, 16.0, 4.0000
53.798994324, 13.970, 22.0, 4.6904
53.865839400, 13.970, 14.0, 3.7417
53.932684476, 13.970, 17.0, 4.1231
53.999529552, 13.970, 16.0, 4.0000
54.066374628, 13.970, 12.0, 3.4641
54.133219704, 13.970, 9.0, 3.0000
54.200064780, 13.970, 13.0, 3.6056
54.266909856, 13.970, 13.0, 3.6056
54.333754932, 13.970, 12.0, 3.4641
54.400600008, 13.970, 13.0, 3.6056
54.467445083, 13.970, 15.0, 3.8730
54.534290159, 13.970, 10.0, 3.1623
54.601135235, 13.970, 14.0, 3.7417
54.667980311, 13.970, 10.0, 3.1623
54.734825387, 13.970, 15.0, 3.8730
54.801670463, 13.970, 20.0, 4.4721
54.868515539, 13.970, 18.0, 4.2426
54.935360615, 13.970, 18.0, 4.2426
55.002205691, 13.970, 16.0, 4.0000
55.069050767, 13.970, 22.0, 4.6904
55.135895843, 13.970, 15.0, 3.8730
55.202740918, 13.970, 19.0, 4.3589
55.269585994, 13.970, 12.0, 3.4641
55.336431070, 13.970, 15.0, 3.8730
55.403276146, 13.970, 16.0, 4.0000
55.470121222, 13.970, 19.0, 4.3589
55.536966298, 13.970, 12.0, 3.4641
55.603811374, 13.970, 16.0, 4.0000
55.670656450, 13.970, 15.0, 3.8730
55.737501526, 13.970, 15.0, 3.8730
55.804346602, 13.970, 20.0, 4.4721
55.871191678, 13.970, 17.0, 4.1231
55.938036754, 13.970, 22.0, 4.6904
56.004881829, 13.970, 9.0, 3.0000
56.071726905, 13.970, 9.0, 3.0000
56.138571981, 13.970, 20.0, 4.4721
56.205417057, 13.970, 21.0, 4.5826
56.272262133, 13.970, 18.0, 4.2426
56.339107209, 13.970, 16.0, 4.0000
56.405952285, 13.970, 16.0, 4.0000
56.472797361, 13.970, 26.0, 5.0990
56.539642437, 13.970, 18.0, 4.2426
56.606487513, 13.970, 19.0, 4.3589
56.673332589, 13.970, 12.0, 3.4641
56.740177664, 13.970, 19.0, 4.3589
56.807022740, 13.970, 18.0, 4.2426
56.873867816, 13.970, 16.0, 4.0000
56.940712892, 13.970, 17.0, 4.1231
57.007557968, 13.970, 21.0, 4.5826
57.074403044, 13.970, 12.0, 3.4641
57.141248120, 13.970, 16.0, 4.0000
57.208093196, 13.970, 21.0, 4.5826
57.274938272, 13.970, 12.0, 3.4641
57.341783348, 13.970, 12.0, 3.4641
57.408628424, 13.970, 22.0, 4.6904
57.475473499, 13.970, 9.0, 3.0000
57.542318575, 13.970, 15.0, 3.8730
57.609163651, 13.970, 10.0, 3.1623
57.676008727, 13.970, 21.0, 4.5826
57.742853803, 13.970, 18.0, 4.2426
57.809698879, 13.970, 21.0, 4.5826
57.876543955, 13.970, 10.0, 3.1623
57.943389031, 13.970, 9.0, 3.0000
58.010234107, 13.970, 18.0, 4.2426
58.077079183, 13.970, 7.0, 2.6458
58.143924259, 13.970, 17.0, 4.1231
58.210769334, 13.970, 16.0, 4.0000
58.277614410, 13.970, 18.0, 4.2426
58.344459486, 13.970, 14.0, 3.7417
58.411304562, 13.970, 8.0, 2.8284
58.478149638, 13.970, 16.0, 4.0000
58.544994714, 13.970, 15.0, 3.8730
58.611839790, 13.970, 12.0, 3.4641
58.678684866, 13.970, 22.0, 4.6904
58.745529942, 13.970, 13.0, 3.6056
58.812375018, 13.970, 18.0, 4.2426
58.879220094, 13.970, 18.0, 4.2426
58.946065169, 13.970, 14.0, 3.7417
59.012910245, 13.970, 22.0, 4.6904
59.079755321, 13.970, 16.0, 4.0000
59.146600397, 13.970, 15.0, 3.8730
59.213445473, 13.970, 14.0, 3.7417
59.280290549, 13.970, 18.0, 4.2426
59.347135625, 13.970, 17.0, 4.1231
59.413980701, 13.970, 21.0, 4.5826
59.480825777, 13.970, 17.0, 4.1231
59.547670853, 13.970, 14.0, 3.7417
59.614515929, 13.970, 21.0, 4.5826
59.681361004, 13.970, 13.0, 3.6056
59.748206080, 13.970, 28.0, 5.2915
59.815051156, 13.970, 12.0, 3.4641
59.881896232, 13.970, 6.0, 2.4495
59.948741308, 13.970, 13.0, 3.6056
60.015586384, 13.970, 16.0, 4.0000
60.082431460, 13.970, 13.0, 3.6056
60.149276536, 13.970, 8.0, 2.8284
60.216121612, 13.970, 21.0, 4.5826
60.282966688, 13.970, 19.0, 4.3589
60.349811764, 13.970, 18.0, 4.2426
60.416656839, 13.970, 18.0, 4.2426
60.483501915, 13.970, 12.0, 3.4641
60.550346991, 13.970, 13.0, 3.6056
60.617192067, 13.970, 18.0, 4.2426
60.684037143, 13.970, 16.0, 4.0000
60.750882219, 13.970, 13.0, 3.6056
60.817727295, 13.970, 16.0, 4.0000
60.884572371, 13.970, 16.0, 4.0000
60.951417447, 13.970, 16.0, 4.0000
61.018262523, 13.970, 13.0, 3.6056
61.085107599, 13.970, 18.0, 4.2426
61.151952674, 13.970, 15.0, 3.8730
61.218797750, 13.970, 9.0, 3.0000
61.285642826, 13.970, 10.0, 3.1623
61.352487902, 13.970, 14.0, 3.7417
61.419332978, 13.970, 15.0, 3.8730
61.486178054, 13.970, 10.0, 3.1623
61.553023130, 13.970, 25.0, 5.0000
61.619868206, 13.970, 17.0, 4.1231
61.686713282, 13.970, 14.0, 3.7417
61.753558358, 13.970, 13.0, 3.6056
61.820403434, 13.970, 12.0, 3.4641
61.887248510, 13.970, 17.0, 4.1231
61.954093585, 13.970, 20.0, 4.4721
62.020938661, 13.970, 6.0, 2.4495
62.087783737, 13.970, 12.0, 3.4641
62.154628813, 13.970, 16.0, 4.0000
62.221473889, 13.970, 20.0, 4.4721
62.288318965, 13.970, 14.0, 3.7417
62.355164041, 13.970, 15.0, 3.8730
62.422009117, 13.970, 9.0, 3.0000
62.488854193, 13.970, 14.0, 3.7417
62.555699269, 13.970, 15.0, 3.8730
62.622544345, 13.970, 15.0, 3.8730
62.689389420, 13.970, 18.0, 4.2426
62.756234496, 13.970, 18.0, 4.2426
62.823079572, 13.970, 10.0, 3.1623
62.889924648, 13.970, 16.0, 4.0000
62.956769724, 13.970, 15.0, 3.8730
63.023614800, 13.970, 21.0, 4.5826
63.090459876, 13.970, 18.0, 4.2426
63.157304952, 13.970, 10.0, 3.1623
63.224150028, 13.970, 10.0, 3.1623
63.290995104, 13.970, 12.0, 3.4641
63.357840180, 13.970, 14.0, 3.7417
63.424685255, 13.970, 12.0, 3.4641
63.491530331, 13.970, 18.0, 4.2426
63.558375407, 13.970, 14.0, 3.7417
63.625220483, 13.970, 15.0, 3.8730
63.692065559, 13.970, 13.0, 3.6056
63.758910635, 13.970, 10.0, 3.1623
63.825755711, 13.970, 18.0, 4.2426
63.892600787, 13.970, 5.0, 2.2361
63.959445863, 13.970, 17.0, 4.1231
64.026290939, 13.970, 16.0, 4.0000
64.093136015, 13.970, 14.0, 3.7417
64.159981090, 13.970, 9.0, 3.0000
64.226826166, 13.970, 15.0, 3.8730
64.293671242, 13.970, 21.0, 4.5826
64.360516318, 13.970, 7.0, 2.6458
64.427361394, 13.970, 13.0, 3.6056
64.494206470, 13.970, 12.0, 3.4641
64.561051546, 13.970, 14.0, 3.7417
64.627896622, 13.970, 18.0, 4.2426
64.694741698, 13.970, 15.0, 3.8730
64.761586774, 13.970, 5.0, 2.2361
64.828431850, 13.970, 19.0, 4.3589
64.895276925, 13.970, 16.0, 4.0000
64.962122001, 13.970, 10.0, 3.1623
65.028967077, 13.970, 15.0, 3.8730
65.095812153, 13.970, 17.0, 4.1231
65.162657229, 13.970, 15.0, 3.8730
65.229502305, 13.970, 9.0, 3.0000
65.296347381, 13.970, 9.0, 3.0000
65.363192457, 13.970, 12.0, 3.4641
65.430037533, 13.970, 10.0, 3.1623
65.496882609, 13.970, 17.0, 4.1231
65.563727685, 13.970, 21.0, 4.5826
65.630572760, 13.970, 8.0, 2.8284
65.697417836, 13.970, 17.0, 4.1231
65.764262912, 13.970, 17.0, 4.1231
65.831107988, 13.970, 21.0, 4.5826
65.897953064, 13.970, 18.0, 4.2426
65.964798140, 13.970, 12.0, 3.4641
66.031643216, 13.970, 18.0, 4.2426
66.098488292, 13.970, 17.0, 4.1231
66.165333368, 13.970, 15.0, 3.8730
66.232178444, 13.970, 14.0, 3.7417
66.299023520, 13.970, 15.0, 3.8730
66.365868595, 13.970, 18.0, 4.2426
66.432713671, 13.970, 17.0, 4.1231
66.499558747, 13.970, 8.0, 2.8284
66.566403823, 13.970, 12.0, 3.4641
66.633248899, 13.970, 9.0, 3.0000
66.700093975, 13.970, 17.0, 4.1231
66.766939051, 13.970, 15.0, 3.8730
66.833784127, 13.970, 10.0, 3.1623
66.900629203, 13.970, 13.0, 3.6056
66.967474279, 13.970, 16.0, 4.0000
67.034319355, 13.970, 7.0, 2.6458
67.101164430, 13.970, 12.0, 3.4641
67.168009506, 13.970, 12.0, 3.4641
67.234854582, 13.970, 16.0, 4.0000
67.301699658, 13.970, 14.0, 3.7417
67.368544734, 13.970, 17.0, 4.1231
67.435389810, 13.970, 13.0, 3.6056
67.502234886, 13.970, 16.0, 4.0000
67.569079962, 13.970, 14.0, 3.7417
67.635925038, 13.970, 16.0, 4.0000
67.702770114, 13.970, 19.0, 4.3589
67.769615190, 13.970, 17.0, 4.1231
67.836460266, 13.970, 9.0, 3.0000
67.903305341, 13.970, 14.0, 3.7417
67.970150417, 13.970, 9.0, 3.0000
68.036995493, 13.970, 17.0, 4.1231
68.103840569, 13.970, 17.0, 4.1231
68.170685645, 13.970, 10.0, 3.1623
68.237530721, 13.970, 19.0, 4.3589
68.304375797, 13.970, 16.0, 4.0000
68.371220873, 13.970, 20.0, 4.4721
68.438065949, 13.970, 14.0, 3.7417
68.504911025, 13.970, 15.0, 3.8730
68.571756101, 13.970, 9.0, 3.0000
68.638601176, 13.970, 16.0, 4.0000
68.705446252, 13.970, 19.0, 4.3589
68.772291328, 13.970, 18.0, 4.2426
68.839136404, 13.970, 20.0, 4.4721
68.905981480, 13.970, 14.0, 3.7417
68.972826556, 13.970, 9.0, 3.0000
69.039671632, 13.970, 9.0, 3.0000
69.106516708, 13.970, 15.0, 3.8730
69.173361784, 13.970, 16.0, 4.0000
69.240206860, 13.970, 17.0, 4.1231
69.307051936, 13.970, 9.0, 3.0000
69.373897011, 13.970, 13.0, 3.6056
69.440742087, 13.970, 14.0, 3.7417
69.507587163, 13.970, 15.0, 3.8730
69.574432239, 13.970, 16.0, 4.0000
69.641277315, 13.970, 9.0, 3.0000
69.708122391, 13.970, 9.0, 3.0000
69.774967467, 13.970, 16.0, 4.0000
69.841812543, 13.970, 4.0, 2.0000
69.908657619, 13.970, 14.0, 3.7417
69.975502695, 13.970, 15.0, 3.8730
70.042347771, 13.970, 17.0, 4.1231
70.109192846, 13.970, 12.0, 3.4641
70.176037922, 13.970, 24.0, 4.8990
70.242882998, 13.970, 18.0, 4.2426
70.309728074, 13.970, 10.0, 3.1623
70.376573150, 13.970, 8.0, 2.8284
70.443418226, 13.970, 13.0, 3.6056
70.510263302, 13.970, 10.0, 3.1623
70.577108378, 13.970, 14.0, 3.7417
70.643953454, 13.970, 19.0, 4.3589
70.710798530, 13.970, 24.0, 4.8990
70.777643606, 13.970, 13.0, 3.6056
70.844488681, 13.970, 13.0, 3.6056
70.911333757, 13.970, 13.0, 3.6056
70.978178833, 13.970, 13.0, 3.6056
71.045023909, 13.970, 9.0, 3.0000
71.111868985, 13.970, 16.0, 4.0000
71.178714061, 13.970, 16.0, 4.0000
71.245559137, 13.970, 24.0, 4.8990
71.312404213, 13.970, 14.0, 3.7417
71.379249289, 13.970, 17.0, 4.1231
71.446094365, 13.970, 15.0, 3.8730
71.512939441, 13.970, 18.0, 4.2426
71.579784516, 13.970, 19.0, 4.3589
71.646629592, 13.970, 19.0, 4.3589
71.713474668, 13.970, 18.0, 4.2426
71.780319744, 13.970, 17.0, 4.1231
71.847164820, 13.970, 25.0, 5.0000
71.914009896, 13.970, 18.0, 4.2426
71.980854972, 13.970, 28.0, 5.2915
72.047700048, 13.970, 14.0, 3.7417
72.114545124, 13.970, 14.0, 3.7417
72.181390200, 13.970, 15.0, 3.8730
72.248235276, 13.970, 14.0, 3.7417
72.315080351, 13.970, 9.0, 3.0000
72.381925427, 13.970, 16.0, 4.0000
72.448770503, 13.970, 7.0, 2.6458
72.515615579, 13.970, 13.0, 3.6056
72.582460655, 13.970, 5.0, 2.2361
72.649305731, 13.970, 7.0, 2.6458
72.716150807, 13.970, 14.0, 3.7417
72.782995883, 13.970, 17.0, 4.1231
72.849840959, 13.970, 14.0, 3.7417
72.916686035, 13.970, 16.0, 4.0000
72.983531111, 13.970, 8.0, 2.8284
73.050376186, 13.970, 20.0, 4.4721
73.117221262, 13.970, 12.0, 3.4641
73.184066338, 13.970, 15.0, 3.8730
73.250911414, 13.970, 17.0, 4.1231
73.317756490, 13.970, 17.0, 4.1231
73.384601566, 13.970, 17.0, 4.1231
73.451446642, 13.970, 26.0, 5.0990
73.518291718, 13.970, 24.0, 4.8990
73.585136794, 13.970, 15.0, 3.8730
73.651981870, 13.970, 27.0, 5.1962
73.718826946, 13.970, 21.0, 4.5826
73.785672022, 13.970, 14.0, 3.7417
73.852517097, 13.970, 9.0, 3.0000
73.919362173, 13.970, 19.0, 4.3589
73.986207249, 13.970, 14.0, 3.7417
74.053052325, 13.970, 8.0, 2.8284
74.119897401, 13.970, 12.0, 3.4641
74.186742477, 13.970, 15.0, 3.8730
74.253587553, 13.970, 13.0, 3.6056
74.320432629, 13.970, 9.0, 3.0000
74.387277705, 13.970, 13.0, 3.6056
74.454122781, 13.970, 8.0, 2.8284
74.520967857, 13.970, 5.0, 2.2361
74.587812932, 13.970, 4.0, 2.0000
74.654658008, 13.970, 14.0, 3.7417
74.721503084, 13.970, 9.0, 3.0000
74.788348160, 13.970, 17.0, 4.1231
74.855193236, 13.970, 9.0, 3.0000
74.922038312, 13.970, 10.0, 3.1623
74.988883388, 13.970, 17.0, 4.1231
75.055728464, 13.970, 13.0, 3.6056
75.122573540, 13.970, 13.0, 3.6056
75.189418616, 13.970, 10.0, 3.1623
75.256263692, 13.970, 14.0, 3.7417
75.323108767, 13.970, 9.0, 3.0000
75.389953843, 13.970, 14.0, 3.7417
75.456798919, 13.970, 16.0, 4.0000
75.523643995, 13.970, 14.0, 3.7417
75.590489071, 13.970, 8.0, 2.8284
75.657334147, 13.970, 4.0, 2.0000
75.724179223, 13.970, 4.0, 2.0000
75.791024299, 13.970, 15.0, 3.8730
75.857869375, 13.970, 12.0, 3.4641
75.924714451, 13.970, 7.0, 2.6458
75.991559527, 13.970, 21.0, 4.5826
76.058404602, 13.970, 14.0, 3.7417
76.125249678, 13.970, 9.0, 3.0000
76.192094754, 13.970, 10.0, 3.1623
76.258939830, 13.970, 14.0, 3.7417
76.325784906, 13.970, 12.0, 3.4641
76.392629982, 13.970, 15.0, 3.8730
76.459475058, 13.970, 18.0, 4.2426
76.526320134, 13.970, 10.0, 3.1623
76.593165210, 13.970, 9.0, 3.0000
76.660010286, 13.970, 14.0, 3.7417
76.726855362, 13.970, 7.0, 2.6458
76.793700437, 13.970, 14.0, 3.7417
76.860545513, 13.970, 15.0, 3.8730
76.927390589, 13.970, 6.0, 2.4495
76.994235665, 13.970, 14.0, 3.7417
77.061080741, 13.970, 7.0, 2.6458
77.127925817, 13.970, 14.0, 3.7417
77.194770893, 13.970, 8.0, 2.8284
77.261615969, 13.970, 15.0, 3.8730
77.328461045, 13.970, 15.0, 3.8730
77.395306121, 13.970, 13.0, 3.6056
77.462151197, 13.970, 9.0, 3.0000
77.528996272, 13.970, 6.0, 2.4495
77.595841348, 13.970, 13.0, 3.6056
77.662686424, 13.970, 20.0, 4.4721
77.729531500, 13.970, 14.0, 3.7417
77.796376576, 13.970, 10.0, 3.1623
77.863221652, 13.970, 12.0, 3.4641
77.930066728, 13.970, 10.0, 3.1623
77.996911804, 13.970, 9.0, 3.0000
78.063756880, 13.970, 9.0, 3.0000
78.130601956, 13.970, 16.0, 4.0000
78.197447032, 13.970, 6.0, 2.4495
78.264292107, 13.970, 8.0, 2.8284
78.331137183, 13.970, 14.0, 3.7417
78.397982259, 13.970, 17.0, 4.1231
78.464827335, 13.970, 13.0, 3.6056
78.531672411, 13.970, 14.0, 3.7417
78.598517487, 13.970, 9.0, 3.0000
78.665362563, 13.970, 14.0, 3.7417
78.732207639, 13.970, 15.0, 3.8730
78.799052715, 13.970, 10.0, 3.1623
78.865897791, 13.970, 8.0, 2.8284
78.932742867, 13.970, 20.0, 4.4721
78.999587942, 13.970, 15.0, 3.8730
79.066433018, 13.970, 13.0, 3.6056
79.133278094, 13.970, 6.0, 2.4495
79.200123170, 13.970, 20.0, 4.4721
79.266968246, 13.970, 12.0, 3.4641
79.333813322, 13.970, 3.0, 1.7321
79.400658398, 13.970, 12.0, 3.4641
79.467503474, 13.970, 5.0, 2.2361
79.534348550, 13.970, 9.0, 3.0000
79.601193626, 13.970, 10.0, 3.1623
79.668038702, 13.970, 9.0, 3.0000
79.734883778, 13.970, 13.0, 3.6056
79.801728853, 13.970, 14.0, 3.7417
79.868573929, 13.970, 15.0, 3.8730
79.935419005, 13.970, 9.0, 3.0000
80.002264081, 13.970, 3.0, 1.7321
80.069109157, 13.970, 12.0, 3.4641
80.135954233, 13.970, 10.0, 3.1623
80.202799309, 13.970, 16.0, 4.0000
80.269644385, 13.970, 12.0, 3.4641
80.336489461, 13.970, 10.0, 3.1623
80.403334537, 13.970, 7.0, 2.6458
80.470179613, 13.970, 13.0, 3.6056
80.537024688, 13.970, 15.0, 3.8730
80.603869764, 13.970, 12.0, 3.4641
80.670714840, 13.970, 18.0, 4.2426
80.737559916, 13.970, 10.0, 3.1623
80.804404992, 13.970, 18.0, 4.2426
80.871250068, 13.970, 3.0, 1.7321
80.938095144, 13.970, 8.0, 2.8284
81.004940220, 13.970, 14.0, 3.7417
81.071785296, 13.970, 10.0, 3.1623
81.138630372, 13.970, 17.0, 4.1231
81.205475448, 13.970, 8.0, 2.8284
81.272320523, 13.970, 14.0, 3.7417
81.339165599, 13.970, 17.0, 4.1231
81.406010675, 13.970, 9.0, 3.0000
81.472855751, 13.970, 12.0, 3.4641
81.539700827, 13.970, 15.0, 3.8730
81.606545903, 13.970, 5.0, 2.2361
81.673390979, 13.970, 13.0, 3.6056
81.740236055, 13.970, 13.0, 3.6056
81.807081131, 13.970, 12.0, 3.4641
81.873926207, 13.970, 13.0, 3.6056
81.940771283, 13.970, 8.0, 2.8284
82.007616358, 13.970, 8.0, 2.8284
82.074461434, 13.970, 14.0, 3.7417
82.141306510, 13.970, 17.0, 4.1231
82.208151586, 13.970, 14.0, 3.7417
82.274996662, 13.970, 9.0, 3.0000
82.341841738, 13.970, 14.0, 3.7417
82.408686814, 13.970, 8.0, 2.8284
82.475531890, 13.970, 16.0, 4.0000
82.542376966, 13.970, 9.0, 3.0000
82.609222042, 13.970, 9.0, 3.0000
82.676067118, 13.970, 14.0, 3.7417
82.742912193, 13.970, 9.0, 3.0000
82.809757269, 13.970, 6.0, 2.4495
82.876602345, 13.970, 12.0, 3.4641
82.943447421, 13.970, 10.0, 3.1623
83.010292497, 13.970, 16.0, 4.0000
83.077137573, 13.970, 9.0, 3.0000
83.143982649, 13.970, 8.0, 2.8284
83.210827725, 13.970, 10.0, 3.1623
83.277672801, 13.970, 4.0, 2.0000
83.344517877, 13.970, 13.0, 3.6056
83.411362953, 13.970, 8.0, 2.8284
83.478208028, 13.970, 14.0, 3.7417
83.545053104, 13.970, 15.0, 3.8730
83.611898180, 13.970, 13.0, 3.6056
83.678743256, 13.970, 5.0, 2.2361
83.745588332, 13.970, 9.0, 3.0000
83.812433408, 13.970, 10.0, 3.1623
83.879278484, 13.970, 20.0, 4.4721
83.946123560, 13.970, 4.0, 2.0000
84.012968636, 13.970, 13.0, 3.6056
84.079813712, 13.970, 8.0, 2.8284
84.146658788, 13.970, 9.0, 3.0000
84.213503863, 13.970, 14.0, 3.7417
84.280348939, 13.970, 5.0, 2.2361
84.347194015, 13.970, 7.0, 2.6458
84.414039091, 13.970, 7.0, 2.6458
84.480884167, 13.970, 10.0, 3.1623
84.547729243, 13.970, 7.0, 2.6458
84.614574319, 13.970, 7.0, 2.6458
84.681419395, 13.970, 7.0, 2.6458
84.748264471, 13.970, 10.0, 3.1623
84.815109547, 13.970, 15.0, 3.8730
84.881954623, 13.970, 7.0, 2.6458
84.948799698, 13.970, 8.0, 2.8284
85.015644774, 13.970, 8.0, 2.8284
85.082489850, 13.970, 10.0, 3.1623
85.149334926, 13.970, 12.0, 3.4641
85.216180002, 13.970, 10.0, 3.1623
85.283025078, 13.970, 12.0, 3.4641
85.349870154, 13.970, 14.0, 3.7417
85.416715230, 13.970, 12.0, 3.4641
85.483560306, 13.970, 14.0, 3.7417
85.550405382, 13.970, 7.0, 2.6458
85.617250458, 13.970, 14.0, 3.7417
85.684095534, 13.970, 9.0, 3.0000
85.750940609, 13.970, 14.0, 3.7417
85.817785685, 13.970, 9.0, 3.0000
85.884630761, 13.970, 10.0, 3.1623
85.951475837, 13.970, 16.0, 4.0000
86.018320913, 13.970, 16.0, 4.0000
86.085165989, 13.970, 13.0, 3.6056
86.152011065, 13.970, 20.0, 4.4721
86.218856141, 13.970, 16.0, 4.0000
86.285701217, 13.970, 24.0, 4.8990
86.352546293, 13.970, 18.0, 4.2426
86.419391369, 13.970, 19.0, 4.3589
86.486236444, 13.970, 22.0, 4.6904
86.553081520, 13.970, 40.0, 6.3246
86.619926596, 13.970, 44.0, 6.6332
86.686771672, 13.970, 38.0, 6.1644
86.753616748, 13.970, 48.0, 6.9282
86.820461824, 13.970, 33.0, 5.7446
86.887306900, 13.970, 21.0, 4.5826
86.954151976, 13.970, 29.0, 5.3852
87.020997052, 13.970, 27.0, 5.1962
87.087842128, 13.970, 21.0, 4.5826
87.154687204, 13.970, 26.0, 5.0990
87.221532279, 13.970, 20.0, 4.4721
87.288377355, 13.970, 14.0, 3.7417
87.355222431, 13.970, 20.0, 4.4721
87.422067507, 13.970, 19.0, 4.3589
87.488912583, 13.970, 12.0, 3.4641
87.555757659, 13.970, 16.0, 4.0000
87.622602735, 13.970, 10.0, 3.1623
87.689447811, 13.970, 12.0, 3.4641
87.756292887, 13.970, 14.0, 3.7417
87.823137963, 13.970, 10.0, 3.1623
87.889983039, 13.970, 7.0, 2.6458
87.956828114, 13.970, 8.0, 2.8284
88.023673190, 13.970, 5.0, 2.2361
88.090518266, 13.970, 12.0, 3.4641
88.157363342, 13.970, 15.0, 3.8730
88.224208418, 13.970, 9.0, 3.0000
88.291053494, 13.970, 14.0, 3.7417
88.357898570, 13.970, 4.0, 2.0000
88.424743646, 13.970, 8.0, 2.8284
88.491588722, 13.970, 6.0, 2.4495
88.558433798, 13.970, 12.0, 3.4641
88.625278874, 13.970, 10.0, 3.1623
88.692123949, 13.970, 7.0, 2.6458
88.758969025, 13.970, 15.0, 3.8730
88.825814101, 13.970, 14.0, 3.7417
88.892659177, 13.970, 14.0, 3.7417
88.959504253, 13.970, 7.0, 2.6458
89.026349329, 13.970, 5.0, 2.2361
89.093194405, 13.970, 8.0, 2.8284
89.160039481, 13.970, 14.0, 3.7417
89.226884557, 13.970, 17.0, 4.1231
89.293729633, 13.970, 25.0, 5.0000
89.360574709, 13.970, 17.0, 4.1231
89.427419784, 13.970, 20.0, 4.4721
89.494264860, 13.970, 21.0, 4.5826
89.561109936, 13.970, 15.0, 3.8730
89.627955012, 13.970, 15.0, 3.8730
89.694800088, 13.970, 7.0, 2.6458
89.761645164, 13.970, 4.0, 2.0000
89.828490240, 13.970, 14.0, 3.7417
89.895335316, 13.970, 12.0, 3.4641
89.962180392, 13.970, 12.0, 3.4641
90.029025468, 13.970, 10.0, 3.1623
90.095870544, 13.970, 5.0, 2.2361
90.162715619, 13.970, 6.0, 2.4495
90.229560695, 13.970, 12.0, 3.4641
90.296405771, 13.970, 8.0, 2.8284
90.363250847, 13.970, 14.0, 3.7417
90.430095923, 13.970, 8.0, 2.8284
90.496940999, 13.970, 9.0, 3.0000
90.563786075, 13.970, 5.0, 2.2361
90.630631151, 13.970, 7.0, 2.6458
90.697476227, 13.970, 10.0, 3.1623
90.764321303, 13.970, 6.0, 2.4495
90.831166379, 13.970, 10.0, 3.1623
90.898011454, 13.970, 6.0, 2.4495
90.964856530, 13.970, 14.0, 3.7417
91.031701606, 13.970, 17.0, 4.1231
91.098546682, 13.970, 12.0, 3.4641
91.165391758, 13.970, 10.0, 3.1623
91.232236834, 13.970, 8.0, 2.8284
91.299081910, 13.970, 6.0, 2.4495
91.365926986, 13.970, 4.0, 2.0000
91.432772062, 13.970, 17.0, 4.1231
91.499617138, 13.970, 17.0, 4.1231
91.566462214, 13.970, 10.0, 3.1623
91.633307290, 13.970, 16.0, 4.0000
91.700152365, 13.970, 30.0, 5.4772
91.766997441, 13.970, 30.0, 5.4772
91.833842517, 13.970, 31.0, 5.5678
91.900687593, 13.970, 28.0, 5.2915
91.967532669, 13.970, 29.0, 5.3852
92.034377745, 13.970, 22.0, 4.6904
92.101222821, 13.970, 16.0, 4.0000
92.168067897, 13.970, 10.0, 3.1623
92.234912973, 13.970, 14.0, 3.7417
92.301758049, 13.970, 12.0, 3.4641
92.368603125, 13.970, 9.0, 3.0000
92.435448200, 13.970, 8.0, 2.8284
92.502293276, 13.970, 15.0, 3.8730
92.569138352, 13.970, 6.0, 2.4495
92.635983428, 13.970, 6.0, 2.4495
92.702828504, 13.970, 5.0, 2.2361
92.769673580, 13.970, 10.0, 3.1623
92.836518656, 13.970, 6.0, 2.4495
92.903363732, 13.970, 8.0, 2.8284
92.970208808, 13.970, 13.0, 3.6056
93.037053884, 13.970, 6.0, 2.4495
93.103898960, 13.970, 7.0, 2.6458
93.170744035, 13.970, 3.0, 1.7321
93.237589111, 13.970, 12.0, 3.4641
93.304434187, 13.970, 6.0, 2.4495
93.371279263, 13.970, 8.0, 2.8284
93.438124339, 13.970, 5.0, 2.2361
93.504969415, 13.970, 16.0, 4.0000
93.571814491, 13.970, 9.0, 3.0000
93.638659567, 13.970, 6.0, 2.4495
93.705504643, 13.970, 10.0, 3.1623
93.772349719, 13.970, 8.0, 2.8284
93.839194795, 13.970, 9.0, 3.0000
93.906039870, 13.970, 13.0, 3.6056
93.972884946, 13.970, 12.0, 3.4641
94.039730022, 13.970, 9.0, 3.0000
94.106575098, 13.970, 9.0, 3.0000
94.173420174, 13.970, 14.0, 3.7417
94.240265250, 13.970, 7.0, 2.6458
94.307110326, 13.970, 9.0, 3.0000
94.373955402, 13.970, 10.0, 3.1623
94.440800478, 13.970, 7.0, 2.6458
94.507645554, 13.970, 14.0, 3.7417
94.574490630, 13.970, 17.0, 4.1231
94.641335705, 13.970, 28.0, 5.2915
94.708180781, 13.970, 18.0, 4.2426
94.775025857, 13.970, 12.0, 3.4641
94.841870933, 13.970, 12.0, 3.4641
94.908716009, 13.970, 13.0, 3.6056
94.975561085, 13.970, 13.0, 3.6056
95.042406161, 13.970, 7.0, 2.6458
95.109251237, 13.970, 7.0, 2.6458
95.176096313, 13.970, 8.0, 2.8284
95.242941389, 13.970, 10.0, 3.1623
95.309786465, 13.970, 4.0, 2.0000
95.376631540, 13.970, 4.0, 2.0000
95.443476616, 13.970, 8.0, 2.8284
95.510321692, 13.970, 12.0, 3.4641
95.577166768, 13.970, 5.0, 2.2361
95.644011844, 13.970, 5.0, 2.2361
95.710856920, 13.970, 9.0, 3.0000
95.777701996, 13.970, 7.0, 2.6458
95.844547072, 13.970, 8.0, 2.8284
95.911392148, 13.970, 7.0, 2.6458
95.978237224, 13.970, 7.0, 2.6458
96.045082300, 13.970, 8.0, 2.8284
96.111927375, 13.970, 14.0, 3.7417
96.178772451, 13.970, 9.0, 3.0000
96.245617527, 13.970, 17.0, 4.1231
96.312462603, 13.970, 7.0, 2.6458
96.379307679, 13.970, 9.0, 3.0000
96.446152755, 13.970, 5.0, 2.2361
96.512997831, 13.970, 10.0, 3.1623
96.579842907, 13.970, 8.0, 2.8284
96.646687983, 13.970, 12.0, 3.4641
96.713533059, 13.970, 12.0, 3.4641
96.780378135, 13.970, 14.0, 3.7417
96.847223210, 13.970, 12.0, 3.4641
96.914068286, 13.970, 4.0, 2.0000
96.980913362, 13.970, 4.0, 2.0000
97.047758438, 13.970, 7.0, 2.6458
97.114603514, 13.970, 7.0, 2.6458
97.181448590, 13.970, 9.0, 3.0000
97.248293666, 13.970, 8.0, 2.8284
97.315138742, 13.970, 8.0, 2.8284
97.381983818, 13.970, 6.0, 2.4495
97.448828894, 13.970, 12.0, 3.4641
97.515673970, 13.970, 7.0, 2.6458
97.582519046, 13.970, 9.0, 3.0000
97.649364121, 13.970, 3.0, 1.7321
97.716209197, 13.970, 15.0, 3.8730
97.783054273, 13.970, 6.0, 2.4495
97.849899349, 13.970, 13.0, 3.6056
97.916744425, 13.970, 8.0, 2.8284
97.983589501, 13.970, 14.0, 3.7417
98.050434577, 13.970, 6.0, 2.4495
98.117279653, 13.970, 7.0, 2.6458
98.184124729, 13.970, 8.0, 2.8284
98.250969805, 13.970, 14.0, 3.7417
98.317814881, 13.970, 6.0, 2.4495
98.384659956, 13.970, 9.0, 3.0000
98.451505032, 13.970, 10.0, 3.1623
98.518350108, 13.970, 6.0, 2.4495
98.585195184, 13.970, 3.0, 1.7321
98.652040260, 13.970, 7.0, 2.6458
98.718885336, 13.970, 7.0, 2.6458
98.785730412, 13.970, 12.0, 3.4641
98.852575488, 13.970, 9.0, 3.0000
98.919420564, 13.970, 4.0, 2.0000
98.986265640, 13.970, 3.0, 1.7321
99.053110716, 13.970, 7.0, 2.6458
99.119955791, 13.970, 14.0, 3.7417
99.186800867, 13.970, 5.0, 2.2361
99.253645943, 13.970, 12.0, 3.4641
99.320491019, 13.970, 5.0, 2.2361
99.387336095, 13.970, 6.0, 2.4495
99.454181171, 13.970, 9.0, 3.0000
99.521026247, 13.970, 4.0, 2.0000
99.587871323, 13.970, 8.0, 2.8284
99.654716399, 13.970, 16.0, 4.0000
99.721561475, 13.970, 7.0, 2.6458
99.788406551, 13.970, 9.0, 3.0000
99.855251626, 13.970, 8.0, 2.8284
99.922096702, 13.970, 7.0, 2.6458
99.988941778, 13.970, 6.0, 2.4495
100.001475230, 13.970, 12.0, 3.4641