File: XRD/data/raw/BFO_sample4_secondsputtering.ras
*RAS_DATA_START
*RAS_HEADER_START
*DISP_LINE_COLOR "4294901760"
*FILE_COMMENT ""
*FILE_MD5 ""
*FILE_MEMO ""
*FILE_OPERATOR "Administrator"
*FILE_PACKAGE_NAME ""
*FILE_PART_ID "GeneralMeasurement"
*FILE_SAMPLE ""
*FILE_SYSTEM_NAME "SmartLab"
*FILE_TYPE "RAS_RAW"
*FILE_USERGROUP "Administrators"
*FILE_VERSION "1"
*HW_ATTACHMENT_ID "ATT0025"
*HW_ATTACHMENT_NAME "Standard"
*HW_ATTACHMENT_NAME_INTERNAL "Standard"
*HW_COUNTER_ID-0 "CUT0051"
*HW_COUNTER_ID-1 "CMC0020"
*HW_COUNTER_MONOCHRO_ID "CMC0020"
*HW_COUNTER_MONOCHRO_NAME "None"
*HW_COUNTER_MONOCHRO_NAME_INTERNAL "None"
*HW_COUNTER_NAME_INTERNAL "HyPix3000(H)"
*HW_COUNTER_NAME-0 "HyPix3000(H)"
*HW_COUNTER_NAME-1 "None"
*HW_COUNTER_SELECT_NAME "HyPix3000(H)"
*HW_EXTERNAL_CONTROLLER_NAME "None"
*HW_EXTERNAL_CONTROLLER_NAME_INTERNAL "None"
*HW_GONIOMETER_ID "GON0021"
*HW_GONIOMETER_NAME "StandardEnc"
*HW_GONIOMETER_NAME_INTERNAL "StandardEnc"
*HW_GONIOMETER_RADIUS-0 "90.0"
*HW_GONIOMETER_RADIUS-1 "114.0"
*HW_GONIOMETER_RADIUS-2 "190.0"
*HW_GONIOMETER_RADIUS-3 "300.0"
*HW_GONIOMETER_RADIUS-4 "187.0"
*HW_GONIOMETER_RADIUS-5 "300.0"
*HW_GONIOMETER_RADIUS-6 "113.0000"
*HW_GONIOMETER_RADIUS-7 "331.0"
*HW_I_CBO_ID "CBO0021"
*HW_I_CBO_NAME "CBO"
*HW_I_CBO_NAME_INTERNAL "CBO"
*HW_I_MONOCHRO_ID "ISO0021"
*HW_I_MONOCHRO_NAME "IPS_adaptor"
*HW_I_MONOCHRO_NAME_INTERNAL "IPS_adaptor"
*HW_I_OPT_ID-0 "CBO0021"
*HW_I_OPT_ID-1 "ISL0021"
*HW_I_PRIMARY_NAME_INTERNAL "Standard"
*HW_I_SLIT_ID "ISL0021"
*HW_I_SLIT_NAME "Auto"
*HW_I_SLIT_NAME_INTERNAL "Auto"
*HW_R_ATTENUATER_AUTOMODE "0"
*HW_R_ATTENUATER_ID "ATN0020"
*HW_R_ATTENUATER_NAME "No_unit"
*HW_R_ATTENUATOR_NAME_INTERNAL "No_unit"
*HW_R_OPT_ID-0 "RSS0022"
*HW_R_OPT_ID-1 "RCR0022"
*HW_R_OPT_ID-2 "RSO0021"
*HW_R_OPT_ID-3 "RRS0022"
*HW_R_OPT_ID-4 "ATN0020"
*HW_R_ROD_ID "RCR0022"
*HW_R_ROD_NAME "ROD_adaptor"
*HW_R_ROD_NAME_INTERNAL "ROD_adaptor"
*HW_R_RPS_ID "RSO0021"
*HW_R_RPS_NAME "RPS_adaptor"
*HW_R_RPS_NAME_INTERNAL "RPS_adaptor"
*HW_R_RS_ID "RRS0022"
*HW_R_RS_NAME "Virtual"
*HW_R_RS_NAME_INTERNAL "Virtual"
*HW_R_SS_ID "RSS0022"
*HW_R_SS_NAME "Auto_Zr"
*HW_R_SS_NAME_INTERNAL "Auto_Zr"
*HW_ROBOT_NAME "No_unit"
*HW_ROBOT_NAME_INTERNAL "No_unit"
*HW_SAMPLE_CAMERA_NAME "SampleCamera_Std"
*HW_SAMPLE_CAMERA_NAME_INTERNAL "SampleCamera_Std"
*HW_SAMPLE_HOLDER_ID "SMP0021"
*HW_SAMPLE_HOLDER_NAME "Z_ChiPhi"
*HW_SAMPLE_HOLDER_NAME_INTERNAL "Z_ChiPhi"
*HW_SAMPLE_NAME "WaferSample"
*HW_SAMPLE_NAME_INTERNAL "WaferSample"
*HW_SAMPLE_PLATE_NAME "ForWafer"
*HW_SAMPLE_PLATE_NAME_INTERNAL "ForWafer"
*HW_SAMPLE_SPACER_NAME "0-3mm"
*HW_SAMPLE_SPACER_NAME_INTERNAL "0-3mm"
*HW_USERINFO_CATALOG_NO ""
*HW_USERINFO_INSTRUMENT_ID ""
*HW_USERINFO_INSTRUMENT_NAME ""
*HW_USERINFO_MODEL ""
*HW_USERINFO_ORDER_NO ""
*HW_USERINFO_SERIAL_NO ""
*HW_USERINFO_VERIFY_INSTRUMENT_ID "00-07-fe-01-14-97"
*HW_VER_RCD_COUNTER_UNIT "1.0.1"
*HW_VER_RCD_CPU "3.2.2"
*HW_VER_RCD_FPGA "1.2.3"
*HW_VER_RCD_GONIO_UNIT "6.1.1"
*HW_VER_RCD_INCIDENT_UNIT "6.1.1"
*HW_VER_RCD_RECEIVING_UNIT "6.1.1"
*HW_VER_RCD_TYPE "RINC"
*HW_VER_XGC_CPU "3.2.2"
*HW_VER_XGC_CW "1.4.9"
*HW_VER_XGC_HV "1.4.9"
*HW_VER_XGC_RS1 "1.4.9"
*HW_VER_XGC_RS2 "N/A"
*HW_VER_XGC_RT "N/A"
*HW_VER_XGC_TYPE "RINC"
*HW_XG_CURRENT_UNIT "mA"
*HW_XG_FOCUS "0.4mm x 12mm"
*HW_XG_FOCUS_TYPE "LongFine"
*HW_XG_TARGET_ATOMIC_NUMBER "29"
*HW_XG_TARGET_NAME "Cu"
*HW_XG_TYPE "Hermetic"
*HW_XG_VOLTAGE_UNIT "kV"
*HW_XG_WAVE_LENGTH_ALPHA1 "1.540593"
*HW_XG_WAVE_LENGTH_ALPHA2 "1.544414"
*HW_XG_WAVE_LENGTH_BETA "1.392246"
*HW_XG_WAVE_LENGTH_UNIT "Angstrom"
*MEAS_COND_AXIS_NAME_INTERNAL-0 "ThetaS"
*MEAS_COND_AXIS_NAME_INTERNAL-1 "ThetaD"
*MEAS_COND_AXIS_NAME_INTERNAL-10 "CBOType"
*MEAS_COND_AXIS_NAME_INTERNAL-11 "CBO-M"
*MEAS_COND_AXIS_NAME_INTERNAL-12 "CBO"
*MEAS_COND_AXIS_NAME_INTERNAL-13 "IncidentSollerSlit"
*MEAS_COND_AXIS_NAME_INTERNAL-14 "IncidentSlitBox"
*MEAS_COND_AXIS_NAME_INTERNAL-15 "IncidentSlitBox-_Axis"
*MEAS_COND_AXIS_NAME_INTERNAL-16 "SlitDS"
*MEAS_COND_AXIS_NAME_INTERNAL-17 "Zs"
*MEAS_COND_AXIS_NAME_INTERNAL-18 "IncidentAxdSlit"
*MEAS_COND_AXIS_NAME_INTERNAL-19 "LLS"
*MEAS_COND_AXIS_NAME_INTERNAL-2 "TwoTheta"
*MEAS_COND_AXIS_NAME_INTERNAL-20 "DHLSlit"
*MEAS_COND_AXIS_NAME_INTERNAL-21 "Chi"
*MEAS_COND_AXIS_NAME_INTERNAL-22 "Phi"
*MEAS_COND_AXIS_NAME_INTERNAL-23 "Z"
*MEAS_COND_AXIS_NAME_INTERNAL-24 "Alpha"
*MEAS_COND_AXIS_NAME_INTERNAL-25 "Beta"
*MEAS_COND_AXIS_NAME_INTERNAL-26 "ReceivingSlitBox1"
*MEAS_COND_AXIS_NAME_INTERNAL-27 "ReceivingSlitBox1-_Axis"
*MEAS_COND_AXIS_NAME_INTERNAL-28 "SlitSS"
*MEAS_COND_AXIS_NAME_INTERNAL-29 "Zr"
*MEAS_COND_AXIS_NAME_INTERNAL-3 "Omega"
*MEAS_COND_AXIS_NAME_INTERNAL-30 "Filter"
*MEAS_COND_AXIS_NAME_INTERNAL-31 "PSA"
*MEAS_COND_AXIS_NAME_INTERNAL-32 "ReceivingSollerSlit"
*MEAS_COND_AXIS_NAME_INTERNAL-33 "ReceivingSlitBox2"
*MEAS_COND_AXIS_NAME_INTERNAL-34 "ReceivingSlitBox2-_Axis"
*MEAS_COND_AXIS_NAME_INTERNAL-35 "SlitRS"
*MEAS_COND_AXIS_NAME_INTERNAL-36 "ModuleSensorType"
*MEAS_COND_AXIS_NAME_INTERNAL-37 "PHA"
*MEAS_COND_AXIS_NAME_INTERNAL-38 "DetectorBeamStop"
*MEAS_COND_AXIS_NAME_INTERNAL-39 "DetectorFilter"
*MEAS_COND_AXIS_NAME_INTERNAL-4 "TwoThetaTheta"
*MEAS_COND_AXIS_NAME_INTERNAL-40 "DedicatedHolder"
*MEAS_COND_AXIS_NAME_INTERNAL-41 "Target_TargetTime"
*MEAS_COND_AXIS_NAME_INTERNAL-42 "Target_XrayOnTime"
*MEAS_COND_AXIS_NAME_INTERNAL-43 "Target_TMPTime"
*MEAS_COND_AXIS_NAME_INTERNAL-44 "Target_RPTime"
*MEAS_COND_AXIS_NAME_INTERNAL-45 "Target_FilamentTime"
*MEAS_COND_AXIS_NAME_INTERNAL-46 "Target_IG"
*MEAS_COND_AXIS_NAME_INTERNAL-47 "Target_GP"
*MEAS_COND_AXIS_NAME_INTERNAL-48 "Target_FC"
*MEAS_COND_AXIS_NAME_INTERNAL-49 "HVPS_HVPSTime"
*MEAS_COND_AXIS_NAME_INTERNAL-5 "TwoThetaOmega"
*MEAS_COND_AXIS_NAME_INTERNAL-50 "HVPS_Type1Time"
*MEAS_COND_AXIS_NAME_INTERNAL-51 "HVPS_Type2Time"
*MEAS_COND_AXIS_NAME_INTERNAL-52 "HVPS_Type3Time"
*MEAS_COND_AXIS_NAME_INTERNAL-53 "CW_IERTime"
*MEAS_COND_AXIS_NAME_INTERNAL-54 "CW_ECTime"
*MEAS_COND_AXIS_NAME_INTERNAL-55 "CW_Flow1"
*MEAS_COND_AXIS_NAME_INTERNAL-56 "CW_Temperature1"
*MEAS_COND_AXIS_NAME_INTERNAL-57 "CW_Pressure1"
*MEAS_COND_AXIS_NAME_INTERNAL-58 "CW_PressureIn"
*MEAS_COND_AXIS_NAME_INTERNAL-59 "CW_PressureOut"
*MEAS_COND_AXIS_NAME_INTERNAL-6 "OmegaTwoTheta"
*MEAS_COND_AXIS_NAME_INTERNAL-60 "CW_Flow2"
*MEAS_COND_AXIS_NAME_INTERNAL-61 "CW_Temperature2"
*MEAS_COND_AXIS_NAME_INTERNAL-62 "CW_Pressure2"
*MEAS_COND_AXIS_NAME_INTERNAL-63 "RE_EnclosureTemp"
*MEAS_COND_AXIS_NAME_INTERNAL-64 "RE_EnclosureHummidity"
*MEAS_COND_AXIS_NAME_INTERNAL-65 "RE_CabinetTemp"
*MEAS_COND_AXIS_NAME_INTERNAL-66 "RE_RPTemp"
*MEAS_COND_AXIS_NAME_INTERNAL-67 "RE_ShutterAXrayOnTime"
*MEAS_COND_AXIS_NAME_INTERNAL-68 "RE_ShutterATimes"
*MEAS_COND_AXIS_NAME_INTERNAL-69 "RE_ShutterAOpenCloseTime"
*MEAS_COND_AXIS_NAME_INTERNAL-7 "Ts"
*MEAS_COND_AXIS_NAME_INTERNAL-70 "RE_ShutterACloseOpenTime"
*MEAS_COND_AXIS_NAME_INTERNAL-71 "RE_ShutterBXrayOnTime"
*MEAS_COND_AXIS_NAME_INTERNAL-72 "RE_ShutterBTimes"
*MEAS_COND_AXIS_NAME_INTERNAL-73 "RE_ShutterBOpenCloseTime"
*MEAS_COND_AXIS_NAME_INTERNAL-74 "RE_ShutterBCloseOpenTime"
*MEAS_COND_AXIS_NAME_INTERNAL-75 "RE_XrayWarningRamp"
*MEAS_COND_AXIS_NAME_INTERNAL-76 "RE_ShutterAInstallation"
*MEAS_COND_AXIS_NAME_INTERNAL-77 "RE_ShutterARamp"
*MEAS_COND_AXIS_NAME_INTERNAL-78 "RE_ShutterBInstallation"
*MEAS_COND_AXIS_NAME_INTERNAL-79 "RE_ShutterBRamp"
*MEAS_COND_AXIS_NAME_INTERNAL-8 "PrimaryGeometry"
*MEAS_COND_AXIS_NAME_INTERNAL-80 "RE_ExtShutterCLS"
*MEAS_COND_AXIS_NAME_INTERNAL-81 "RE_ExtXrayOFF"
*MEAS_COND_AXIS_NAME_INTERNAL-82 "RE_ExtSafetyCircuit"
*MEAS_COND_AXIS_NAME_INTERNAL-83 "Version_CPU"
*MEAS_COND_AXIS_NAME_INTERNAL-84 "Version_RS1"
*MEAS_COND_AXIS_NAME_INTERNAL-85 "Version_RS2"
*MEAS_COND_AXIS_NAME_INTERNAL-86 "Version_HV"
*MEAS_COND_AXIS_NAME_INTERNAL-87 "Version_CW"
*MEAS_COND_AXIS_NAME_INTERNAL-88 "Version_RT"
*MEAS_COND_AXIS_NAME_INTERNAL-89 "Lens"
*MEAS_COND_AXIS_NAME_INTERNAL-9 "PrimaryMirrorType"
*MEAS_COND_AXIS_NAME_INTERNAL-90 "IncidentPrimary"
*MEAS_COND_AXIS_NAME_INTERNAL-91 "IncidentMonochromator"
*MEAS_COND_AXIS_NAME_INTERNAL-92 "ReceivingOptics"
*MEAS_COND_AXIS_NAME_INTERNAL-93 "CounterMonochromatorKind"
*MEAS_COND_AXIS_NAME-0 "ThetaS"
*MEAS_COND_AXIS_NAME-1 "ThetaD"
*MEAS_COND_AXIS_NAME-10 "CBOType"
*MEAS_COND_AXIS_NAME-11 "CBO-M"
*MEAS_COND_AXIS_NAME-12 "CBO"
*MEAS_COND_AXIS_NAME-13 "IncidentSollerSlit"
*MEAS_COND_AXIS_NAME-14 "IncidentSlitBox"
*MEAS_COND_AXIS_NAME-15 "IncidentSlitBox-_Axis"
*MEAS_COND_AXIS_NAME-16 "SlitDS"
*MEAS_COND_AXIS_NAME-17 "Zs"
*MEAS_COND_AXIS_NAME-18 "IncidentAxdSlit"
*MEAS_COND_AXIS_NAME-19 "LLS"
*MEAS_COND_AXIS_NAME-2 "TwoTheta"
*MEAS_COND_AXIS_NAME-20 "DHLSlit"
*MEAS_COND_AXIS_NAME-21 "Chi"
*MEAS_COND_AXIS_NAME-22 "Phi"
*MEAS_COND_AXIS_NAME-23 "Z"
*MEAS_COND_AXIS_NAME-24 "Alpha"
*MEAS_COND_AXIS_NAME-25 "Beta"
*MEAS_COND_AXIS_NAME-26 "ReceivingSlitBox1"
*MEAS_COND_AXIS_NAME-27 "ReceivingSlitBox1-_Axis"
*MEAS_COND_AXIS_NAME-28 "SlitSS"
*MEAS_COND_AXIS_NAME-29 "Zr"
*MEAS_COND_AXIS_NAME-3 "Omega"
*MEAS_COND_AXIS_NAME-30 "Filter"
*MEAS_COND_AXIS_NAME-31 "PSA"
*MEAS_COND_AXIS_NAME-32 "ReceivingSollerSlit"
*MEAS_COND_AXIS_NAME-33 "ReceivingSlitBox2"
*MEAS_COND_AXIS_NAME-34 "ReceivingSlitBox2-_Axis"
*MEAS_COND_AXIS_NAME-35 "SlitRS"
*MEAS_COND_AXIS_NAME-36 "ModuleSensorType"
*MEAS_COND_AXIS_NAME-37 "PHA"
*MEAS_COND_AXIS_NAME-38 "DetectorBeamStop"
*MEAS_COND_AXIS_NAME-39 "DetectorFilter"
*MEAS_COND_AXIS_NAME-4 "TwoThetaTheta"
*MEAS_COND_AXIS_NAME-40 "DedicatedHolder"
*MEAS_COND_AXIS_NAME-41 "Target_TargetTime"
*MEAS_COND_AXIS_NAME-42 "Target_XrayOnTime"
*MEAS_COND_AXIS_NAME-43 "Target_TMPTime"
*MEAS_COND_AXIS_NAME-44 "Target_RPTime"
*MEAS_COND_AXIS_NAME-45 "Target_FilamentTime"
*MEAS_COND_AXIS_NAME-46 "Target_IG"
*MEAS_COND_AXIS_NAME-47 "Target_GP"
*MEAS_COND_AXIS_NAME-48 "Target_FC"
*MEAS_COND_AXIS_NAME-49 "HVPS_HVPSTime"
*MEAS_COND_AXIS_NAME-5 "TwoThetaOmega"
*MEAS_COND_AXIS_NAME-50 "HVPS_Type1Time"
*MEAS_COND_AXIS_NAME-51 "HVPS_Type2Time"
*MEAS_COND_AXIS_NAME-52 "HVPS_Type3Time"
*MEAS_COND_AXIS_NAME-53 "CW_IERTime"
*MEAS_COND_AXIS_NAME-54 "CW_ECTime"
*MEAS_COND_AXIS_NAME-55 "CW_Flow1"
*MEAS_COND_AXIS_NAME-56 "CW_Temperature1"
*MEAS_COND_AXIS_NAME-57 "CW_Pressure1"
*MEAS_COND_AXIS_NAME-58 "CW_PressureIn"
*MEAS_COND_AXIS_NAME-59 "CW_PressureOut"
*MEAS_COND_AXIS_NAME-6 "OmegaTwoTheta"
*MEAS_COND_AXIS_NAME-60 "CW_Flow2"
*MEAS_COND_AXIS_NAME-61 "CW_Temperature2"
*MEAS_COND_AXIS_NAME-62 "CW_Pressure2"
*MEAS_COND_AXIS_NAME-63 "RE_EnclosureTemp"
*MEAS_COND_AXIS_NAME-64 "RE_EnclosureHummidity"
*MEAS_COND_AXIS_NAME-65 "RE_CabinetTemp"
*MEAS_COND_AXIS_NAME-66 "RE_RPTemp"
*MEAS_COND_AXIS_NAME-67 "RE_ShutterAXrayOnTime"
*MEAS_COND_AXIS_NAME-68 "RE_ShutterATimes"
*MEAS_COND_AXIS_NAME-69 "RE_ShutterAOpenCloseTime"
*MEAS_COND_AXIS_NAME-7 "Ts"
*MEAS_COND_AXIS_NAME-70 "RE_ShutterACloseOpenTime"
*MEAS_COND_AXIS_NAME-71 "RE_ShutterBXrayOnTime"
*MEAS_COND_AXIS_NAME-72 "RE_ShutterBTimes"
*MEAS_COND_AXIS_NAME-73 "RE_ShutterBOpenCloseTime"
*MEAS_COND_AXIS_NAME-74 "RE_ShutterBCloseOpenTime"
*MEAS_COND_AXIS_NAME-75 "RE_XrayWarningRamp"
*MEAS_COND_AXIS_NAME-76 "RE_ShutterAInstallation"
*MEAS_COND_AXIS_NAME-77 "RE_ShutterARamp"
*MEAS_COND_AXIS_NAME-78 "RE_ShutterBInstallation"
*MEAS_COND_AXIS_NAME-79 "RE_ShutterBRamp"
*MEAS_COND_AXIS_NAME-8 "PrimaryGeometry"
*MEAS_COND_AXIS_NAME-80 "RE_ExtShutterCLS"
*MEAS_COND_AXIS_NAME-81 "RE_ExtXrayOFF"
*MEAS_COND_AXIS_NAME-82 "RE_ExtSafetyCircuit"
*MEAS_COND_AXIS_NAME-83 "Version_CPU"
*MEAS_COND_AXIS_NAME-84 "Version_RS1"
*MEAS_COND_AXIS_NAME-85 "Version_RS2"
*MEAS_COND_AXIS_NAME-86 "Version_HV"
*MEAS_COND_AXIS_NAME-87 "Version_CW"
*MEAS_COND_AXIS_NAME-88 "Version_RT"
*MEAS_COND_AXIS_NAME-89 "Lens"
*MEAS_COND_AXIS_NAME-9 "PrimaryMirrorType"
*MEAS_COND_AXIS_NAME-90 "IncidentPrimary"
*MEAS_COND_AXIS_NAME-91 "IncidentMonochromator"
*MEAS_COND_AXIS_NAME-92 "ReceivingOptics"
*MEAS_COND_AXIS_NAME-93 "CounterMonochromatorKind"
*MEAS_COND_AXIS_OFFSET-0 "1.5548"
*MEAS_COND_AXIS_OFFSET-1 "-0.2629"
*MEAS_COND_AXIS_OFFSET-10 "0"
*MEAS_COND_AXIS_OFFSET-11 "0"
*MEAS_COND_AXIS_OFFSET-12 "0"
*MEAS_COND_AXIS_OFFSET-13 "0"
*MEAS_COND_AXIS_OFFSET-14 "0"
*MEAS_COND_AXIS_OFFSET-15 "0"
*MEAS_COND_AXIS_OFFSET-16 "0"
*MEAS_COND_AXIS_OFFSET-17 "0"
*MEAS_COND_AXIS_OFFSET-18 "0"
*MEAS_COND_AXIS_OFFSET-19 "0"
*MEAS_COND_AXIS_OFFSET-2 "1.2919"
*MEAS_COND_AXIS_OFFSET-20 "0"
*MEAS_COND_AXIS_OFFSET-21 "0"
*MEAS_COND_AXIS_OFFSET-22 "0"
*MEAS_COND_AXIS_OFFSET-23 "0"
*MEAS_COND_AXIS_OFFSET-24 "0"
*MEAS_COND_AXIS_OFFSET-25 "0"
*MEAS_COND_AXIS_OFFSET-26 "0"
*MEAS_COND_AXIS_OFFSET-27 "0"
*MEAS_COND_AXIS_OFFSET-28 "0"
*MEAS_COND_AXIS_OFFSET-29 "0"
*MEAS_COND_AXIS_OFFSET-3 "1.5548"
*MEAS_COND_AXIS_OFFSET-30 "0"
*MEAS_COND_AXIS_OFFSET-31 "0"
*MEAS_COND_AXIS_OFFSET-32 "0"
*MEAS_COND_AXIS_OFFSET-33 "0"
*MEAS_COND_AXIS_OFFSET-34 "0"
*MEAS_COND_AXIS_OFFSET-35 "0"
*MEAS_COND_AXIS_OFFSET-36 "0"
*MEAS_COND_AXIS_OFFSET-37 "0"
*MEAS_COND_AXIS_OFFSET-38 "0"
*MEAS_COND_AXIS_OFFSET-39 "0"
*MEAS_COND_AXIS_OFFSET-4 "0"
*MEAS_COND_AXIS_OFFSET-40 "0"
*MEAS_COND_AXIS_OFFSET-41 "0"
*MEAS_COND_AXIS_OFFSET-42 "0"
*MEAS_COND_AXIS_OFFSET-43 "0"
*MEAS_COND_AXIS_OFFSET-44 "0"
*MEAS_COND_AXIS_OFFSET-45 "0"
*MEAS_COND_AXIS_OFFSET-46 "0"
*MEAS_COND_AXIS_OFFSET-47 "0"
*MEAS_COND_AXIS_OFFSET-48 "0"
*MEAS_COND_AXIS_OFFSET-49 "0"
*MEAS_COND_AXIS_OFFSET-5 "0"
*MEAS_COND_AXIS_OFFSET-50 "0"
*MEAS_COND_AXIS_OFFSET-51 "0"
*MEAS_COND_AXIS_OFFSET-52 "0"
*MEAS_COND_AXIS_OFFSET-53 "0"
*MEAS_COND_AXIS_OFFSET-54 "0"
*MEAS_COND_AXIS_OFFSET-55 "0"
*MEAS_COND_AXIS_OFFSET-56 "0"
*MEAS_COND_AXIS_OFFSET-57 "0"
*MEAS_COND_AXIS_OFFSET-58 "0"
*MEAS_COND_AXIS_OFFSET-59 "0"
*MEAS_COND_AXIS_OFFSET-6 "0"
*MEAS_COND_AXIS_OFFSET-60 "0"
*MEAS_COND_AXIS_OFFSET-61 "0"
*MEAS_COND_AXIS_OFFSET-62 "0"
*MEAS_COND_AXIS_OFFSET-63 "0"
*MEAS_COND_AXIS_OFFSET-64 "0"
*MEAS_COND_AXIS_OFFSET-65 "0"
*MEAS_COND_AXIS_OFFSET-66 "0"
*MEAS_COND_AXIS_OFFSET-67 "0"
*MEAS_COND_AXIS_OFFSET-68 "0"
*MEAS_COND_AXIS_OFFSET-69 "0"
*MEAS_COND_AXIS_OFFSET-7 "0"
*MEAS_COND_AXIS_OFFSET-70 "0"
*MEAS_COND_AXIS_OFFSET-71 "0"
*MEAS_COND_AXIS_OFFSET-72 "0"
*MEAS_COND_AXIS_OFFSET-73 "0"
*MEAS_COND_AXIS_OFFSET-74 "0"
*MEAS_COND_AXIS_OFFSET-75 "0"
*MEAS_COND_AXIS_OFFSET-76 "0"
*MEAS_COND_AXIS_OFFSET-77 "0"
*MEAS_COND_AXIS_OFFSET-78 "0"
*MEAS_COND_AXIS_OFFSET-79 "0"
*MEAS_COND_AXIS_OFFSET-8 "0"
*MEAS_COND_AXIS_OFFSET-80 "0"
*MEAS_COND_AXIS_OFFSET-81 "0"
*MEAS_COND_AXIS_OFFSET-82 "0"
*MEAS_COND_AXIS_OFFSET-83 "0"
*MEAS_COND_AXIS_OFFSET-84 "0"
*MEAS_COND_AXIS_OFFSET-85 "0"
*MEAS_COND_AXIS_OFFSET-86 "0"
*MEAS_COND_AXIS_OFFSET-87 "0"
*MEAS_COND_AXIS_OFFSET-88 "0"
*MEAS_COND_AXIS_OFFSET-89 "0"
*MEAS_COND_AXIS_OFFSET-9 "0"
*MEAS_COND_AXIS_OFFSET-90 "0"
*MEAS_COND_AXIS_OFFSET-91 "0"
*MEAS_COND_AXIS_OFFSET-92 "0"
*MEAS_COND_AXIS_OFFSET-93 "0"
*MEAS_COND_AXIS_POSITION-0 "0.0000"
*MEAS_COND_AXIS_POSITION-1 "0.0000"
*MEAS_COND_AXIS_POSITION-10 "Type1"
*MEAS_COND_AXIS_POSITION-11 "0"
*MEAS_COND_AXIS_POSITION-12 "PB"
*MEAS_COND_AXIS_POSITION-13 "Soller_slit_2.5deg"
*MEAS_COND_AXIS_POSITION-14 "1.000mm"
*MEAS_COND_AXIS_POSITION-15 "1.000000"
*MEAS_COND_AXIS_POSITION-16 "1.000mm"
*MEAS_COND_AXIS_POSITION-17 "-0.6371875"
*MEAS_COND_AXIS_POSITION-18 "5mm"
*MEAS_COND_AXIS_POSITION-19 "5mm"
*MEAS_COND_AXIS_POSITION-2 "0.0000"
*MEAS_COND_AXIS_POSITION-20 "5mm"
*MEAS_COND_AXIS_POSITION-21 "0.000"
*MEAS_COND_AXIS_POSITION-22 "0.000"
*MEAS_COND_AXIS_POSITION-23 "-0.5876"
*MEAS_COND_AXIS_POSITION-24 "90.000"
*MEAS_COND_AXIS_POSITION-25 "0.000"
*MEAS_COND_AXIS_POSITION-26 "1.000mm"
*MEAS_COND_AXIS_POSITION-27 "1.000000"
*MEAS_COND_AXIS_POSITION-28 "1.000mm"
*MEAS_COND_AXIS_POSITION-29 "-0.0084375"
*MEAS_COND_AXIS_POSITION-3 "0.0000"
*MEAS_COND_AXIS_POSITION-30 "Cu_K-beta"
*MEAS_COND_AXIS_POSITION-31 "PSA_open"
*MEAS_COND_AXIS_POSITION-32 "Soller_slit_2.5deg"
*MEAS_COND_AXIS_POSITION-33 "1.100mm"
*MEAS_COND_AXIS_POSITION-34 "1.1"
*MEAS_COND_AXIS_POSITION-35 "1.100mm"
*MEAS_COND_AXIS_POSITION-36 "AC"
*MEAS_COND_AXIS_POSITION-37 ""
*MEAS_COND_AXIS_POSITION-38 "None"
*MEAS_COND_AXIS_POSITION-39 "None"
*MEAS_COND_AXIS_POSITION-4 "0.0000"
*MEAS_COND_AXIS_POSITION-40 "None"
*MEAS_COND_AXIS_POSITION-41 ""
*MEAS_COND_AXIS_POSITION-42 ""
*MEAS_COND_AXIS_POSITION-43 ""
*MEAS_COND_AXIS_POSITION-44 ""
*MEAS_COND_AXIS_POSITION-45 ""
*MEAS_COND_AXIS_POSITION-46 ""
*MEAS_COND_AXIS_POSITION-47 ""
*MEAS_COND_AXIS_POSITION-48 ""
*MEAS_COND_AXIS_POSITION-49 ""
*MEAS_COND_AXIS_POSITION-5 "0.0000"
*MEAS_COND_AXIS_POSITION-50 ""
*MEAS_COND_AXIS_POSITION-51 ""
*MEAS_COND_AXIS_POSITION-52 ""
*MEAS_COND_AXIS_POSITION-53 ""
*MEAS_COND_AXIS_POSITION-54 ""
*MEAS_COND_AXIS_POSITION-55 ""
*MEAS_COND_AXIS_POSITION-56 ""
*MEAS_COND_AXIS_POSITION-57 ""
*MEAS_COND_AXIS_POSITION-58 ""
*MEAS_COND_AXIS_POSITION-59 ""
*MEAS_COND_AXIS_POSITION-6 "0.0000"
*MEAS_COND_AXIS_POSITION-60 ""
*MEAS_COND_AXIS_POSITION-61 ""
*MEAS_COND_AXIS_POSITION-62 ""
*MEAS_COND_AXIS_POSITION-63 ""
*MEAS_COND_AXIS_POSITION-64 ""
*MEAS_COND_AXIS_POSITION-65 ""
*MEAS_COND_AXIS_POSITION-66 ""
*MEAS_COND_AXIS_POSITION-67 ""
*MEAS_COND_AXIS_POSITION-68 ""
*MEAS_COND_AXIS_POSITION-69 ""
*MEAS_COND_AXIS_POSITION-7 "0.4552500"
*MEAS_COND_AXIS_POSITION-70 ""
*MEAS_COND_AXIS_POSITION-71 ""
*MEAS_COND_AXIS_POSITION-72 ""
*MEAS_COND_AXIS_POSITION-73 ""
*MEAS_COND_AXIS_POSITION-74 ""
*MEAS_COND_AXIS_POSITION-75 ""
*MEAS_COND_AXIS_POSITION-76 ""
*MEAS_COND_AXIS_POSITION-77 ""
*MEAS_COND_AXIS_POSITION-78 ""
*MEAS_COND_AXIS_POSITION-79 ""
*MEAS_COND_AXIS_POSITION-8 "Right"
*MEAS_COND_AXIS_POSITION-80 ""
*MEAS_COND_AXIS_POSITION-81 ""
*MEAS_COND_AXIS_POSITION-82 ""
*MEAS_COND_AXIS_POSITION-83 ""
*MEAS_COND_AXIS_POSITION-84 ""
*MEAS_COND_AXIS_POSITION-85 ""
*MEAS_COND_AXIS_POSITION-86 ""
*MEAS_COND_AXIS_POSITION-87 ""
*MEAS_COND_AXIS_POSITION-88 ""
*MEAS_COND_AXIS_POSITION-89 "1"
*MEAS_COND_AXIS_POSITION-9 "None"
*MEAS_COND_AXIS_POSITION-90 "Standard"
*MEAS_COND_AXIS_POSITION-91 "IPS_adaptor"
*MEAS_COND_AXIS_POSITION-92 "PSA_open"
*MEAS_COND_AXIS_POSITION-93 "None"
*MEAS_COND_AXIS_UNIT-0 "deg"
*MEAS_COND_AXIS_UNIT-1 "deg"
*MEAS_COND_AXIS_UNIT-10 ""
*MEAS_COND_AXIS_UNIT-11 "pulse"
*MEAS_COND_AXIS_UNIT-12 ""
*MEAS_COND_AXIS_UNIT-13 ""
*MEAS_COND_AXIS_UNIT-14 ""
*MEAS_COND_AXIS_UNIT-15 "mm"
*MEAS_COND_AXIS_UNIT-16 ""
*MEAS_COND_AXIS_UNIT-17 "mm"
*MEAS_COND_AXIS_UNIT-18 ""
*MEAS_COND_AXIS_UNIT-19 ""
*MEAS_COND_AXIS_UNIT-2 "deg"
*MEAS_COND_AXIS_UNIT-20 ""
*MEAS_COND_AXIS_UNIT-21 "deg"
*MEAS_COND_AXIS_UNIT-22 "deg"
*MEAS_COND_AXIS_UNIT-23 "mm"
*MEAS_COND_AXIS_UNIT-24 "deg"
*MEAS_COND_AXIS_UNIT-25 "deg"
*MEAS_COND_AXIS_UNIT-26 ""
*MEAS_COND_AXIS_UNIT-27 "mm"
*MEAS_COND_AXIS_UNIT-28 ""
*MEAS_COND_AXIS_UNIT-29 "mm"
*MEAS_COND_AXIS_UNIT-3 "deg"
*MEAS_COND_AXIS_UNIT-30 ""
*MEAS_COND_AXIS_UNIT-31 ""
*MEAS_COND_AXIS_UNIT-32 ""
*MEAS_COND_AXIS_UNIT-33 ""
*MEAS_COND_AXIS_UNIT-34 "mm"
*MEAS_COND_AXIS_UNIT-35 ""
*MEAS_COND_AXIS_UNIT-36 ""
*MEAS_COND_AXIS_UNIT-37 "keV"
*MEAS_COND_AXIS_UNIT-38 ""
*MEAS_COND_AXIS_UNIT-39 ""
*MEAS_COND_AXIS_UNIT-4 "deg"
*MEAS_COND_AXIS_UNIT-40 ""
*MEAS_COND_AXIS_UNIT-41 "H"
*MEAS_COND_AXIS_UNIT-42 "H"
*MEAS_COND_AXIS_UNIT-43 "H"
*MEAS_COND_AXIS_UNIT-44 "H"
*MEAS_COND_AXIS_UNIT-45 "H"
*MEAS_COND_AXIS_UNIT-46 "mV"
*MEAS_COND_AXIS_UNIT-47 "V"
*MEAS_COND_AXIS_UNIT-48 "V"
*MEAS_COND_AXIS_UNIT-49 "H"
*MEAS_COND_AXIS_UNIT-5 "deg"
*MEAS_COND_AXIS_UNIT-50 "H"
*MEAS_COND_AXIS_UNIT-51 "H"
*MEAS_COND_AXIS_UNIT-52 "H"
*MEAS_COND_AXIS_UNIT-53 "H"
*MEAS_COND_AXIS_UNIT-54 "uS/m"
*MEAS_COND_AXIS_UNIT-55 "L/min"
*MEAS_COND_AXIS_UNIT-56 "degree"
*MEAS_COND_AXIS_UNIT-57 "MPa"
*MEAS_COND_AXIS_UNIT-58 "MPa"
*MEAS_COND_AXIS_UNIT-59 "MPa"
*MEAS_COND_AXIS_UNIT-6 "deg"
*MEAS_COND_AXIS_UNIT-60 "L/min"
*MEAS_COND_AXIS_UNIT-61 "C"
*MEAS_COND_AXIS_UNIT-62 "MPa"
*MEAS_COND_AXIS_UNIT-63 "degree"
*MEAS_COND_AXIS_UNIT-64 "percent"
*MEAS_COND_AXIS_UNIT-65 "degree"
*MEAS_COND_AXIS_UNIT-66 "C"
*MEAS_COND_AXIS_UNIT-67 "H"
*MEAS_COND_AXIS_UNIT-68 "time"
*MEAS_COND_AXIS_UNIT-69 "msec"
*MEAS_COND_AXIS_UNIT-7 "mm"
*MEAS_COND_AXIS_UNIT-70 "msec"
*MEAS_COND_AXIS_UNIT-71 "H"
*MEAS_COND_AXIS_UNIT-72 "times"
*MEAS_COND_AXIS_UNIT-73 "msec"
*MEAS_COND_AXIS_UNIT-74 "msec"
*MEAS_COND_AXIS_UNIT-75 "-"
*MEAS_COND_AXIS_UNIT-76 "-"
*MEAS_COND_AXIS_UNIT-77 "-"
*MEAS_COND_AXIS_UNIT-78 ""
*MEAS_COND_AXIS_UNIT-79 "-"
*MEAS_COND_AXIS_UNIT-8 ""
*MEAS_COND_AXIS_UNIT-80 "-"
*MEAS_COND_AXIS_UNIT-81 "-"
*MEAS_COND_AXIS_UNIT-82 ""
*MEAS_COND_AXIS_UNIT-83 ""
*MEAS_COND_AXIS_UNIT-84 ""
*MEAS_COND_AXIS_UNIT-85 ""
*MEAS_COND_AXIS_UNIT-86 ""
*MEAS_COND_AXIS_UNIT-87 ""
*MEAS_COND_AXIS_UNIT-88 ""
*MEAS_COND_AXIS_UNIT-89 ""
*MEAS_COND_AXIS_UNIT-9 ""
*MEAS_COND_AXIS_UNIT-90 ""
*MEAS_COND_AXIS_UNIT-91 ""
*MEAS_COND_AXIS_UNIT-92 ""
*MEAS_COND_AXIS_UNIT-93 ""
*MEAS_COND_OPT_ATTR "PB"
*MEAS_COND_OPT_NAME "User defined settings"
*MEAS_COND_XG_CURRENT "40"
*MEAS_COND_XG_VOLTAGE "40"
*MEAS_COND_XG_WAVE_TYPE "Ka"
*MEAS_DATA_COUNT "7001"
*MEAS_SCAN_AXIS_X "TwoThetaTheta"
*MEAS_SCAN_AXIS_X_INTERNAL "TwoThetaTheta"
*MEAS_SCAN_END_TIME "03/08/2023 17:11:07"
*MEAS_SCAN_MODE "CONTINUOUS"
*MEAS_SCAN_MODE_INTERNAL "CONTINUOUS"
*MEAS_SCAN_RESOLUTION_X "0.0002"
*MEAS_SCAN_SPEED "2.4000"
*MEAS_SCAN_SPEED_UNIT "deg/min"
*MEAS_SCAN_START "10.0000"
*MEAS_SCAN_START_TIME "03/08/2023 16:41:37"
*MEAS_SCAN_STEP "0.0100"
*MEAS_SCAN_STOP "80.0000"
*MEAS_SCAN_UNIT_X "deg"
*MEAS_SCAN_UNIT_Y "counts"
*RAS_HEADER_END
*RAS_INT_START
10.0000 12.4018 1.0000
10.0500 10.7230 1.0000
10.1000 25.4860 1.0000
10.1500 9.0732 1.0000
10.2000 10.2390 1.0000
10.2500 20.8208 1.0000
10.3000 23.5030 1.0000
10.3500 18.3335 1.0000
10.4000 19.1379 1.0000
10.4500 20.5073 1.0000
10.5000 17.6478 1.0000
10.5500 24.2123 1.0000
10.6000 15.4084 1.0000
10.6500 18.4786 1.0000
10.7000 18.1003 1.0000
10.7500 17.6531 1.0000
10.8000 17.7112 1.0000
10.8500 16.5186 1.0000
10.9000 15.0897 1.0000
10.9500 15.9866 1.0000
11.0000 15.9354 1.0000
11.0500 8.2312 1.0000
11.1000 26.2895 1.0000
11.1500 19.2436 1.0000
11.2000 16.3471 1.0000
11.2500 16.5603 1.0000
11.3000 19.2821 1.0000
11.3500 22.2128 1.0000
11.4000 21.1197 1.0000
11.4500 21.0687 1.0000
11.5000 22.2279 1.0000
11.5500 17.6432 1.0000
11.6000 21.6153 1.0000
11.6500 23.0210 1.0000
11.7000 27.9246 1.0000
11.7500 19.7381 1.0000
11.8000 20.3753 1.0000
11.8500 20.9143 1.0000
11.9000 18.2428 1.0000
11.9500 19.7983 1.0000
12.0000 23.7862 1.0000
12.0500 13.5030 1.0000
12.1000 19.1172 1.0000
12.1500 23.3834 1.0000
12.2000 18.8827 1.0000
12.2500 26.9357 1.0000
12.3000 27.4399 1.0000
12.3500 18.9184 1.0000
12.4000 19.9500 1.0000
12.4500 20.4522 1.0000
12.5000 20.9410 1.0000
12.5500 27.4744 1.0000
12.6000 19.6910 1.0000
12.6500 13.7807 1.0000
12.7000 20.5688 1.0000
12.7500 22.1881 1.0000
12.8000 25.8761 1.0000
12.8500 24.0603 1.0000
12.9000 17.8816 1.0000
12.9500 26.1121 1.0000
13.0000 23.5485 1.0000
13.0500 16.5011 1.0000
13.1000 18.6169 1.0000
13.1500 26.1741 1.0000
13.2000 24.3794 1.0000
13.2500 26.7686 1.0000
13.3000 23.0696 1.0000
13.3500 20.4124 1.0000
13.4000 24.6944 1.0000
13.4500 13.7278 1.0000
13.5000 18.8858 1.0000
13.5500 19.9065 1.0000
13.6000 20.2082 1.0000
13.6500 17.1063 1.0000
13.7000 20.4997 1.0000
13.7500 15.7121 1.0000
13.8000 17.7655 1.0000
13.8500 19.1790 1.0000
13.9000 21.1626 1.0000
13.9500 14.4606 1.0000
14.0000 19.4490 1.0000
14.0500 21.3853 1.0000
14.1000 27.5266 1.0000
14.1500 24.1449 1.0000
14.2000 20.9443 1.0000
14.2500 16.5408 1.0000
14.3000 18.4686 1.0000
14.3500 14.8219 1.0000
14.4000 21.2733 1.0000
14.4500 17.9379 1.0000
14.5000 19.6779 1.0000
14.5500 25.2580 1.0000
14.6000 22.2494 1.0000
14.6500 28.3382 1.0000
14.7000 22.0845 1.0000
14.7500 17.3868 1.0000
14.8000 20.1583 1.0000
14.8500 34.3930 1.0000
14.9000 19.1567 1.0000
14.9500 26.2337 1.0000
15.0000 25.2132 1.0000
15.0500 16.0328 1.0000
15.1000 18.9733 1.0000
15.1500 28.0184 1.0000
15.2000 19.3546 1.0000
15.2500 16.9886 1.0000
15.3000 21.8535 1.0000
15.3500 28.3674 1.0000
15.4000 18.8333 1.0000
15.4500 24.9204 1.0000
15.5000 16.9520 1.0000
15.5500 23.9276 1.0000
15.6000 27.6667 1.0000
15.6500 20.8158 1.0000
15.7000 21.5688 1.0000
15.7500 11.4557 1.0000
15.8000 15.6533 1.0000
15.8500 19.5539 1.0000
15.9000 16.3272 1.0000
15.9500 21.6771 1.0000
16.0000 20.6460 1.0000
16.0500 18.6127 1.0000
16.1000 24.0609 1.0000
16.1500 20.9402 1.0000
16.2000 26.7972 1.0000
16.2500 16.7332 1.0000
16.3000 16.7198 1.0000
16.3500 27.0058 1.0000
16.4000 15.3537 1.0000
16.4500 14.6877 1.0000
16.5000 20.7028 1.0000
16.5500 19.3508 1.0000
16.6000 21.7979 1.0000
16.6500 14.4622 1.0000
16.7000 18.8812 1.0000
16.7500 26.5043 1.0000
16.8000 22.3069 1.0000
16.8500 21.5162 1.0000
16.9000 23.4573 1.0000
16.9500 22.5893 1.0000
17.0000 17.7945 1.0000
17.0500 18.0165 1.0000
17.1000 30.0335 1.0000
17.1500 15.0576 1.0000
17.2000 18.1088 1.0000
17.2500 30.2182 1.0000
17.3000 18.3098 1.0000
17.3500 16.5797 1.0000
17.4000 18.9368 1.0000
17.4500 18.8116 1.0000
17.5000 16.2490 1.0000
17.5500 28.4556 1.0000
17.6000 19.9205 1.0000
17.6500 24.6969 1.0000
17.7000 16.0125 1.0000
17.7500 17.8896 1.0000
17.8000 18.8989 1.0000
17.8500 14.5493 1.0000
17.9000 23.3366 1.0000
17.9500 22.9292 1.0000
18.0000 24.8567 1.0000
18.0500 26.3129 1.0000
18.1000 26.4594 1.0000
18.1500 28.7233 1.0000
18.2000 25.6612 1.0000
18.2500 20.8884 1.0000
18.3000 28.9367 1.0000
18.3500 19.6064 1.0000
18.4000 12.0996 1.0000
18.4500 19.1984 1.0000
18.5000 20.2207 1.0000
18.5500 26.7214 1.0000
18.6000 24.3321 1.0000
18.6500 18.9193 1.0000
18.7000 27.4679 1.0000
18.7500 27.3427 1.0000
18.8000 19.6118 1.0000
18.8500 24.1001 1.0000
18.9000 22.5474 1.0000
18.9500 17.7180 1.0000
19.0000 24.1604 1.0000
19.0500 22.8297 1.0000
19.1000 23.0754 1.0000
19.1500 17.6612 1.0000
19.2000 25.5504 1.0000
19.2500 20.9106 1.0000
19.3000 20.7686 1.0000
19.3500 16.3314 1.0000
19.4000 22.1331 1.0000
19.4500 26.2216 1.0000
19.5000 23.3415 1.0000
19.5500 23.4507 1.0000
19.6000 24.9203 1.0000
19.6500 20.9108 1.0000
19.7000 17.0992 1.0000
19.7500 26.7000 1.0000
19.8000 25.0191 1.0000
19.8500 26.7689 1.0000
19.9000 18.2669 1.0000
19.9500 17.3691 1.0000
20.0000 35.9166 1.0000
20.0500 21.8690 1.0000
20.1000 24.2133 1.0000
20.1500 35.6273 1.0000
20.2000 25.7052 1.0000
20.2500 23.7775 1.0000
20.3000 22.5896 1.0000
20.3500 22.2168 1.0000
20.4000 34.6458 1.0000
20.4500 27.3378 1.0000
20.5000 26.9911 1.0000
20.5500 22.7530 1.0000
20.6000 15.9042 1.0000
20.6500 28.6725 1.0000
20.7000 25.1328 1.0000
20.7500 27.2535 1.0000
20.8000 27.4130 1.0000
20.8500 37.4221 1.0000
20.9000 25.3948 1.0000
20.9500 25.0798 1.0000
21.0000 35.1976 1.0000
21.0500 35.7794 1.0000
21.1000 26.7658 1.0000
21.1500 34.5672 1.0000
21.2000 26.3129 1.0000
21.2500 20.6974 1.0000
21.3000 18.5512 1.0000
21.3500 33.4638 1.0000
21.4000 29.6112 1.0000
21.4500 27.7445 1.0000
21.5000 18.3009 1.0000
21.5500 29.3464 1.0000
21.6000 28.7539 1.0000
21.6500 20.6995 1.0000
21.7000 27.7784 1.0000
21.7500 32.3628 1.0000
21.8000 20.5885 1.0000
21.8500 35.0091 1.0000
21.9000 27.5126 1.0000
21.9500 22.1218 1.0000
22.0000 25.0938 1.0000
22.0500 24.5036 1.0000
22.1000 28.9706 1.0000
22.1500 44.3643 1.0000
22.2000 35.7863 1.0000
22.2500 52.4310 1.0000
22.3000 63.9356 1.0000
22.3500 77.9035 1.0000
22.4000 73.6454 1.0000
22.4500 90.8139 1.0000
22.5000 69.1138 1.0000
22.5500 64.4880 1.0000
22.6000 50.4700 1.0000
22.6500 44.8087 1.0000
22.7000 37.4618 1.0000
22.7500 25.1142 1.0000
22.8000 36.7881 1.0000
22.8500 25.0164 1.0000
22.9000 33.7405 1.0000
22.9500 31.2324 1.0000
23.0000 28.6113 1.0000
23.0500 45.9537 1.0000
23.1000 31.8216 1.0000
23.1500 36.9213 1.0000
23.2000 26.5910 1.0000
23.2500 27.6751 1.0000
23.3000 36.6158 1.0000
23.3500 23.6746 1.0000
23.4000 27.0454 1.0000
23.4500 31.7536 1.0000
23.5000 27.2552 1.0000
23.5500 28.5846 1.0000
23.6000 27.3094 1.0000
23.6500 39.8533 1.0000
23.7000 42.8650 1.0000
23.7500 33.7893 1.0000
23.8000 36.3476 1.0000
23.8500 42.0266 1.0000
23.9000 32.7922 1.0000
23.9500 29.8323 1.0000
24.0000 31.7694 1.0000
24.0500 37.9433 1.0000
24.1000 42.4587 1.0000
24.1500 25.8690 1.0000
24.2000 22.0820 1.0000
24.2500 20.8186 1.0000
24.3000 25.8318 1.0000
24.3500 32.1848 1.0000
24.4000 28.6806 1.0000
24.4500 37.9444 1.0000
24.5000 23.7963 1.0000
24.5500 36.2236 1.0000
24.6000 19.9695 1.0000
24.6500 45.2364 1.0000
24.7000 19.8118 1.0000
24.7500 37.5205 1.0000
24.8000 28.9040 1.0000
24.8500 36.3190 1.0000
24.9000 43.0492 1.0000
24.9500 37.8713 1.0000
25.0000 26.2172 1.0000
25.0500 30.0406 1.0000
25.1000 36.5973 1.0000
25.1500 18.5040 1.0000
25.2000 33.7058 1.0000
25.2500 35.0503 1.0000
25.3000 36.1166 1.0000
25.3500 33.3601 1.0000
25.4000 28.6141 1.0000
25.4500 32.7237 1.0000
25.5000 27.0924 1.0000
25.5500 31.1529 1.0000
25.6000 36.4113 1.0000
25.6500 51.6487 1.0000
25.7000 32.4861 1.0000
25.7500 37.4672 1.0000
25.8000 34.8629 1.0000
25.8500 33.1223 1.0000
25.9000 32.6867 1.0000
25.9500 30.4886 1.0000
26.0000 36.2896 1.0000
26.0500 31.9218 1.0000
26.1000 33.7033 1.0000
26.1500 26.0671 1.0000
26.2000 30.8832 1.0000
26.2500 33.8539 1.0000
26.3000 37.0988 1.0000
26.3500 39.4983 1.0000
26.4000 24.6312 1.0000
26.4500 42.9295 1.0000
26.5000 38.7486 1.0000
26.5500 37.2429 1.0000
26.6000 29.7462 1.0000
26.6500 35.5332 1.0000
26.7000 47.6957 1.0000
26.7500 39.8827 1.0000
26.8000 35.6398 1.0000
26.8500 47.5448 1.0000
26.9000 31.1756 1.0000
26.9500 36.1242 1.0000
27.0000 44.5848 1.0000
27.0500 36.8498 1.0000
27.1000 41.5274 1.0000
27.1500 36.0647 1.0000
27.2000 28.5858 1.0000
27.2500 36.8287 1.0000
27.3000 40.4455 1.0000
27.3500 38.6077 1.0000
27.4000 43.3988 1.0000
27.4500 35.4383 1.0000
27.5000 32.5566 1.0000
27.5500 54.0295 1.0000
27.6000 35.9655 1.0000
27.6500 35.1944 1.0000
27.7000 44.8199 1.0000
27.7500 36.1778 1.0000
27.8000 43.7023 1.0000
27.8500 46.9807 1.0000
27.9000 46.6313 1.0000
27.9500 57.6419 1.0000
28.0000 63.3889 1.0000
28.0500 55.8148 1.0000
28.1000 62.3305 1.0000
28.1500 60.6512 1.0000
28.2000 59.0864 1.0000
28.2500 45.4592 1.0000
28.3000 46.0438 1.0000
28.3500 36.7143 1.0000
28.4000 45.6784 1.0000
28.4500 34.9075 1.0000
28.5000 36.7348 1.0000
28.5500 45.3902 1.0000
28.6000 38.6523 1.0000
28.6500 41.8590 1.0000
28.7000 47.8764 1.0000
28.7500 45.7216 1.0000
28.8000 72.0404 1.0000
28.8500 66.0729 1.0000
28.9000 48.3836 1.0000
28.9500 53.0632 1.0000
29.0000 56.5646 1.0000
29.0500 53.0242 1.0000
29.1000 46.6609 1.0000
29.1500 49.5819 1.0000
29.2000 53.6390 1.0000
29.2500 43.6194 1.0000
29.3000 43.1065 1.0000
29.3500 34.7904 1.0000
29.4000 36.8859 1.0000
29.4500 55.6091 1.0000
29.5000 40.4282 1.0000
29.5500 37.7923 1.0000
29.6000 44.7017 1.0000
29.6500 44.7135 1.0000
29.7000 41.4335 1.0000
29.7500 45.9537 1.0000
29.8000 37.4447 1.0000
29.8500 41.0439 1.0000
29.9000 47.4655 1.0000
29.9500 45.5064 1.0000
30.0000 39.8966 1.0000
30.0500 39.2109 1.0000
30.1000 53.3862 1.0000
30.1500 43.3915 1.0000
30.2000 53.7917 1.0000
30.2500 42.1947 1.0000
30.3000 30.2260 1.0000
30.3500 35.5455 1.0000
30.4000 46.5899 1.0000
30.4500 32.7200 1.0000
30.5000 29.2230 1.0000
30.5500 38.1483 1.0000
30.6000 38.2864 1.0000
30.6500 30.9591 1.0000
30.7000 42.4263 1.0000
30.7500 45.0368 1.0000
30.8000 40.0947 1.0000
30.8500 41.2648 1.0000
30.9000 44.6916 1.0000
30.9500 44.5822 1.0000
31.0000 40.5742 1.0000
31.0500 43.1655 1.0000
31.1000 35.0874 1.0000
31.1500 38.7273 1.0000
31.2000 37.5007 1.0000
31.2500 41.5236 1.0000
31.3000 40.9478 1.0000
31.3500 49.2591 1.0000
31.4000 45.3623 1.0000
31.4500 38.3187 1.0000
31.5000 48.8969 1.0000
31.5500 61.5796 1.0000
31.6000 79.4949 1.0000
31.6500 70.9344 1.0000
31.7000 109.9206 1.0000
31.7500 105.5292 1.0000
31.8000 100.9086 1.0000
31.8500 99.9338 1.0000
31.9000 97.1659 1.0000
31.9500 92.8926 1.0000
32.0000 90.1304 1.0000
32.0500 113.9379 1.0000
32.1000 99.7046 1.0000
32.1500 91.7644 1.0000
32.2000 80.0038 1.0000
32.2500 61.7427 1.0000
32.3000 50.4315 1.0000
32.3500 37.2955 1.0000
32.4000 39.4245 1.0000
32.4500 38.2645 1.0000
32.5000 40.5491 1.0000
32.5500 30.5507 1.0000
32.6000 41.5531 1.0000
32.6500 35.4468 1.0000
32.7000 26.5121 1.0000
32.7500 33.3319 1.0000
32.8000 41.2241 1.0000
32.8500 29.8979 1.0000
32.9000 31.9280 1.0000
32.9500 39.9986 1.0000
33.0000 39.7766 1.0000
33.0500 27.7991 1.0000
33.1000 30.3313 1.0000
33.1500 28.8376 1.0000
33.2000 40.5673 1.0000
33.2500 34.4734 1.0000
33.3000 25.9030 1.0000
33.3500 27.3122 1.0000
33.4000 26.0927 1.0000
33.4500 37.5235 1.0000
33.5000 24.2137 1.0000
33.5500 46.2424 1.0000
33.6000 50.4531 1.0000
33.6500 34.3011 1.0000
33.7000 35.0036 1.0000
33.7500 39.2923 1.0000
33.8000 34.3020 1.0000
33.8500 22.1737 1.0000
33.9000 24.4170 1.0000
33.9500 26.1627 1.0000
34.0000 38.1477 1.0000
34.0500 22.4256 1.0000
34.1000 25.9538 1.0000
34.1500 37.6024 1.0000
34.2000 28.0928 1.0000
34.2500 22.3887 1.0000
34.3000 27.7020 1.0000
34.3500 33.0244 1.0000
34.4000 33.3373 1.0000
34.4500 32.5276 1.0000
34.5000 28.9588 1.0000
34.5500 29.4080 1.0000
34.6000 36.9363 1.0000
34.6500 29.8427 1.0000
34.7000 26.9627 1.0000
34.7500 28.5057 1.0000
34.8000 27.4965 1.0000
34.8500 20.5075 1.0000
34.9000 21.8123 1.0000
34.9500 18.9809 1.0000
35.0000 26.7589 1.0000
35.0500 28.6960 1.0000
35.1000 27.6081 1.0000
35.1500 30.7210 1.0000
35.2000 24.7500 1.0000
35.2500 30.0504 1.0000
35.3000 22.9893 1.0000
35.3500 24.1774 1.0000
35.4000 26.3374 1.0000
35.4500 20.1027 1.0000
35.5000 25.6448 1.0000
35.5500 23.2042 1.0000
35.6000 21.1292 1.0000
35.6500 30.4714 1.0000
35.7000 32.0884 1.0000
35.7500 23.2611 1.0000
35.8000 30.3711 1.0000
35.8500 20.4446 1.0000
35.9000 25.8448 1.0000
35.9500 19.3642 1.0000
36.0000 13.8793 1.0000
36.0500 32.2609 1.0000
36.1000 23.4847 1.0000
36.1500 21.7334 1.0000
36.2000 20.1164 1.0000
36.2500 21.7085 1.0000
36.3000 15.8108 1.0000
36.3500 14.6455 1.0000
36.4000 23.8345 1.0000
36.4500 14.7838 1.0000
36.5000 23.0434 1.0000
36.5500 21.3576 1.0000
36.6000 34.7696 1.0000
36.6500 16.2552 1.0000
36.7000 23.3454 1.0000
36.7500 24.8472 1.0000
36.8000 19.7887 1.0000
36.8500 19.3773 1.0000
36.9000 23.5528 1.0000
36.9500 22.4088 1.0000
37.0000 21.4654 1.0000
37.0500 16.6187 1.0000
37.1000 17.2144 1.0000
37.1500 29.0993 1.0000
37.2000 29.5413 1.0000
37.2500 25.8107 1.0000
37.3000 29.6460 1.0000
37.3500 31.4765 1.0000
37.4000 18.7163 1.0000
37.4500 29.7615 1.0000
37.5000 19.6593 1.0000
37.5500 31.5605 1.0000
37.6000 19.2249 1.0000
37.6500 24.0853 1.0000
37.7000 20.9357 1.0000
37.7500 34.4583 1.0000
37.8000 27.6234 1.0000
37.8500 26.0202 1.0000
37.9000 28.2674 1.0000
37.9500 14.2970 1.0000
38.0000 21.6478 1.0000
38.0500 21.5805 1.0000
38.1000 13.8015 1.0000
38.1500 13.3208 1.0000
38.2000 25.4732 1.0000
38.2500 20.1953 1.0000
38.3000 20.3358 1.0000
38.3500 29.3242 1.0000
38.4000 25.4095 1.0000
38.4500 24.2306 1.0000
38.5000 21.6056 1.0000
38.5500 28.7970 1.0000
38.6000 21.4808 1.0000
38.6500 28.6266 1.0000
38.7000 31.8652 1.0000
38.7500 22.9618 1.0000
38.8000 28.3982 1.0000
38.8500 20.7350 1.0000
38.9000 27.8300 1.0000
38.9500 34.9533 1.0000
39.0000 26.5779 1.0000
39.0500 31.6509 1.0000
39.1000 23.2957 1.0000
39.1500 19.6347 1.0000
39.2000 33.3065 1.0000
39.2500 15.7717 1.0000
39.3000 20.4562 1.0000
39.3500 27.8600 1.0000
39.4000 33.9410 1.0000
39.4500 47.9030 1.0000
39.5000 43.3181 1.0000
39.5500 39.7845 1.0000
39.6000 26.8713 1.0000
39.6500 44.8410 1.0000
39.7000 35.1062 1.0000
39.7500 29.3855 1.0000
39.8000 22.9882 1.0000
39.8500 17.5498 1.0000
39.9000 24.6498 1.0000
39.9500 23.9057 1.0000
40.0000 29.9638 1.0000
40.0500 27.9515 1.0000
40.1000 16.9862 1.0000
40.1500 24.2649 1.0000
40.2000 13.6118 1.0000
40.2500 24.7131 1.0000
40.3000 19.0218 1.0000
40.3500 18.1280 1.0000
40.4000 22.0975 1.0000
40.4500 12.9995 1.0000
40.5000 19.9609 1.0000
40.5500 14.5629 1.0000
40.6000 23.3253 1.0000
40.6500 26.5013 1.0000
40.7000 22.4700 1.0000
40.7500 28.5649 1.0000
40.8000 16.2780 1.0000
40.8500 16.1367 1.0000
40.9000 20.1666 1.0000
40.9500 17.2367 1.0000
41.0000 12.2859 1.0000
41.0500 27.2005 1.0000
41.1000 17.6946 1.0000
41.1500 19.1942 1.0000
41.2000 13.6169 1.0000
41.2500 22.3535 1.0000
41.3000 23.4141 1.0000
41.3500 21.7283 1.0000
41.4000 19.1629 1.0000
41.4500 16.2917 1.0000
41.5000 18.7379 1.0000
41.5500 23.7363 1.0000
41.6000 19.4776 1.0000
41.6500 26.1822 1.0000
41.7000 19.5362 1.0000
41.7500 21.7360 1.0000
41.8000 19.7048 1.0000
41.8500 18.2232 1.0000
41.9000 28.1548 1.0000
41.9500 18.6513 1.0000
42.0000 20.6869 1.0000
42.0500 25.3554 1.0000
42.1000 20.7171 1.0000
42.1500 22.4468 1.0000
42.2000 21.6219 1.0000
42.2500 21.0696 1.0000
42.3000 8.9844 1.0000
42.3500 16.3619 1.0000
42.4000 18.2075 1.0000
42.4500 17.6485 1.0000
42.5000 19.1796 1.0000
42.5500 26.0857 1.0000
42.6000 30.0542 1.0000
42.6500 29.2026 1.0000
42.7000 22.7013 1.0000
42.7500 22.7368 1.0000
42.8000 28.4384 1.0000
42.8500 23.7179 1.0000
42.9000 14.6119 1.0000
42.9500 20.7163 1.0000
43.0000 24.4712 1.0000
43.0500 19.7395 1.0000
43.1000 17.4656 1.0000
43.1500 19.3536 1.0000
43.2000 24.3383 1.0000
43.2500 25.1670 1.0000
43.3000 23.0741 1.0000
43.3500 11.2670 1.0000
43.4000 18.3710 1.0000
43.4500 21.9680 1.0000
43.5000 23.1459 1.0000
43.5500 17.7287 1.0000
43.6000 27.6414 1.0000
43.6500 25.7074 1.0000
43.7000 21.2140 1.0000
43.7500 15.6450 1.0000
43.8000 22.9808 1.0000
43.8500 35.1249 1.0000
43.9000 30.5685 1.0000
43.9500 29.2529 1.0000
44.0000 26.0137 1.0000
44.0500 35.6469 1.0000
44.1000 43.0496 1.0000
44.1500 59.4960 1.0000
44.2000 31.5942 1.0000
44.2500 47.9264 1.0000
44.3000 23.7096 1.0000
44.3500 32.0375 1.0000
44.4000 23.5489 1.0000
44.4500 23.4594 1.0000
44.5000 17.6999 1.0000
44.5500 17.2930 1.0000
44.6000 14.2263 1.0000
44.6500 17.6879 1.0000
44.7000 23.8008 1.0000
44.7500 30.1361 1.0000
44.8000 19.8670 1.0000
44.8500 24.9053 1.0000
44.9000 23.2196 1.0000
44.9500 26.7388 1.0000
45.0000 22.2533 1.0000
45.0500 23.9413 1.0000
45.1000 17.3973 1.0000
45.1500 27.3209 1.0000
45.2000 18.2804 1.0000
45.2500 29.0236 1.0000
45.3000 15.0124 1.0000
45.3500 30.7755 1.0000
45.4000 19.9321 1.0000
45.4500 33.7714 1.0000
45.5000 34.8053 1.0000
45.5500 23.4152 1.0000
45.6000 37.0176 1.0000
45.6500 37.7263 1.0000
45.7000 45.3534 1.0000
45.7500 39.5142 1.0000
45.8000 40.0154 1.0000
45.8500 41.0729 1.0000
45.9000 30.2280 1.0000
45.9500 26.5501 1.0000
46.0000 27.1173 1.0000
46.0500 20.4097 1.0000
46.1000 35.4958 1.0000
46.1500 24.4882 1.0000
46.2000 24.1634 1.0000
46.2500 28.2595 1.0000
46.3000 15.8482 1.0000
46.3500 27.7854 1.0000
46.4000 30.0289 1.0000
46.4500 23.3868 1.0000
46.5000 23.9502 1.0000
46.5500 23.6294 1.0000
46.6000 19.6446 1.0000
46.6500 26.3345 1.0000
46.7000 28.5325 1.0000
46.7500 26.5795 1.0000
46.8000 23.3113 1.0000
46.8500 23.3084 1.0000
46.9000 30.4003 1.0000
46.9500 33.5728 1.0000
47.0000 29.2759 1.0000
47.0500 27.0774 1.0000
47.1000 30.4891 1.0000
47.1500 17.2771 1.0000
47.2000 20.8103 1.0000
47.2500 24.6921 1.0000
47.3000 37.2071 1.0000
47.3500 33.8346 1.0000
47.4000 25.5297 1.0000
47.4500 27.3432 1.0000
47.5000 22.4473 1.0000
47.5500 17.2116 1.0000
47.6000 16.8966 1.0000
47.6500 19.6370 1.0000
47.7000 27.0392 1.0000
47.7500 18.6486 1.0000
47.8000 28.2223 1.0000
47.8500 29.9301 1.0000
47.9000 20.5707 1.0000
47.9500 26.4500 1.0000
48.0000 19.3513 1.0000
48.0500 24.5009 1.0000
48.1000 24.2871 1.0000
48.1500 14.3018 1.0000
48.2000 17.7569 1.0000
48.2500 19.1756 1.0000
48.3000 24.2076 1.0000
48.3500 33.8835 1.0000
48.4000 20.8443 1.0000
48.4500 29.8476 1.0000
48.5000 15.8852 1.0000
48.5500 24.5684 1.0000
48.6000 19.1854 1.0000
48.6500 23.0662 1.0000
48.7000 25.0485 1.0000
48.7500 23.6108 1.0000
48.8000 16.9692 1.0000
48.8500 18.5690 1.0000
48.9000 26.5033 1.0000
48.9500 19.1903 1.0000
49.0000 14.9185 1.0000
49.0500 21.8191 1.0000
49.1000 24.8458 1.0000
49.1500 16.3659 1.0000
49.2000 15.1998 1.0000
49.2500 21.1581 1.0000
49.3000 19.2901 1.0000
49.3500 29.7942 1.0000
49.4000 35.1972 1.0000
49.4500 19.7161 1.0000
49.5000 23.6460 1.0000
49.5500 21.6481 1.0000
49.6000 22.0523 1.0000
49.6500 25.8950 1.0000
49.7000 27.1670 1.0000
49.7500 23.1007 1.0000
49.8000 20.3877 1.0000
49.8500 26.0850 1.0000
49.9000 28.1432 1.0000
49.9500 14.8051 1.0000
50.0000 18.1705 1.0000
50.0500 18.7418 1.0000
50.1000 16.7321 1.0000
50.1500 22.8978 1.0000
50.2000 26.0443 1.0000
50.2500 29.0638 1.0000
50.3000 12.4855 1.0000
50.3500 21.1290 1.0000
50.4000 19.0022 1.0000
50.4500 22.5611 1.0000
50.5000 35.0202 1.0000
50.5500 25.7572 1.0000
50.6000 29.3886 1.0000
50.6500 15.8863 1.0000
50.7000 22.6670 1.0000
50.7500 23.8566 1.0000
50.8000 27.0748 1.0000
50.8500 31.8529 1.0000
50.9000 24.5794 1.0000
50.9500 19.1361 1.0000
51.0000 18.0670 1.0000
51.0500 19.5997 1.0000
51.1000 29.3451 1.0000
51.1500 21.3375 1.0000
51.2000 35.0924 1.0000
51.2500 32.9182 1.0000
51.3000 28.7720 1.0000
51.3500 40.0478 1.0000
51.4000 24.5343 1.0000
51.4500 28.4215 1.0000
51.5000 35.1042 1.0000
51.5500 29.7960 1.0000
51.6000 21.2875 1.0000
51.6500 36.2135 1.0000
51.7000 20.1257 1.0000
51.7500 35.6568 1.0000
51.8000 22.2791 1.0000
51.8500 28.4933 1.0000
51.9000 33.2255 1.0000
51.9500 18.3161 1.0000
52.0000 24.0132 1.0000
52.0500 23.7779 1.0000
52.1000 24.2591 1.0000
52.1500 24.6398 1.0000
52.2000 19.6112 1.0000
52.2500 17.4195 1.0000
52.3000 19.8581 1.0000
52.3500 14.9452 1.0000
52.4000 33.3312 1.0000
52.4500 19.2917 1.0000
52.5000 19.8504 1.0000
52.5500 23.7439 1.0000
52.6000 21.1337 1.0000
52.6500 25.3365 1.0000
52.7000 26.2503 1.0000
52.7500 28.4271 1.0000
52.8000 27.9563 1.0000
52.8500 22.1491 1.0000
52.9000 20.3311 1.0000
52.9500 22.2972 1.0000
53.0000 15.2394 1.0000
53.0500 14.7187 1.0000
53.1000 19.8212 1.0000
53.1500 21.2344 1.0000
53.2000 25.2890 1.0000
53.2500 22.9915 1.0000
53.3000 26.9719 1.0000
53.3500 18.4642 1.0000
53.4000 23.8911 1.0000
53.4500 17.2858 1.0000
53.5000 16.5627 1.0000
53.5500 16.4840 1.0000
53.6000 9.5490 1.0000
53.6500 16.1346 1.0000
53.7000 23.5805 1.0000
53.7500 15.0954 1.0000
53.8000 16.8377 1.0000
53.8500 23.7384 1.0000
53.9000 28.1585 1.0000
53.9500 26.0165 1.0000
54.0000 19.9389 1.0000
54.0500 13.5486 1.0000
54.1000 31.9077 1.0000
54.1500 18.5213 1.0000
54.2000 29.8294 1.0000
54.2500 27.4953 1.0000
54.3000 25.9158 1.0000
54.3500 23.3811 1.0000
54.4000 19.5175 1.0000
54.4500 25.9978 1.0000
54.5000 11.4810 1.0000
54.5500 20.5077 1.0000
54.6000 21.4589 1.0000
54.6500 21.8049 1.0000
54.7000 23.8654 1.0000
54.7500 20.5193 1.0000
54.8000 16.0830 1.0000
54.8500 21.4631 1.0000
54.9000 15.9579 1.0000
54.9500 20.5024 1.0000
55.0000 17.8667 1.0000
55.0500 17.6003 1.0000
55.1000 21.4891 1.0000
55.1500 23.9925 1.0000
55.2000 20.2517 1.0000
55.2500 19.6159 1.0000
55.3000 28.6889 1.0000
55.3500 21.6828 1.0000
55.4000 36.9140 1.0000
55.4500 23.4004 1.0000
55.5000 19.7273 1.0000
55.5500 30.9113 1.0000
55.6000 23.8960 1.0000
55.6500 17.1509 1.0000
55.7000 22.0437 1.0000
55.7500 22.2712 1.0000
55.8000 18.0618 1.0000
55.8500 21.3217 1.0000
55.9000 18.8832 1.0000
55.9500 19.5319 1.0000
56.0000 17.3842 1.0000
56.0500 24.1667 1.0000
56.1000 28.2584 1.0000
56.1500 29.1698 1.0000
56.2000 23.2391 1.0000
56.2500 30.9008 1.0000
56.3000 21.1207 1.0000
56.3500 37.4748 1.0000
56.4000 37.1955 1.0000
56.4500 32.1446 1.0000
56.5000 28.8445 1.0000
56.5500 37.7250 1.0000
56.6000 24.8903 1.0000
56.6500 33.1961 1.0000
56.7000 31.2708 1.0000
56.7500 41.5174 1.0000
56.8000 29.2011 1.0000
56.8500 40.2812 1.0000
56.9000 42.4645 1.0000
56.9500 58.3971 1.0000
57.0000 46.1082 1.0000
57.0500 44.3284 1.0000
57.1000 51.4432 1.0000
57.1500 32.7666 1.0000
57.2000 38.1449 1.0000
57.2500 45.6399 1.0000
57.3000 13.6960 1.0000
57.3500 18.0483 1.0000
57.4000 20.8911 1.0000
57.4500 28.3056 1.0000
57.5000 15.1845 1.0000
57.5500 20.7088 1.0000
57.6000 20.0254 1.0000
57.6500 22.9043 1.0000
57.7000 19.4692 1.0000
57.7500 12.8987 1.0000
57.8000 28.9279 1.0000
57.8500 23.7667 1.0000
57.9000 20.8205 1.0000
57.9500 17.2614 1.0000
58.0000 17.9805 1.0000
58.0500 19.1186 1.0000
58.1000 23.8059 1.0000
58.1500 16.9946 1.0000
58.2000 17.8552 1.0000
58.2500 16.6734 1.0000
58.3000 10.9374 1.0000
58.3500 23.4319 1.0000
58.4000 17.9007 1.0000
58.4500 21.6566 1.0000
58.5000 22.4983 1.0000
58.5500 25.7004 1.0000
58.6000 22.2526 1.0000
58.6500 30.9235 1.0000
58.7000 13.3325 1.0000
58.7500 17.7028 1.0000
58.8000 11.9878 1.0000
58.8500 22.4173 1.0000
58.9000 22.4815 1.0000
58.9500 23.7607 1.0000
59.0000 23.2156 1.0000
59.0500 14.9278 1.0000
59.1000 16.0101 1.0000
59.1500 23.5516 1.0000
59.2000 20.9750 1.0000
59.2500 20.4374 1.0000
59.3000 22.2128 1.0000
59.3500 16.7546 1.0000
59.4000 23.2371 1.0000
59.4500 17.3968 1.0000
59.5000 20.2627 1.0000
59.5500 18.8556 1.0000
59.6000 19.7095 1.0000
59.6500 25.8012 1.0000
59.7000 30.9420 1.0000
59.7500 15.2324 1.0000
59.8000 21.1224 1.0000
59.8500 15.7400 1.0000
59.9000 20.1820 1.0000
59.9500 10.6655 1.0000
60.0000 15.1657 1.0000
60.0500 20.0162 1.0000
60.1000 18.0560 1.0000
60.1500 18.0091 1.0000
60.2000 22.9638 1.0000
60.2500 18.7821 1.0000
60.3000 22.4490 1.0000
60.3500 21.4095 1.0000
60.4000 23.5736 1.0000
60.4500 16.2492 1.0000
60.5000 17.0708 1.0000
60.5500 22.5188 1.0000
60.6000 21.1661 1.0000
60.6500 21.5880 1.0000
60.7000 17.8123 1.0000
60.7500 26.4787 1.0000
60.8000 17.0133 1.0000
60.8500 16.7032 1.0000
60.9000 15.6709 1.0000
60.9500 27.0034 1.0000
61.0000 26.4686 1.0000
61.0500 13.2993 1.0000
61.1000 14.7767 1.0000
61.1500 19.2038 1.0000
61.2000 18.3713 1.0000
61.2500 12.7162 1.0000
61.3000 20.8343 1.0000
61.3500 18.9506 1.0000
61.4000 15.6304 1.0000
61.4500 16.0162 1.0000
61.5000 14.4277 1.0000
61.5500 29.6984 1.0000
61.6000 22.8083 1.0000
61.6500 18.1452 1.0000
61.7000 13.4238 1.0000
61.7500 10.5141 1.0000
61.8000 25.5683 1.0000
61.8500 16.6285 1.0000
61.9000 23.3226 1.0000
61.9500 26.4800 1.0000
62.0000 22.8393 1.0000
62.0500 15.7562 1.0000
62.1000 19.0602 1.0000
62.1500 20.6601 1.0000
62.2000 22.0636 1.0000
62.2500 23.7053 1.0000
62.3000 20.9502 1.0000
62.3500 17.4879 1.0000
62.4000 26.3741 1.0000
62.4500 27.6936 1.0000
62.5000 15.1266 1.0000
62.5500 22.0724 1.0000
62.6000 14.9447 1.0000
62.6500 19.2474 1.0000
62.7000 19.4147 1.0000
62.7500 24.1536 1.0000
62.8000 24.0740 1.0000
62.8500 12.8316 1.0000
62.9000 27.5429 1.0000
62.9500 25.8428 1.0000
63.0000 22.9172 1.0000
63.0500 24.6159 1.0000
63.1000 22.2585 1.0000
63.1500 21.3756 1.0000
63.2000 22.7927 1.0000
63.2500 17.1573 1.0000
63.3000 19.7663 1.0000
63.3500 17.3148 1.0000
63.4000 21.5878 1.0000
63.4500 16.9503 1.0000
63.5000 18.6901 1.0000
63.5500 18.1719 1.0000
63.6000 22.8367 1.0000
63.6500 18.6802 1.0000
63.7000 12.9581 1.0000
63.7500 20.3713 1.0000
63.8000 21.9568 1.0000
63.8500 22.0803 1.0000
63.9000 23.9067 1.0000
63.9500 23.1866 1.0000
64.0000 14.5507 1.0000
64.0500 21.3129 1.0000
64.1000 23.5521 1.0000
64.1500 17.6900 1.0000
64.2000 18.8859 1.0000
64.2500 23.0136 1.0000
64.3000 14.8717 1.0000
64.3500 24.9588 1.0000
64.4000 23.1405 1.0000
64.4500 20.5984 1.0000
64.5000 13.9944 1.0000
64.5500 19.6122 1.0000
64.6000 19.9904 1.0000
64.6500 17.7572 1.0000
64.7000 23.9649 1.0000
64.7500 19.2327 1.0000
64.8000 24.3795 1.0000
64.8500 25.0518 1.0000
64.9000 25.0133 1.0000
64.9500 21.5871 1.0000
65.0000 18.9427 1.0000
65.0500 16.0244 1.0000
65.1000 18.5254 1.0000
65.1500 18.2388 1.0000
65.2000 24.6821 1.0000
65.2500 20.4645 1.0000
65.3000 31.4891 1.0000
65.3500 21.6629 1.0000
65.4000 21.4901 1.0000
65.4500 20.1496 1.0000
65.5000 21.3480 1.0000
65.5500 18.0130 1.0000
65.6000 13.6930 1.0000
65.6500 18.4012 1.0000
65.7000 19.3067 1.0000
65.7500 21.4592 1.0000
65.8000 22.5969 1.0000
65.8500 18.5632 1.0000
65.9000 17.8812 1.0000
65.9500 19.2255 1.0000
66.0000 23.6268 1.0000
66.0500 24.1063 1.0000
66.1000 17.2847 1.0000
66.1500 20.0513 1.0000
66.2000 22.1307 1.0000
66.2500 25.2482 1.0000
66.3000 12.8831 1.0000
66.3500 19.3044 1.0000
66.4000 21.9193 1.0000
66.4500 19.4655 1.0000
66.5000 14.5471 1.0000
66.5500 15.4408 1.0000
66.6000 16.1281 1.0000
66.6500 17.0425 1.0000
66.7000 28.4444 1.0000
66.7500 24.8333 1.0000
66.8000 27.5428 1.0000
66.8500 21.6091 1.0000
66.9000 21.7333 1.0000
66.9500 19.8304 1.0000
67.0000 32.7572 1.0000
67.0500 21.9256 1.0000
67.1000 25.2662 1.0000
67.1500 28.4594 1.0000
67.2000 13.9196 1.0000
67.2500 23.8559 1.0000
67.3000 25.3789 1.0000
67.3500 29.1671 1.0000
67.4000 29.0333 1.0000
67.4500 20.0752 1.0000
67.5000 24.7145 1.0000
67.5500 26.9804 1.0000
67.6000 21.5906 1.0000
67.6500 19.8770 1.0000
67.7000 28.3514 1.0000
67.7500 28.8300 1.0000
67.8000 21.7448 1.0000
67.8500 18.4709 1.0000
67.9000 21.8008 1.0000
67.9500 22.7736 1.0000
68.0000 15.0178 1.0000
68.0500 19.8636 1.0000
68.1000 12.3323 1.0000
68.1500 22.0556 1.0000
68.2000 13.9892 1.0000
68.2500 22.6844 1.0000
68.3000 18.3225 1.0000
68.3500 19.1482 1.0000
68.4000 14.4878 1.0000
68.4500 23.2968 1.0000
68.5000 20.1669 1.0000
68.5500 19.1754 1.0000
68.6000 22.6194 1.0000
68.6500 20.1898 1.0000
68.7000 28.9480 1.0000
68.7500 18.4399 1.0000
68.8000 20.4250 1.0000
68.8500 20.1113 1.0000
68.9000 13.2014 1.0000
68.9500 20.0103 1.0000
69.0000 17.5217 1.0000
69.0500 21.0557 1.0000
69.1000 23.2310 1.0000
69.1500 16.3872 1.0000
69.2000 15.5606 1.0000
69.2500 13.8762 1.0000
69.3000 19.5195 1.0000
69.3500 12.7253 1.0000
69.4000 21.2983 1.0000
69.4500 22.7910 1.0000
69.5000 18.7335 1.0000
69.5500 13.7880 1.0000
69.6000 17.9017 1.0000
69.6500 17.4783 1.0000
69.7000 18.7370 1.0000
69.7500 15.9777 1.0000
69.8000 14.6068 1.0000
69.8500 15.9126 1.0000
69.9000 27.8625 1.0000
69.9500 16.6864 1.0000
70.0000 29.7151 1.0000
70.0500 13.0534 1.0000
70.1000 18.5506 1.0000
70.1500 21.2633 1.0000
70.2000 22.8836 1.0000
70.2500 18.0186 1.0000
70.3000 14.5551 1.0000
70.3500 21.5693 1.0000
70.4000 23.9140 1.0000
70.4500 28.8570 1.0000
70.5000 22.3060 1.0000
70.5500 14.3354 1.0000
70.6000 21.0621 1.0000
70.6500 23.2486 1.0000
70.7000 20.0823 1.0000
70.7500 20.5736 1.0000
70.8000 17.7600 1.0000
70.8500 20.4108 1.0000
70.9000 17.8784 1.0000
70.9500 20.9400 1.0000
71.0000 24.5954 1.0000
71.0500 20.7871 1.0000
71.1000 25.6444 1.0000
71.1500 17.3560 1.0000
71.2000 29.7383 1.0000
71.2500 20.3653 1.0000
71.3000 22.1118 1.0000
71.3500 21.7182 1.0000
71.4000 19.7909 1.0000
71.4500 26.4422 1.0000
71.5000 18.2455 1.0000
71.5500 19.5877 1.0000
71.6000 22.7998 1.0000
71.6500 19.4517 1.0000
71.7000 19.2567 1.0000
71.7500 20.4111 1.0000
71.8000 27.9468 1.0000
71.8500 29.3669 1.0000
71.9000 26.7197 1.0000
71.9500 21.1009 1.0000
72.0000 14.1028 1.0000
72.0500 21.9898 1.0000
72.1000 23.9057 1.0000
72.1500 17.7333 1.0000
72.2000 21.3468 1.0000
72.2500 23.1655 1.0000
72.3000 13.5272 1.0000
72.3500 17.5669 1.0000
72.4000 17.6772 1.0000
72.4500 12.1696 1.0000
72.5000 13.9918 1.0000
72.5500 12.8583 1.0000
72.6000 17.5987 1.0000
72.6500 12.1014 1.0000
72.7000 17.3816 1.0000
72.7500 22.2491 1.0000
72.8000 21.6716 1.0000
72.8500 15.8786 1.0000
72.9000 22.8139 1.0000
72.9500 17.7196 1.0000
73.0000 17.5015 1.0000
73.0500 24.0098 1.0000
73.1000 19.4170 1.0000
73.1500 15.2902 1.0000
73.2000 12.8210 1.0000
73.2500 19.2454 1.0000
73.3000 18.1781 1.0000
73.3500 19.8667 1.0000
73.4000 24.4647 1.0000
73.4500 16.2109 1.0000
73.5000 18.9198 1.0000
73.5500 24.2480 1.0000
73.6000 17.2075 1.0000
73.6500 13.9936 1.0000
73.7000 17.8067 1.0000
73.7500 18.8607 1.0000
73.8000 24.4453 1.0000
73.8500 23.9286 1.0000
73.9000 20.4944 1.0000
73.9500 9.1458 1.0000
74.0000 20.4300 1.0000
74.0500 14.2971 1.0000
74.1000 15.5035 1.0000
74.1500 22.2189 1.0000
74.2000 15.0716 1.0000
74.2500 16.1025 1.0000
74.3000 16.6454 1.0000
74.3500 7.5352 1.0000
74.4000 19.0974 1.0000
74.4500 16.1293 1.0000
74.5000 17.8346 1.0000
74.5500 21.5065 1.0000
74.6000 18.6512 1.0000
74.6500 17.8288 1.0000
74.7000 16.0120 1.0000
74.7500 22.6950 1.0000
74.8000 10.3135 1.0000
74.8500 14.0133 1.0000
74.9000 19.1796 1.0000
74.9500 14.1793 1.0000
75.0000 10.4263 1.0000
75.0500 22.5593 1.0000
75.1000 16.6193 1.0000
75.1500 12.2426 1.0000
75.2000 12.9590 1.0000
75.2500 15.8535 1.0000
75.3000 19.1889 1.0000
75.3500 12.0940 1.0000
75.4000 27.8583 1.0000
75.4500 20.3029 1.0000
75.5000 21.3284 1.0000
75.5500 23.1091 1.0000
75.6000 16.7092 1.0000
75.6500 18.2729 1.0000
75.7000 32.1467 1.0000
75.7500 26.7326 1.0000
75.8000 23.2882 1.0000
75.8500 33.1204 1.0000
75.9000 15.6809 1.0000
75.9500 24.5871 1.0000
76.0000 23.0214 1.0000
76.0500 11.1305 1.0000
76.1000 11.6641 1.0000
76.1500 21.5011 1.0000
76.2000 17.3095 1.0000
76.2500 13.8318 1.0000
76.3000 17.3304 1.0000
76.3500 18.8281 1.0000
76.4000 12.8976 1.0000
76.4500 21.6060 1.0000
76.5000 20.7105 1.0000
76.5500 18.5545 1.0000
76.6000 23.0282 1.0000
76.6500 21.2457 1.0000
76.7000 22.3582 1.0000
76.7500 25.4030 1.0000
76.8000 15.9571 1.0000
76.8500 17.7982 1.0000
76.9000 15.2701 1.0000
76.9500 16.1413 1.0000
77.0000 19.7032 1.0000
77.0500 12.2859 1.0000
77.1000 19.3875 1.0000
77.1500 13.3086 1.0000
77.2000 26.5014 1.0000
77.2500 15.0775 1.0000
77.3000 15.3755 1.0000
77.3500 17.5916 1.0000
77.4000 17.0579 1.0000
77.4500 18.8739 1.0000
77.5000 9.0508 1.0000
77.5500 14.3098 1.0000
77.6000 19.2979 1.0000
77.6500 25.0693 1.0000
77.7000 16.8406 1.0000
77.7500 21.3461 1.0000
77.8000 19.0351 1.0000
77.8500 12.8440 1.0000
77.9000 15.1181 1.0000
77.9500 25.0475 1.0000
78.0000 18.8884 1.0000
78.0500 17.1177 1.0000
78.1000 21.1831 1.0000
78.1500 17.7769 1.0000
78.2000 17.0477 1.0000
78.2500 13.6607 1.0000
78.3000 20.3329 1.0000
78.3500 17.3647 1.0000
78.4000 10.9940 1.0000
78.4500 19.7747 1.0000
78.5000 7.8569 1.0000
78.5500 19.6708 1.0000
78.6000 14.2785 1.0000
78.6500 10.9903 1.0000
78.7000 9.4067 1.0000
78.7500 21.9749 1.0000
78.8000 16.9213 1.0000
78.8500 22.3718 1.0000
78.9000 15.3904 1.0000
78.9500 18.1973 1.0000
79.0000 23.0216 1.0000
79.0500 19.1523 1.0000
79.1000 13.9867 1.0000
79.1500 27.0890 1.0000
79.2000 18.2355 1.0000
79.2500 20.0722 1.0000
79.3000 24.1599 1.0000
79.3500 12.2572 1.0000
79.4000 23.2548 1.0000
79.4500 15.8579 1.0000
79.5000 9.4842 1.0000
79.5500 15.5216 1.0000
79.6000 20.7919 1.0000
79.6500 25.0258 1.0000
79.7000 14.0141 1.0000
79.7500 17.7598 1.0000
79.8000 14.0780 1.0000
79.8500 21.1240 1.0000
79.9000 17.1727 1.0000
79.9500 18.3770 1.0000
80.0000 16.1878 1.0000
*RAS_INT_END
*RAS_DATA_END
*DSC_DATA_END